<?xml version='1.0' encoding='utf-8'?>
<robot name="Hexapod">

    <material name="gray">
        <color rgba="0.4 0.4 0.4 1" />
    </material>

    <!-- Body -->

    <link name="base">
        <inertial>
            <origin xyz="-4.567197330417133e-06 0.0014207813889969261 0.00658135692503016" rpy="0.0 0.0 0.0" />
            <mass value="0.07235996288634414" />
            <inertia ixx="0.00027503594673628195" iyy="0.00019910910165675598" izz="0.0004719684331235039" ixy="1.1044492824149298e-08" iyz="-4.230155688856179e-07" ixz="-8.119007727403214e-10" />
        </inertial>
        <visual name="base_visual">
            <origin xyz="0.0 0.0 0.0" rpy="0.0 0.0 0.0" />
            <geometry>
                <mesh filename="CAD/base.stl" scale="0.001 0.001 0.001" />
            </geometry>
            <material name="gray"/>
        </visual>
        <collision name="base_collision">
            <origin xyz="0.0 0.0 0.0" rpy="0.0 0.0 0.0" />
            <geometry>
                <mesh filename="CAD/base.stl" scale="0.001 0.001 0.001" />
            </geometry>
        </collision>
    </link>
    <link name="base_cover">
        <inertial>
            <origin xyz="0.030635004061402942 0.05126297721134841 -0.0008001845156470179" rpy="0.0 -0.0 0.0" />
            <mass value="0.018994847098647162" />
            <inertia ixx="2.2940391506653537e-05" iyy="7.3396261104543045e-06" izz="3.0238507454307017e-05" ixy="2.8124993856809636e-20" iyz="-2.7973561537982384e-09" ixz="8.848247614903168e-22" />
        </inertial>
        <visual name="base_cover_visual">
            <origin xyz="0.030635004061402335 0.05200000323275548 -0.002" rpy="0.0 -0.0 3.141592653589793" />
            <geometry>
                <mesh filename="CAD/base_cover.stl" scale="0.001 0.001 0.001" />
            </geometry>
            <material name="gray"/>
        </visual>
        <collision name="base_cover_collision">
            <origin xyz="0.030635004061402335 0.05200000323275548 -0.002" rpy="0.0 -0.0 3.141592653589793" />
            <geometry>
                <mesh filename="CAD/base_cover.stl" scale="0.001 0.001 0.001" />
            </geometry>
        </collision>
    </link>
    <link name="battery">
        <inertial>
            <origin xyz="4.061402343290277e-09 -0.004000003232755452 0.013299999999999996" rpy="0.0 -0.0 0.0" />
            <mass value="0.19006392383638834" />
            <inertia ixx="0.00031379250632943294" iyy="4.5877280158112334e-05" izz="0.0003377756922451688" ixy="-2.586759211575828e-20" iyz="-3.9979955110402976e-19" ixz="2.5808035111654463e-19" />
        </inertial>
        <visual name="battery_visual">
            <origin xyz="-0.023749995938597668 0.06549999676724455 0.026599999999999967" rpy="3.1415926535897927 -1.6653345369377343e-16 -6.695352868347747e-17" />
            <geometry>
                <mesh filename="CAD/battery.stl" scale="0.001 0.001 0.001" />
            </geometry>
            <material name="gray"/>
        </visual>
        <collision name="battery_collision">
            <origin xyz="-0.023749995938597668 0.06549999676724455 0.026599999999999967" rpy="3.1415926535897927 -1.6653345369377343e-16 -6.695352868347747e-17" />
            <geometry>
                <mesh filename="CAD/battery.stl" scale="0.001 0.001 0.001" />
            </geometry>
        </collision>
    </link>
    <link name="mounting_plate">
        <inertial>
            <origin xyz="-0.03291399940042262 -0.05932272752394369 -0.0010651495731488715" rpy="0.0 -0.0 0.0" />
            <mass value="0.018349928101856598" />
            <inertia ixx="2.4460418273207888e-05" iyy="1.4008760034433459e-05" izz="3.8443273521518956e-05" ixy="1.6788466865974587e-07" iyz="-1.9067093496822743e-08" ixz="-2.1864035181144862e-09" />
        </inertial>
        <visual name="mounting_plate_visual">
            <origin xyz="-0.03263499593859754 -0.05800000323275541 -4.440892098500626e-18" rpy="3.141592653589793 -0.0 -3.141592653589793" />
            <geometry>
                <mesh filename="CAD/mounting_plate.stl" scale="0.001 0.001 0.001" />
            </geometry>
            <material name="gray"/>
        </visual>
        <collision name="mounting_plate_collision">
            <origin xyz="-0.03263499593859754 -0.05800000323275541 -4.440892098500626e-18" rpy="3.141592653589793 -0.0 -3.141592653589793" />
            <geometry>
                <mesh filename="CAD/mounting_plate.stl" scale="0.001 0.001 0.001" />
            </geometry>
        </collision>
    </link>

    <joint name="base_base_cover" type="fixed">
        <origin xyz="0.03063500406140232 0.05200000323275548 0.0" rpy="0.0 -0.0 -3.141592653589793" />
        <parent link="base" />
        <child link="base_cover" />
    </joint>
    <joint name="base_cover_battery" type="fixed">
        <origin xyz="0.030635 0.052000000000000005 -0.002" rpy="3.141592653589793 -0.0 0.0" />
        <parent link="base_cover" />
        <child link="battery" />
    </joint>
    <joint name="base_mounting_plate" type="fixed">
        <origin xyz="-0.032634995938597595 0.058000003232755476 0.013999999999999999" rpy="3.141592653589793 -0.0 -3.141592653589793" />
        <parent link="base" />
        <child link="mounting_plate" />
    </joint>

    <!-- Leg 1 -->

    <link name="leg_1_coxa_motor">
        <inertial>
            <origin xyz="0.013574471662495436 0.020999093948920588 0.008369892907608513" rpy="0.0 -0.0 0.0" />
            <mass value="0.029139949883713843" />
            <inertia ixx="5.5905783876468375e-06" iyy="5.590577528174812e-06" izz="5.0762677862824235e-06" ixy="-1.601493742541156e-06" iyz="-4.6930327749458066e-08" ixz="-4.693166015165574e-08" />
        </inertial>
        <visual name="leg_1_coxa_motor_visual">
            <origin xyz="0.034789656534207805 0.02842569347242403 -2.958437799684093e-17" rpy="-3.1415926535897922 -7.606971055477596e-16 -2.35619449019235" />
            <geometry>
                <mesh filename="CAD/MG996R.stl" scale="0.001 0.001 0.001" />
            </geometry>
            <material name="gray"/>
        </visual>
        <collision name="leg_1_coxa_motor_collision">
            <origin xyz="0.034789656534207805 0.02842569347242403 -2.958437799684093e-17" rpy="-3.1415926535897922 -7.606971055477596e-16 -2.35619449019235" />
            <geometry>
                <mesh filename="CAD/MG996R.stl" scale="0.001 0.001 0.001" />
            </geometry>
        </collision>
    </link>
    <link name="leg_1_coxa_bracket_B">
        <inertial>
            <origin xyz="-0.003105251669849143 0.014525191609803123 -0.0074541224383952095" rpy="5.691615141457044e-61 -0.0 0.0" />
            <mass value="0.004130529991365324" />
            <inertia ixx="7.023383537157265e-07" iyy="3.6345289474121016e-07" izz="3.6345289474575026e-07" ixy="7.667259002195375e-09" iyz="1.866291193022852e-07" ixz="-7.667259001889596e-09" />
        </inertial>
        <visual name="leg_1_coxa_bracket_B_visual">
            <origin xyz="0.022900003203435226 0.000707103897757353 0.006363965273596914" rpy="2.3561944901923506 -6.414614657916635e-16 3.1415926535897905" />
            <geometry>
                <mesh filename="CAD/bracket_B.stl" scale="0.001 0.001 0.001" />
            </geometry>
            <material name="gray"/>
        </visual>
        <collision name="leg_1_coxa_bracket_B_collision">
            <origin xyz="0.022900003203435226 0.000707103897757353 0.006363965273596914" rpy="2.3561944901923506 -6.414614657916635e-16 3.1415926535897905" />
            <geometry>
                <mesh filename="CAD/bracket_B.stl" scale="0.001 0.001 0.001" />
            </geometry>
        </collision>
    </link>
    <link name="leg_1_coxa_bracket_A">
        <inertial>
            <origin xyz="-0.015926416210366803 -0.015926407039013685 -0.010950415401159198" rpy="0.0 -0.0 0.0" />
            <mass value="0.01302030082235085" />
            <inertia ixx="4.456492754704972e-06" iyy="4.4564927547023565e-06" izz="2.2212930817995568e-06" ixy="-6.7818217166459e-07" iyz="-9.764098496075963e-07" ixz="-9.764098496048723e-07" />
        </inertial>
        <visual name="leg_1_coxa_bracket_A_visual">
            <origin xyz="-0.055545471515115345 -0.055545462343760815 -0.04320260861218249" rpy="-0.7853981633974432 1.5707963267948941 0" />
            <geometry>
                <mesh filename="CAD/bracket_A.stl" scale="0.001 0.001 0.001" />
            </geometry>
            <material name="gray"/>
        </visual>
        <collision name="leg_1_coxa_bracket_A_collision">
            <origin xyz="-0.055545471515115345 -0.055545462343760815 -0.04320260861218249" rpy="-0.7853981633974432 1.5707963267948941 0" />
            <geometry>
                <mesh filename="CAD/bracket_A.stl" scale="0.001 0.001 0.001" />
            </geometry>
        </collision>
    </link>
    <link name="leg_1_femur_bracket_A">
        <inertial>
            <origin xyz="-0.012675760983264742 -0.003554678519033221 0.005000003203434631" rpy="0.0 -0.0 0.0" />
            <mass value="0.01302030082235085" />
            <inertia ixx="1.6189497806714257e-06" iyy="4.380653884166873e-06" izz="5.134674926367841e-06" ixy="7.785087506199451e-07" iyz="-4.726443845678996e-19" ixz="2.349669395683429e-18" />
        </inertial>
        <visual name="leg_1_femur_bracket_A_visual">
            <origin xyz="0.04974903884913646 0.013258632258061188 0.005000003203435334" rpy="1.5707963267948983 1.2896663962143586e-15 -0.7853981633974524" />
            <geometry>
                <mesh filename="CAD/bracket_A.stl" scale="0.001 0.001 0.001" />
            </geometry>
            <material name="gray"/>
        </visual>
        <collision name="leg_1_femur_bracket_A_collision">
            <origin xyz="0.04974903884913646 0.013258632258061188 0.005000003203435334" rpy="1.5707963267948983 1.2896663962143586e-15 -0.7853981633974524" />
            <geometry>
                <mesh filename="CAD/bracket_A.stl" scale="0.001 0.001 0.001" />
            </geometry>
        </collision>
    </link>
    <link name="leg_1_femur_bracket_B">
        <inertial>
            <origin xyz="-0.0049999967965269135 -0.013185405881645487 0.008793910918232131" rpy="0.0 -0.0 0.0" />
            <mass value="0.004130529991365324" />
            <inertia ixx="5.500820140457417e-07" iyy="4.2873792291154715e-07" izz="4.5042420624536415e-07" ixy="1.7550522667109103e-18" iyz="2.627572891372471e-07" ixz="-1.4560496363301423e-18" />
        </inertial>
        <visual name="leg_1_femur_bracket_B_visual">
            <origin xyz="-0.004999996796564824 0.01902117389775734 0.013364315273596947" rpy="-1.7383551510003044e-15 0.7853981633974443 -1.5707963267948983" />
            <geometry>
                <mesh filename="CAD/bracket_B.stl" scale="0.001 0.001 0.001" />
            </geometry>
            <material name="gray"/>
        </visual>
        <collision name="leg_1_femur_bracket_B_collision">
            <origin xyz="-0.004999996796564824 0.01902117389775734 0.013364315273596947" rpy="-1.7383551510003044e-15 0.7853981633974443 -1.5707963267948983" />
            <geometry>
                <mesh filename="CAD/bracket_B.stl" scale="0.001 0.001 0.001" />
            </geometry>
        </collision>
    </link>
    <link name="leg_1_femur_motor">
        <inertial>
            <origin xyz="5.4061232124258395e-09 -0.0231178146864527 -0.008979636323357543" rpy="4.337878534446334e-75 -0.0 0.0" />
            <mass value="0.029139949883713843" />
            <inertia ixx="7.1920717004518315e-06" iyy="4.599046448966514e-06" izz="4.466305552685429e-06" ixy="9.700703510872458e-13" iyz="5.435917854563437e-07" ixz="3.6233184150507507e-13" />
        </inertial>
        <visual name="leg_1_femur_motor_visual">
            <origin xyz="-0.009749996796564731 -0.043357114916835776 -0.0005771521585247364" rpy="-3.1415926535897833 0.7853981633974512 1.5707963267948943" />
            <geometry>
                <mesh filename="CAD/MG996R.stl" scale="0.001 0.001 0.001" />
            </geometry>
            <material name="gray"/>
        </visual>
        <collision name="leg_1_femur_motor_collision">
            <origin xyz="-0.009749996796564731 -0.043357114916835776 -0.0005771521585247364" rpy="-3.1415926535897833 0.7853981633974512 1.5707963267948943" />
            <geometry>
                <mesh filename="CAD/MG996R.stl" scale="0.001 0.001 0.001" />
            </geometry>
        </collision>
    </link>
    <link name="leg_1_femur">
        <inertial>
            <origin xyz="-0.04233946112690463 -0.032331021486653955 -0.005249996796564785" rpy="0.0 7.006492321624085e-46 1.2066609121497597e-89" />
            <mass value="0.021802151943504742" />
            <inertia ixx="1.5076488302837017e-05" iyy="1.5076488302836252e-05" izz="2.5188056838580504e-05" ixy="-1.223245766346636e-05" iyz="-1.6940658945086154e-20" ixz="-2.7105054312137533e-20" />
        </inertial>
        <visual name="leg_1_femur_visual">
            <origin xyz="-0.06738728096951471 -0.04758828817165156 -0.005249996796564868" rpy="1.5707963267948986 -1.5804414278766448e-15 0.7853981633974446" />
            <geometry>
                <mesh filename="CAD/femur.stl" scale="0.001 0.001 0.001" />
            </geometry>
            <material name="gray"/>
        </visual>
        <collision name="leg_1_femur_collision">
            <origin xyz="-0.06738728096951471 -0.04758828817165156 -0.005249996796564868" rpy="1.5707963267948986 -1.5804414278766448e-15 0.7853981633974446" />
            <geometry>
                <mesh filename="CAD/femur.stl" scale="0.001 0.001 0.001" />
            </geometry>
        </collision>
    </link>
    <link name="leg_1_tibia_motor">
        <inertial>
            <origin xyz="0.011368372072919223 -0.023205191063109327 0.005249998999252793" rpy="0.0 -0.0 -1.9481407417666057e-90" />
            <mass value="0.029139949883713843" />
            <inertia ixx="4.599046448966731e-06" iyy="4.466305552685537e-06" izz="7.192071700452265e-06" ixy="5.435917854563436e-07" iyz="-3.62331848281338e-13" ixz="-9.700703578635096e-13" />
        </inertial>
        <visual name="leg_1_tibia_motor_visual">
            <origin xyz="0.031607672303302387 -0.03160767522794195 -0.004500003203435124" rpy="1.5707963267948946 -1.4579767479619077e-15 2.3561944901923497" />
            <geometry>
                <mesh filename="CAD/MG996R.stl" scale="0.001 0.001 0.001" />
            </geometry>
            <material name="gray"/>
        </visual>
        <collision name="leg_1_tibia_motor_collision">
            <origin xyz="0.031607672303302387 -0.03160767522794195 -0.004500003203435124" rpy="1.5707963267948946 -1.4579767479619077e-15 2.3561944901923497" />
            <geometry>
                <mesh filename="CAD/MG996R.stl" scale="0.001 0.001 0.001" />
            </geometry>
        </collision>
    </link>
    <link name="leg_1_tibia_bracket_A">
        <inertial>
            <origin xyz="-0.008183294094499942 -0.023669531630267856 3.203435771093055e-09" rpy="0.0 -0.0 -5.001342253538129e-90" />
            <mass value="0.01302030082235085" />
            <inertia ixx="4.380653884166928e-06" iyy="1.6189497806713173e-06" izz="5.134674926367678e-06" ixy="7.785087506200264e-07" iyz="2.3954091748351614e-18" ixz="-5.183841637196319e-19" />
        </inertial>
        <visual name="leg_1_tibia_bracket_A_visual">
            <origin xyz="-0.024996604871594885 -0.08609433146266905 3.203434947307571e-09" rpy="-1.570796326794895 2.6216440076822113e-15 -0.7853981633974513" />
            <geometry>
                <mesh filename="CAD/bracket_A.stl" scale="0.001 0.001 0.001" />
            </geometry>
            <material name="gray"/>
        </visual>
        <collision name="leg_1_tibia_bracket_A_collision">
            <origin xyz="-0.024996604871594885 -0.08609433146266905 3.203434947307571e-09" rpy="-1.570796326794895 2.6216440076822113e-15 -0.7853981633974513" />
            <geometry>
                <mesh filename="CAD/bracket_A.stl" scale="0.001 0.001 0.001" />
            </geometry>
        </collision>
    </link>
    <link name="leg_1_tibia_bracket_B">
        <inertial>
            <origin xyz="-0.004999996796602597 0.008793918304699026 -0.013185403268111866" rpy="1.5241149863310267e-61 8.758115402030107e-47 0.0" />
            <mass value="0.004130529991365324" />
            <inertia ixx="5.500820140457688e-07" iyy="4.5042420624536405e-07" izz="4.2873792291151327e-07" ixy="1.4602848010664136e-18" iyz="2.6275728913721994e-07" ixz="-1.748276003132876e-18" />
        </inertial>
        <visual name="leg_1_tibia_bracket_B_visual">
            <origin xyz="-0.004999996796564574 0.01336432266006412 0.01902117651129096" rpy="-3.1415926535897922 0.7853981633974451 -1.570796326794902" />
            <geometry>
                <mesh filename="CAD/bracket_B.stl" scale="0.001 0.001 0.001" />
            </geometry>
            <material name="gray"/>
        </visual>
        <collision name="leg_1_tibia_bracket_B_collision">
            <origin xyz="-0.004999996796564574 0.01336432266006412 0.01902117651129096" rpy="-3.1415926535897922 0.7853981633974451 -1.570796326794902" />
            <geometry>
                <mesh filename="CAD/bracket_B.stl" scale="0.001 0.001 0.001" />
            </geometry>
        </collision>
    </link>
    <link name="leg_1_tibia">
        <inertial>
            <origin xyz="0.026965073129646255 0.03403614230100331 -0.026581936859366603" rpy="0.0 -3.503246160812043e-46 0.0" />
            <mass value="0.02243468417663065" />
            <inertia ixx="2.20268536708009e-05" iyy="2.2026853670809242e-05" izz="3.948923882044343e-05" ixy="-1.9223537837673336e-05" iyz="2.9439831431853673e-06" ixz="2.9439831431894402e-06" />
        </inertial>
        <visual name="leg_1_tibia_visual">
            <origin xyz="0.023334521173797997 0.030405590345152902 -0.004999996871070658" rpy="2.1072934008282714e-15 -2.164998327842474e-15 2.3561944901923417" />
            <geometry>
                <mesh filename="CAD/tibia.stl" scale="0.001 0.001 0.001" />
            </geometry>
            <material name="gray"/>
        </visual>
        <collision name="leg_1_tibia_collision">
            <origin xyz="0.023334521173797997 0.030405590345152902 -0.004999996871070658" rpy="2.1072934008282714e-15 -2.164998327842474e-15 2.3561944901923417" />
            <geometry>
                <mesh filename="CAD/tibia.stl" scale="0.001 0.001 0.001" />
            </geometry>
        </collision>
    </link>

    <joint name="base_leg_1_base_coxa_motor" type="fixed">
        <origin xyz="0.06338894406140227 0.09617856323275542 0.0" rpy="0.0 -0.0 -3.141592653589793" />
        <parent link="base" />
        <child link="leg_1_coxa_motor" />
    </joint>
    <joint name="leg_1_coxa_bracket_A_leg_1_coxa_bracket" type="fixed">
        <origin xyz="-0.017677670000000003 -0.024748730000000007 -0.0453" rpy="3.3187136453961136e-46 -1.5707963267948966 0" />
        <parent link="leg_1_coxa_bracket_A" />
        <child link="leg_1_coxa_bracket_B" />
    </joint>
    <joint name="leg_1_coxa" type="revolute">
        <origin xyz="0.006505390000000002 0.013930000000000007 0.03106621" rpy="1.9721522630525295e-31 -0.0 -3.3187136453961136e-46" />
        <parent link="leg_1_coxa_motor" />
        <child link="leg_1_coxa_bracket_A" />
        <axis xyz="0.0 -1.9721522630525295e-31 -1.0" />
        <limit lower="-1.570796" upper="1.570796" effort="1000000" velocity="1000000" />
    </joint>
    <joint name="leg_1_femur_bracket_A_leg_1_coxa_bracket_femur_bracket" type="fixed">
        <origin xyz="0.01689985 -0.022556709999999997 0.01" rpy="3.944304526105059e-31 -1.5707963267948966 0" />
        <parent link="leg_1_femur_bracket_A" />
        <child link="leg_1_femur_bracket_B" />
    </joint>
    <joint name="leg_1_coxa_bracket_A_leg_1_femur_bracket" type="fixed">
        <origin xyz="-0.027577170000000005 -0.020506090000000015 -0.027400000000000004" rpy="2.6887765138291873e-30 6.5450086261912554e-77 3.3187136453961136e-46" />
        <parent link="leg_1_coxa_bracket_A" />
        <child link="leg_1_femur_bracket_A" />
    </joint>
    <joint name="leg_1_femur" type="revolute">
        <origin xyz="-0.03634529000000001 -0.011737969999999986 0.005" rpy="-6.661338147750935e-16 -1.5707963267948966 0" />
        <parent link="leg_1_femur_bracket_A" />
        <child link="leg_1_femur_motor" />
        <axis xyz="-2.594261684304826e-30 0.7071069999999996 0.7071070000000005" />
        <limit lower="-1.570796" upper="1.570796" effort="1000000" velocity="1000000" />
    </joint>
    <joint name="leg_1_femur_motor_leg_1_femur_motor_femur" type="fixed">
        <origin xyz="0.00525 -0.011749439999999965 -0.032184830000000025" rpy="-6.611709141336395e-45 1.570796326794896 0" />
        <parent link="leg_1_femur_motor" />
        <child link="leg_1_femur" />
    </joint>
    <joint name="leg_1_femur_leg_1_femur_tibia_motor" type="fixed">
        <origin xyz="-0.07467048 -0.07467048000000003 2.220446049250313e-18" rpy="3.141592653589793 -1.51226552030483e-30 3.94430452610506e-31" />
        <parent link="leg_1_femur" />
        <child link="leg_1_tibia_motor" />
    </joint>
    <joint name="leg_1_tibia_bracket_A_leg_1_tibia_bracket" type="fixed">
        <origin xyz="0.010818740000000026 -0.05324515000000002 0.005000000000000001" rpy="-1.97215226305253e-31 -1.5707963267948966 0" />
        <parent link="leg_1_tibia_bracket_A" />
        <child link="leg_1_tibia_bracket_B" />
    </joint>
    <joint name="leg_1_tibia" type="revolute">
        <origin xyz="-0.01174944 -0.032184830000000025 0.00525" rpy="-3.141592653589793 4.759319555259372e-30 1.1543557789201666e-90" />
        <parent link="leg_1_tibia_motor" />
        <child link="leg_1_tibia_bracket_A" />
        <axis xyz="0.707107 -0.707107 -1.0126468723405215e-29" />
        <limit lower="-2.181662" upper="-0.0" effort="1000000" velocity="1000000" />
    </joint>
    <joint name="leg_1_tibia_bracket_A_leg_1_tibia_bracket_tibia" type="fixed">
        <origin xyz="-0.004666899999999998 -0.043416360000000015 0.005000000000000001" rpy="-9.860761315262648e-31 4.894350220025294e-30 -1.9721522630525295e-31" />
        <parent link="leg_1_tibia_bracket_A" />
        <child link="leg_1_tibia" />
    </joint>

    <!-- Leg 2 -->

    <link name="leg_2_coxa_motor">
        <inertial>
            <origin xyz="0.02444720409026191 0.0052500054354434715 0.008369892907608496" rpy="0.0 -0.0 0.0" />
            <mass value="0.20795327871559424" />
            <inertia ixx="2.8467555536956224e-05" iyy="5.132523895322533e-05" izz="3.6226092838469756e-05" ixy="-3.0667524590763037e-12" iyz="6.72352947090753e-12" ixz="-4.7364365263922396e-07" />
        </inertial>
        <visual name="leg_2_coxa_motor_visual">
            <origin xyz="0.044700004061402086 -0.004499996767244423 -7.679184985266577e-17" rpy="-3.141592653589793 -1.7201985660320116e-15 3.141592653589793" />
            <geometry>
                <mesh filename="CAD/MG996R.stl" scale="0.001 0.001 0.001" />
            </geometry>
            <material name="gray"/>
        </visual>
        <collision name="leg_2_coxa_motor_collision">
            <origin xyz="0.044700004061402086 -0.004499996767244423 -7.679184985266577e-17" rpy="-3.141592653589793 -1.7201985660320116e-15 3.141592653589793" />
            <geometry>
                <mesh filename="CAD/MG996R.stl" scale="0.001 0.001 0.001" />
            </geometry>
        </collision>
    </link>
    <link name="leg_2_coxa_bracket_B">
        <inertial>
            <origin xyz="-0.0031052516698490164 0.005000003232793494 -0.015541731109800186" rpy="0.0 -0.0 0.0" />
            <mass value="0.029476964029288902" />
            <inertia ixx="5.0121418878803635e-06" iyy="3.925585282053807e-06" izz="1.2618787611030848e-06" ixy="1.5353530960168262e-18" iyz="1.6205434346869274e-17" ixz="-7.738060189573621e-08" />
        </inertial>
        <visual name="leg_2_coxa_bracket_B_visual">
            <origin xyz="0.0229000032034354 0.005000003232755467 0.0039999959385979625" rpy="3.1415926535897927 -8.24298540808992e-16 3.1415926535897913" />
            <geometry>
                <mesh filename="CAD/bracket_B.stl" scale="0.001 0.001 0.001" />
            </geometry>
            <material name="gray"/>
        </visual>
        <collision name="leg_2_coxa_bracket_B_collision">
            <origin xyz="0.0229000032034354 0.005000003232755467 0.0039999959385979625" rpy="3.1415926535897927 -8.24298540808992e-16 3.1415926535897913" />
            <geometry>
                <mesh filename="CAD/bracket_B.stl" scale="0.001 0.001 0.001" />
            </geometry>
        </collision>
    </link>
    <link name="leg_2_coxa_bracket_A">
        <inertial>
            <origin xyz="-0.022523343077750165 3.2327548002419883e-09 -0.010950415401159055" rpy="0.0 -0.0 0.0" />
            <mass value="0.09291760132314016" />
            <inertia ixx="2.6963398251687907e-05" iyy="3.6642907429082646e-05" izz="1.5851955174660498e-05" ixy="-9.337691210531407e-18" iyz="-1.3833318578083606e-17" ixz="-9.8542623692912e-06" />
        </inertial>
        <visual name="leg_2_coxa_bracket_A_visual">
            <origin xyz="-0.07855314841813432 3.2327555024580513e-09 -0.04320260861218222" rpy="-3.194319442119254e-45 1.5707963267948948 0" />
            <geometry>
                <mesh filename="CAD/bracket_A.stl" scale="0.001 0.001 0.001" />
            </geometry>
            <material name="gray"/>
        </visual>
        <collision name="leg_2_coxa_bracket_A_collision">
            <origin xyz="-0.07855314841813432 3.2327555024580513e-09 -0.04320260861218222" rpy="-3.194319442119254e-45 1.5707963267948948 0" />
            <geometry>
                <mesh filename="CAD/bracket_A.stl" scale="0.001 0.001 0.001" />
            </geometry>
        </collision>
    </link>
    <link name="leg_2_femur_bracket_A">
        <inertial>
            <origin xyz="-0.011476648799445517 0.0064495846281610175 0.0050000032034348205" rpy="0.0 -0.0 0.0" />
            <mass value="0.09291760132314016" />
            <inertia ixx="2.696339825168818e-05" iyy="1.5851955174657354e-05" izz="3.664290742907907e-05" ixy="9.854262369290794e-06" iyz="-1.4267422963551435e-17" ixz="9.513874063560301e-18" />
        </inertial>
        <visual name="leg_2_femur_bracket_A_visual">
            <origin xyz="0.04455315654093875 -0.02580260858286211 0.005000003203435406" rpy="1.570796326794896 8.510717720686041e-16 -1.5707963267948954" />
            <geometry>
                <mesh filename="CAD/bracket_A.stl" scale="0.001 0.001 0.001" />
            </geometry>
            <material name="gray"/>
        </visual>
        <collision name="leg_2_femur_bracket_A_collision">
            <origin xyz="0.04455315654093875 -0.02580260858286211 0.005000003203435406" rpy="1.570796326794896 8.510717720686041e-16 -1.5707963267948954" />
            <geometry>
                <mesh filename="CAD/bracket_A.stl" scale="0.001 0.001 0.001" />
            </geometry>
        </collision>
    </link>
    <link name="leg_2_femur_bracket_B">
        <inertial>
            <origin xyz="-0.0049999967965266776 -0.003105251640528857 0.015541722986996156" rpy="0.0 -0.0 0.0" />
            <mass value="0.029476964029288902" />
            <inertia ixx="3.92558528205378e-06" iyy="5.012141887880445e-06" izz="1.261878761103178e-06" ixy="1.5077186461126546e-18" iyz="7.738060189576331e-08" ixz="-1.620882247865829e-17" />
        </inertial>
        <visual name="leg_2_femur_bracket_B_visual">
            <origin xyz="-0.004999996796564646 0.022900003232755522 -0.004000004061401992" rpy="-1.295326278414143e-15 1.0547118733938999e-15 -1.5707963267948974" />
            <geometry>
                <mesh filename="CAD/bracket_B.stl" scale="0.001 0.001 0.001" />
            </geometry>
            <material name="gray"/>
        </visual>
        <collision name="leg_2_femur_bracket_B_collision">
            <origin xyz="-0.004999996796564646 0.022900003232755522 -0.004000004061401992" rpy="-1.295326278414143e-15 1.0547118733938999e-15 -1.5707963267948974" />
            <geometry>
                <mesh filename="CAD/bracket_B.stl" scale="0.001 0.001 0.001" />
            </geometry>
        </collision>
    </link>
    <link name="leg_2_femur_motor">
        <inertial>
            <origin xyz="5.406123489981596e-09 -0.0226963170630714 0.009997195967457665" rpy="5.402641209858873e-93 -0.0 0.0" />
            <mass value="0.20795327871559424" />
            <inertia ixx="5.13252389532249e-05" iyy="3.6226092838469e-05" izz="2.8467555536956125e-05" ixy="6.7235294484611595e-12" iyz="-4.736436526391849e-07" ixz="-3.066752526838935e-12" />
        </inertial>
        <visual name="leg_2_femur_motor_visual">
            <origin xyz="-0.009749996796564402 -0.031066209970679957 0.03024999593859782" rpy="1.570796326794899 1.5707963267948941 0" />
            <geometry>
                <mesh filename="CAD/MG996R.stl" scale="0.001 0.001 0.001" />
            </geometry>
            <material name="gray"/>
        </visual>
        <collision name="leg_2_femur_motor_collision">
            <origin xyz="-0.009749996796564402 -0.031066209970679957 0.03024999593859782" rpy="1.570796326794899 1.5707963267948941 0" />
            <geometry>
                <mesh filename="CAD/MG996R.stl" scale="0.001 0.001 0.001" />
            </geometry>
        </collision>
    </link>
    <link name="leg_2_femur">
        <inertial>
            <origin xyz="-0.052799995938616 0.007077033500005008 -0.005249996796564443" rpy="0.0 -0.0 0.0" />
            <mass value="0.155588084324102" />
            <inertia ixx="2.0296036835505468e-05" iyy="0.00019488656894134197" izz="0.00017975113289350313" ixy="-3.1704443215728458e-18" iyz="4.8572045569113707e-20" ixz="5.4210108624275186e-20" />
        </inertial>
        <visual name="leg_2_femur_visual">
            <origin xyz="-0.081299995938598 0.014000000029319995 -0.005249996796564461" rpy="1.5707963267948981 7.771561172376091e-16 1.3877787807814457e-15" />
            <geometry>
                <mesh filename="CAD/femur.stl" scale="0.001 0.001 0.001" />
            </geometry>
            <material name="gray"/>
        </visual>
        <collision name="leg_2_femur_collision">
            <origin xyz="-0.081299995938598 0.014000000029319995 -0.005249996796564461" rpy="1.5707963267948981 7.771561172376091e-16 1.3877787807814457e-15" />
            <geometry>
                <mesh filename="CAD/femur.stl" scale="0.001 0.001 0.001" />
            </geometry>
        </collision>
    </link>
    <link name="leg_2_tibia_motor">
        <inertial>
            <origin xyz="0.024447204090261715 -0.008369892936928471 0.005249998999252401" rpy="0.0 -0.0 -1.0767935747447776e-62" />
            <mass value="0.20795327871559424" />
            <inertia ixx="2.8467555536956068e-05" iyy="3.622609283846813e-05" izz="5.132523895322663e-05" ixy="4.7364365263925784e-07" iyz="-6.7235295230000565e-12" ixz="-3.0667525268389395e-12" />
        </inertial>
        <visual name="leg_2_tibia_motor_visual">
            <origin xyz="0.044700004061401906 -2.931993758892304e-11 -0.004500003203435472" rpy="1.570796326794895 8.996207971523451e-16 3.1415926535897927" />
            <geometry>
                <mesh filename="CAD/MG996R.stl" scale="0.001 0.001 0.001" />
            </geometry>
            <material name="gray"/>
        </visual>
        <collision name="leg_2_tibia_motor_collision">
            <origin xyz="0.044700004061401906 -2.931993758892304e-11 -0.004500003203435472" rpy="1.570796326794895 8.996207971523451e-16 3.1415926535897927" />
            <geometry>
                <mesh filename="CAD/MG996R.stl" scale="0.001 0.001 0.001" />
            </geometry>
        </collision>
    </link>
    <link name="leg_2_tibia_bracket_A">
        <inertial>
            <origin xyz="-0.02252334307775044 -0.01095041537183914 3.2034362584809628e-09" rpy="0.0 -0.0 0.0" />
            <mass value="0.09291760132314016" />
            <inertia ixx="2.696339825168882e-05" iyy="1.585195517465627e-05" izz="3.6642907429077984e-05" ixy="-9.854262369291445e-06" iyz="1.473498515043581e-17" ixz="9.459663954936026e-18" />
        </inertial>
        <visual name="leg_2_tibia_bracket_A_visual">
            <origin xyz="-0.07855314841813467 -0.04320260858286247 3.2034355823551408e-09" rpy="-1.5707963267948974 2.1830493835364575e-15 -1.5707963267948943" />
            <geometry>
                <mesh filename="CAD/bracket_A.stl" scale="0.001 0.001 0.001" />
            </geometry>
            <material name="gray"/>
        </visual>
        <collision name="leg_2_tibia_bracket_A_collision">
            <origin xyz="-0.07855314841813467 -0.04320260858286247 3.2034355823551408e-09" rpy="-1.5707963267948974 2.1830493835364575e-15 -1.5707963267948943" />
            <geometry>
                <mesh filename="CAD/bracket_A.stl" scale="0.001 0.001 0.001" />
            </geometry>
        </collision>
    </link>
    <link name="leg_2_tibia_bracket_B">
        <inertial>
            <origin xyz="-0.004999996796602131 -0.0031052516405290476 -0.015541731109800132" rpy="0.0 -0.0 0.0" />
            <mass value="0.029476964029288902" />
            <inertia ixx="3.9255852820534e-06" iyy="5.0121418878803364e-06" izz="1.2618787611031272e-06" ixy="-1.4594377681191595e-18" iyz="-7.738060189566845e-08" ixz="-1.620882247865829e-17" />
        </inertial>
        <visual name="leg_2_tibia_bracket_B_visual">
            <origin xyz="-0.004999996796564074 0.02290000323275531 0.003999995938598105" rpy="3.141592653589793 2.0539125955565404e-15 -1.5707963267949" />
            <geometry>
                <mesh filename="CAD/bracket_B.stl" scale="0.001 0.001 0.001" />
            </geometry>
            <material name="gray"/>
        </visual>
        <collision name="leg_2_tibia_bracket_B_collision">
            <origin xyz="-0.004999996796564074 0.02290000323275531 0.003999995938598105" rpy="3.141592653589793 2.0539125955565404e-15 -1.5707963267949" />
            <geometry>
                <mesh filename="CAD/bracket_B.stl" scale="0.001 0.001 0.001" />
            </geometry>
        </collision>
    </link>
    <link name="leg_2_tibia">
        <inertial>
            <origin xyz="0.04313437987626397 0.005000003232756968 -0.026581936859366308" rpy="0.0 -0.0 0.0" />
            <mass value="0.16010206435140967" />
            <inertia ixx="2.0005481172803085e-05" iyy="0.00029437779394686763" izz="0.00028180956794589" ixy="2.791820594150174e-17" iyz="-2.041772919356491e-17" ixz="2.971168543152168e-05" />
        </inertial>
        <visual name="leg_2_tibia_visual">
            <origin xyz="0.03800000406140175 0.005000003232755413 -0.0049999968710703595" rpy="3.885780586188056e-15 -2.3055140634511926e-15 1.5707963267948986" />
            <geometry>
                <mesh filename="CAD/tibia.stl" scale="0.001 0.001 0.001" />
            </geometry>
            <material name="gray"/>
        </visual>
        <collision name="leg_2_tibia_collision">
            <origin xyz="0.03800000406140175 0.005000003232755413 -0.0049999968710703595" rpy="3.885780586188056e-15 -2.3055140634511926e-15 1.5707963267948986" />
            <geometry>
                <mesh filename="CAD/tibia.stl" scale="0.001 0.001 0.001" />
            </geometry>
        </collision>
    </link>

    <joint name="base_leg_2_base_coxa_motor" type="fixed">
        <origin xyz="0.08513500406140226 0.005250003232755546 0.0" rpy="0.0 -0.0 -3.141592653589793" />
        <parent link="base" />
        <child link="leg_2_coxa_motor" />
    </joint>
    <joint name="leg_2_coxa_bracket_A_leg_2_coxa_bracket" type="fixed">
        <origin xyz="-0.029999999999999992 -0.005 -0.0453" rpy="3.503246160812043e-46 -1.5707963267948966 0" />
        <parent link="leg_2_coxa_bracket_A" />
        <child link="leg_2_coxa_bracket_B" />
    </joint>
    <joint name="leg_2_coxa" type="revolute">
        <origin xyz="0.014449999999999994 0.00525 0.03106621" rpy="3.0814879110195774e-33 -0.0 -3.503246160812043e-46" />
        <parent link="leg_2_coxa_motor" />
        <child link="leg_2_coxa_bracket_A" />
        <axis xyz="-0.0 -3.0814879110195774e-33 -1.0" />
        <limit lower="-1.570796" upper="1.570796" effort="1000000" velocity="1000000" />
    </joint>
    <joint name="leg_2_femur_bracket_A_leg_2_coxa_bracket_femur_bracket" type="fixed">
        <origin xyz="-0.0040000000000000036 -0.0279 0.01" rpy="1.9721522630525295e-31 -1.5707963267948966 0" />
        <parent link="leg_2_femur_bracket_A" />
        <child link="leg_2_femur_bracket_B" />
    </joint>
    <joint name="leg_2_coxa_bracket_A_leg_2_femur_bracket" type="fixed">
        <origin xyz="-0.033999999999999996 0.005 -0.027400000000000004" rpy="-3.0814879110195774e-33 1.0795210693868056e-78 3.503246160812043e-46" />
        <parent link="leg_2_coxa_bracket_A" />
        <child link="leg_2_femur_bracket_A" />
    </joint>
    <joint name="leg_2_femur" type="revolute">
        <origin xyz="-0.034 0.017400000000000002 0.005" rpy="-6.661338147750937e-16 -1.5707963267948966 0" />
        <parent link="leg_2_femur_bracket_A" />
        <child link="leg_2_femur_motor" />
        <axis xyz="0.0 1.0 6.661338147750937e-16" />
        <limit lower="-1.570796" upper="1.570796" effort="1000000" velocity="1000000" />
    </joint>
    <joint name="leg_2_femur_motor_leg_2_femur_motor_femur" type="fixed">
        <origin xyz="0.00525 -0.031066209999999993 -0.01445000000000002" rpy="1.825139890882535e-46 1.570796326794896 0" />
        <parent link="leg_2_femur_motor" />
        <child link="leg_2_femur" />
    </joint>
    <joint name="leg_2_femur_leg_2_femur_tibia_motor" type="fixed">
        <origin xyz="-0.10559999999999999 0.0 0.0" rpy="-3.141592653589793 -4.52291709077779e-32 9.860761315262648e-32" />
        <parent link="leg_2_femur" />
        <child link="leg_2_tibia_motor" />
    </joint>
    <joint name="leg_2_tibia_bracket_A_leg_2_tibia_bracket" type="fixed">
        <origin xyz="-0.03 -0.0453 0.005000000000000001" rpy="-9.522483540078376e-62 -1.5707963267948966 0" />
        <parent link="leg_2_tibia_bracket_A" />
        <child link="leg_2_tibia_bracket_B" />
    </joint>
    <joint name="leg_2_tibia" type="revolute">
        <origin xyz="0.014450000000000003 -0.03106621 0.00525" rpy="3.141592653589793 1.4537699757513598e-31 9.860761315262648e-32" />
        <parent link="leg_2_tibia_motor" />
        <child link="leg_2_tibia_bracket_A" />
        <axis xyz="0.0 -1.0 -1.9721522630525295e-31" />
        <limit lower="-2.181662" upper="-0.0" effort="1000000" velocity="1000000" />
    </joint>
    <joint name="leg_2_tibia_bracket_A_leg_2_tibia_bracket_tibia" type="fixed">
        <origin xyz="-0.03399999999999999 -0.027400000000000004 0.005000000000000001" rpy="9.860761315262648e-32 -4.8284727900975155e-31 -9.522483540078376e-62" />
        <parent link="leg_2_tibia_bracket_A" />
        <child link="leg_2_tibia" />
    </joint>

    <!-- Leg 3 -->

    <link name="leg_3_coxa_motor">
        <inertial>
            <origin xyz="0.02099909477756648 -0.01357446436833831 0.008369892907608513" rpy="0.0 -0.0 0.0" />
            <mass value="0.029139949883713843" />
            <inertia ixx="5.590577528174812e-06" iyy="5.59057838764681e-06" izz="5.076267786282369e-06" ixy="1.6014937425411425e-06" iyz="4.6931660151654047e-08" ixz="-4.6930327749461454e-08" />
        </inertial>
        <visual name="leg_3_coxa_motor_visual">
            <origin xyz="0.028425694301069965 -0.03478964924005066 -2.9584377996840855e-17" rpy="-3.1415926535897922 -7.606971055477591e-16 2.356194490192342" />
            <geometry>
                <mesh filename="CAD/MG996R.stl" scale="0.001 0.001 0.001" />
            </geometry>
            <material name="gray"/>
        </visual>
        <collision name="leg_3_coxa_motor_collision">
            <origin xyz="0.028425694301069965 -0.03478964924005066 -2.9584377996840855e-17" rpy="-3.1415926535897922 -7.606971055477591e-16 2.356194490192342" />
            <geometry>
                <mesh filename="CAD/MG996R.stl" scale="0.001 0.001 0.001" />
            </geometry>
        </collision>
    </link>
    <link name="leg_3_coxa_bracket_B">
        <inertial>
            <origin xyz="-0.003105251669849143 -0.007454125144238067 -0.014525192438449004" rpy="5.6916151414570475e-61 -0.0 0.0" />
            <mass value="0.004130529991365324" />
            <inertia ixx="7.023383537157267e-07" iyy="3.634528947457471e-07" izz="3.6345289474121016e-07" ixy="-7.6672590018896e-09" iyz="-1.8662911930228187e-07" ixz="-7.66725900219453e-09" />
        </inertial>
        <visual name="leg_3_coxa_bracket_B_visual">
            <origin xyz="0.02290000320343522 0.00636396256775404 -0.0007071047264031982" rpy="-2.3561944901923426 2.809873712853343e-15 3.1415926535897927" />
            <geometry>
                <mesh filename="CAD/bracket_B.stl" scale="0.001 0.001 0.001" />
            </geometry>
            <material name="gray"/>
        </visual>
        <collision name="leg_3_coxa_bracket_B_collision">
            <origin xyz="0.02290000320343522 0.00636396256775404 -0.0007071047264031982" rpy="-2.3561944901923426 2.809873712853343e-15 3.1415926535897927" />
            <geometry>
                <mesh filename="CAD/bracket_B.stl" scale="0.001 0.001 0.001" />
            </geometry>
        </collision>
    </link>
    <link name="leg_3_coxa_bracket_A">
        <inertial>
            <origin xyz="-0.015926416210367868 0.015926413504523892 -0.01095041540115921" rpy="0.0 -0.0 7.670458539527609e-93" />
            <mass value="0.01302030082235085" />
            <inertia ixx="4.456492754702424e-06" iyy="4.456492754704959e-06" izz="2.2212930817996372e-06" ixy="6.781821716646171e-07" iyz="9.764098496048585e-07" ixz="-9.76409849607603e-07" />
        </inertial>
        <visual name="leg_3_coxa_bracket_A_visual">
            <origin xyz="-0.055545471515115075 0.05554546880927237 -0.04320260861218251" rpy="0.7853981633974512 1.5707963267948941 0" />
            <geometry>
                <mesh filename="CAD/bracket_A.stl" scale="0.001 0.001 0.001" />
            </geometry>
            <material name="gray"/>
        </visual>
        <collision name="leg_3_coxa_bracket_A_collision">
            <origin xyz="-0.055545471515115075 0.05554546880927237 -0.04320260861218251" rpy="0.7853981633974512 1.5707963267948941 0" />
            <geometry>
                <mesh filename="CAD/bracket_A.stl" scale="0.001 0.001 0.001" />
            </geometry>
        </collision>
    </link>
    <link name="leg_3_femur_bracket_A">
        <inertial>
            <origin xyz="-0.0035546776903874733 0.01267575827742183 0.005000003203434634" rpy="0.0 -0.0 0.0" />
            <mass value="0.01302030082235085" />
            <inertia ixx="4.380653884167036e-06" iyy="1.6189497806713994e-06" izz="5.134674926367897e-06" ixy="-7.785087506199453e-07" iyz="-2.3547515933669557e-18" ixz="-4.726443845678997e-19" />
        </inertial>
        <visual name="leg_3_femur_bracket_A_visual">
            <origin xyz="0.013258633086707095 -0.04974904155497933 0.005000003203435337" rpy="1.5707963267948983 1.2896663962143594e-15 -2.3561944901923466" />
            <geometry>
                <mesh filename="CAD/bracket_A.stl" scale="0.001 0.001 0.001" />
            </geometry>
            <material name="gray"/>
        </visual>
        <collision name="leg_3_femur_bracket_A_collision">
            <origin xyz="0.013258633086707095 -0.04974904155497933 0.005000003203435337" rpy="1.5707963267948983 1.2896663962143594e-15 -2.3561944901923466" />
            <geometry>
                <mesh filename="CAD/bracket_A.stl" scale="0.001 0.001 0.001" />
            </geometry>
        </collision>
    </link>
    <link name="leg_3_femur_bracket_B">
        <inertial>
            <origin xyz="-0.004999996796526915 0.008793918212389116 0.013185405052999625" rpy="-7.235508984711272e-61 -0.0 0.0" />
            <mass value="0.004130529991365324" />
            <inertia ixx="5.500820140457686e-07" iyy="4.5042420624539126e-07" izz="4.2873792291154694e-07" ixy="-1.4556261198565147e-18" iyz="-2.627572891372538e-07" ixz="-1.755899299658164e-18" />
        </inertial>
        <visual name="leg_3_femur_bracket_B_visual">
            <origin xyz="-0.004999996796564827 0.013364322567754012 -0.019021174726403203" rpy="3.862897684400556e-15 -0.7853981633974502 -1.5707963267948983" />
            <geometry>
                <mesh filename="CAD/bracket_B.stl" scale="0.001 0.001 0.001" />
            </geometry>
            <material name="gray"/>
        </visual>
        <collision name="leg_3_femur_bracket_B_collision">
            <origin xyz="-0.004999996796564827 0.013364322567754012 -0.019021174726403203" rpy="3.862897684400556e-15 -0.7853981633974502 -1.5707963267948983" />
            <geometry>
                <mesh filename="CAD/bracket_B.stl" scale="0.001 0.001 0.001" />
            </geometry>
        </collision>
    </link>
    <link name="leg_3_femur_motor">
        <inertial>
            <origin xyz="5.406123213536063e-09 -0.008979639029200417 0.023117813857807014" rpy="9.860761315262648e-32 -0.0 0.0" />
            <mass value="0.029139949883713843" />
            <inertia ixx="7.1920717004519365e-06" iyy="4.466305552685483e-06" izz="4.599046448966512e-06" ixy="3.6233184828133855e-13" iyz="-5.435917854562894e-07" ixz="-9.700703510872454e-13" />
        </inertial>
        <visual name="leg_3_femur_motor_visual">
            <origin xyz="-0.009749996796564733 -0.0005771548643676461 0.043357114088190145" rpy="-4.102986532631015e-15 0.7853981633974478 -1.5707963267948943" />
            <geometry>
                <mesh filename="CAD/MG996R.stl" scale="0.001 0.001 0.001" />
            </geometry>
            <material name="gray"/>
        </visual>
        <collision name="leg_3_femur_motor_collision">
            <origin xyz="-0.009749996796564733 -0.0005771548643676461 0.043357114088190145" rpy="-4.102986532631015e-15 0.7853981633974478 -1.5707963267948943" />
            <geometry>
                <mesh filename="CAD/MG996R.stl" scale="0.001 0.001 0.001" />
            </geometry>
        </collision>
    </link>
    <link name="leg_3_femur">
        <inertial>
            <origin xyz="-0.03233102065800832 0.04233945842106165 -0.005249996796564788" rpy="0.0 -0.0 0.0" />
            <mass value="0.021802151943504742" />
            <inertia ixx="1.5076488302836143e-05" iyy="1.5076488302836794e-05" izz="2.5188056838580165e-05" ixy="1.2232457663466194e-05" iyz="2.0328790734103398e-20" ixz="-2.032879073410312e-20" />
        </inertial>
        <visual name="leg_3_femur_visual">
            <origin xyz="-0.047588287343005985 0.06738727826367169 -0.0052499967965648695" rpy="1.5707963267948986 -1.5804414278766462e-15 -0.7853981633974498" />
            <geometry>
                <mesh filename="CAD/femur.stl" scale="0.001 0.001 0.001" />
            </geometry>
            <material name="gray"/>
        </visual>
        <collision name="leg_3_femur_collision">
            <origin xyz="-0.047588287343005985 0.06738727826367169 -0.0052499967965648695" rpy="1.5707963267948986 -1.5804414278766462e-15 -0.7853981633974498" />
            <geometry>
                <mesh filename="CAD/femur.stl" scale="0.001 0.001 0.001" />
            </geometry>
        </collision>
    </link>
    <link name="leg_3_tibia_motor">
        <inertial>
            <origin xyz="0.023205191891754958 0.011368374778762238 0.005249998999252789" rpy="0.0 -0.0 0.0" />
            <mass value="0.029139949883713843" />
            <inertia ixx="4.466305552685429e-06" iyy="4.599046448966514e-06" izz="7.192071700451615e-06" ixy="-5.43591785456452e-07" iyz="-9.700703714160368e-13" ixz="3.62331848281338e-13" />
        </inertial>
        <visual name="leg_3_tibia_motor_visual">
            <origin xyz="0.03160767605658764 0.03160767500914538 -0.004500003203435128" rpy="1.5707963267948946 -1.4579767479619083e-15 -2.3561944901923426" />
            <geometry>
                <mesh filename="CAD/MG996R.stl" scale="0.001 0.001 0.001" />
            </geometry>
            <material name="gray"/>
        </visual>
        <collision name="leg_3_tibia_motor_collision">
            <origin xyz="0.03160767605658764 0.03160767500914538 -0.004500003203435128" rpy="1.5707963267948946 -1.4579767479619083e-15 -2.3561944901923426" />
            <geometry>
                <mesh filename="CAD/MG996R.stl" scale="0.001 0.001 0.001" />
            </geometry>
        </collision>
    </link>
    <link name="leg_3_tibia_bracket_A">
        <inertial>
            <origin xyz="-0.023669530801622436 0.008183291388657032 3.203435771093055e-09" rpy="0.0 -0.0 -5.001342253538141e-90" />
            <mass value="0.01302030082235085" />
            <inertia ixx="1.6189497806713173e-06" iyy="4.3806538841671444e-06" izz="5.13467492636757e-06" ixy="-7.78508750619918e-07" iyz="5.183841637196318e-19" ixz="2.3954091748351614e-18" />
        </inertial>
        <visual name="leg_3_tibia_bracket_A_visual">
            <origin xyz="-0.08609433063402368 0.024996602165751832 3.203434947307571e-09" rpy="-1.570796326794895 2.6216440076822105e-15 -2.3561944901923457" />
            <geometry>
                <mesh filename="CAD/bracket_A.stl" scale="0.001 0.001 0.001" />
            </geometry>
            <material name="gray"/>
        </visual>
        <collision name="leg_3_tibia_bracket_A_collision">
            <origin xyz="-0.08609433063402368 0.024996602165751832 3.203434947307571e-09" rpy="-1.570796326794895 2.6216440076822105e-15 -2.3561944901923457" />
            <geometry>
                <mesh filename="CAD/bracket_A.stl" scale="0.001 0.001 0.001" />
            </geometry>
        </collision>
    </link>
    <link name="leg_3_tibia_bracket_B">
        <inertial>
            <origin xyz="-0.004999996796602591 -0.013185405973954971 -0.008793909133344577" rpy="0.0 8.758115402030107e-47 0.0" />
            <mass value="0.004130529991365324" />
            <inertia ixx="5.500820140457146e-07" iyy="4.2873792291154027e-07" izz="4.5042420624530994e-07" ixy="-1.749970069027384e-18" iyz="-2.6275728913727415e-07" ixz="-1.4594377681191595e-18" />
        </inertial>
        <visual name="leg_3_tibia_bracket_B_visual">
            <origin xyz="-0.004999996796564567 0.019021173805447874 -0.013364313488709598" rpy="-3.14159265358979 -0.7853981633974491 -1.570796326794902" />
            <geometry>
                <mesh filename="CAD/bracket_B.stl" scale="0.001 0.001 0.001" />
            </geometry>
            <material name="gray"/>
        </visual>
        <collision name="leg_3_tibia_bracket_B_collision">
            <origin xyz="-0.004999996796564567 0.019021173805447874 -0.013364313488709598" rpy="-3.14159265358979 -0.7853981633974491 -1.570796326794902" />
            <geometry>
                <mesh filename="CAD/bracket_B.stl" scale="0.001 0.001 0.001" />
            </geometry>
        </collision>
    </link>
    <link name="leg_3_tibia">
        <inertial>
            <origin xyz="0.03403614312964887 -0.026965075835489183 -0.026581936859366603" rpy="0.0 -3.503246160812043e-46 0.0" />
            <mass value="0.02243468417663065" />
            <inertia ixx="2.2026853670809032e-05" iyy="2.2026853670800894e-05" izz="3.948923882044343e-05" ixy="1.9223537837673336e-05" iyz="-2.9439831431894466e-06" ixz="2.9439831431853813e-06" />
        </inertial>
        <visual name="leg_3_tibia_visual">
            <origin xyz="0.030405591173798447 -0.02333452387964094 -0.004999996871070658" rpy="2.107293400828271e-15 -2.1649983278424786e-15 0.7853981633974474" />
            <geometry>
                <mesh filename="CAD/tibia.stl" scale="0.001 0.001 0.001" />
            </geometry>
            <material name="gray"/>
        </visual>
        <collision name="leg_3_tibia_collision">
            <origin xyz="0.030405591173798447 -0.02333452387964094 -0.004999996871070658" rpy="2.107293400828271e-15 -2.1649983278424786e-15 0.7853981633974474" />
            <geometry>
                <mesh filename="CAD/tibia.stl" scale="0.001 0.001 0.001" />
            </geometry>
        </collision>
    </link>

    <joint name="base_leg_3_base_coxa_motor" type="fixed">
        <origin xyz="0.07081356406140228 -0.08875393676724434 0.0" rpy="0.0 -0.0 -3.141592653589793" />
        <parent link="base" />
        <child link="leg_3_coxa_motor" />
    </joint>
    <joint name="leg_3_coxa_bracket_A_leg_3_coxa_bracket" type="fixed">
        <origin xyz="-0.02474874000000001 0.017677669999999993 -0.045300000000000014" rpy="5.917287137060639e-77 -1.5707963267948966 0" />
        <parent link="leg_3_coxa_bracket_A" />
        <child link="leg_3_coxa_bracket_B" />
    </joint>
    <joint name="leg_3_coxa" type="revolute">
        <origin xyz="0.013930010000000008 -0.006505379999999992 0.03106621" rpy="-1.97215226305253e-31 -9.860761315262648e-32 -5.9172871370606394e-77" />
        <parent link="leg_3_coxa_motor" />
        <child link="leg_3_coxa_bracket_A" />
        <axis xyz="-9.860761315262648e-32 1.9721522630525295e-31 -0.9999999999999999" />
        <limit lower="-1.570796" upper="1.570796" effort="1000000" velocity="1000000" />
    </joint>
    <joint name="leg_3_femur_bracket_A_leg_3_coxa_bracket_femur_bracket" type="fixed">
        <origin xyz="-0.022556710000000004 -0.016899859999999992 0.01" rpy="-5.122504467411497e-60 -1.5707963267948966 0" />
        <parent link="leg_3_femur_bracket_A" />
        <child link="leg_3_femur_bracket_B" />
    </joint>
    <joint name="leg_3_coxa_bracket_A_leg_3_femur_bracket" type="fixed">
        <origin xyz="-0.020506100000000006 0.027577169999999995 -0.02740000000000001" rpy="3.083206966439695e-30 9.86076131526265e-32 5.91728713706064e-77" />
        <parent link="leg_3_coxa_bracket_A" />
        <child link="leg_3_femur_bracket_A" />
    </joint>
    <joint name="leg_3_femur" type="revolute">
        <origin xyz="-0.011737969999999995 0.03634529000000001 0.004999999999999999" rpy="-6.661338147750938e-16 -1.5707963267948966 0" />
        <parent link="leg_3_femur_bracket_A" />
        <child link="leg_3_femur_motor" />
        <axis xyz="2.3153571502507704e-30 0.7071070000000005 -0.7071069999999995" />
        <limit lower="-1.570796" upper="1.570796" effort="1000000" velocity="1000000" />
    </joint>
    <joint name="leg_3_femur_motor_leg_3_femur_motor_femur" type="fixed">
        <origin xyz="0.005250000000000001 -0.032184830000000025 0.011749439999999965" rpy="-6.699958282553032e-45 1.570796326794896 0" />
        <parent link="leg_3_femur_motor" />
        <child link="leg_3_femur" />
    </joint>
    <joint name="leg_3_femur_leg_3_femur_tibia_motor" type="fixed">
        <origin xyz="-0.07467048 0.07467048 0.0" rpy="3.141592653589793 -1.5122655203048314e-30 5.9648357364109684e-61" />
        <parent link="leg_3_femur" />
        <child link="leg_3_tibia_motor" />
    </joint>
    <joint name="leg_3_tibia_bracket_A_leg_3_tibia_bracket" type="fixed">
        <origin xyz="-0.05324514000000001 -0.010818739999999992 0.005000000000000001" rpy="-1.97215226305253e-31 -1.5707963267948966 0" />
        <parent link="leg_3_tibia_bracket_A" />
        <child link="leg_3_tibia_bracket_B" />
    </joint>
    <joint name="leg_3_tibia" type="revolute">
        <origin xyz="0.03218482999999999 -0.01174944 0.00525" rpy="-3.141592653589793 4.759319555259378e-30 -1.9721522630525295e-31" />
        <parent link="leg_3_tibia_motor" />
        <child link="leg_3_tibia_bracket_A" />
        <axis xyz="-0.707107 -0.707107 1.0126468723405223e-29" />
        <limit lower="-2.181662" upper="-0.0" effort="1000000" velocity="1000000" />
    </joint>
    <joint name="leg_3_tibia_bracket_A_leg_3_tibia_bracket_tibia" type="fixed">
        <origin xyz="-0.04341635999999998 0.004666899999999998 0.005000000000000001" rpy="-3.9443045261050586e-31 4.8943502200252996e-30 -1.9721522630525295e-31" />
        <parent link="leg_3_tibia_bracket_A" />
        <child link="leg_3_tibia" />
    </joint>

    <!-- Leg 4 -->

    <link name="leg_4_coxa_motor">
        <inertial>
            <origin xyz="-0.013574473539690662 -0.020999097483409414 0.008369892907608513" rpy="0.0 -0.0 0.0" />
            <mass value="0.029139949883713843" />
            <inertia ixx="5.5905783876468375e-06" iyy="5.590577528174812e-06" izz="5.076267786282478e-06" ixy="-1.601493742541129e-06" iyz="4.6930327749461454e-08" ixz="4.6931660151654047e-08" />
        </inertial>
        <visual name="leg_4_coxa_motor_visual">
            <origin xyz="-0.03478965841140303 -0.028425697006912855 -2.958437799684087e-17" rpy="-3.1415926535897922 -7.606971055477591e-16 0.7853981633974432" />
            <geometry>
                <mesh filename="CAD/MG996R.stl" scale="0.001 0.001 0.001" />
            </geometry>
            <material name="gray"/>
        </visual>
        <collision name="leg_4_coxa_motor_collision">
            <origin xyz="-0.03478965841140303 -0.028425697006912855 -2.958437799684087e-17" rpy="-3.1415926535897922 -7.606971055477591e-16 0.7853981633974432" />
            <geometry>
                <mesh filename="CAD/MG996R.stl" scale="0.001 0.001 0.001" />
            </geometry>
        </collision>
    </link>
    <link name="leg_4_coxa_bracket_B">
        <inertial>
            <origin xyz="-0.003105251669849145 -0.014525195144291967 0.007454124315590365" rpy="0.0 -0.0 0.0" />
            <mass value="0.004130529991365324" />
            <inertia ixx="7.023383537157199e-07" iyy="3.6345289474121037e-07" izz="3.634528947457435e-07" ixy="-7.667259002194532e-09" iyz="1.866291193022751e-07" ixz="7.667259001890445e-09" />
        </inertial>
        <visual name="leg_4_coxa_bracket_B_visual">
            <origin xyz="0.022900003203435215 -0.0007071074322461791 -0.00636396339640176" rpy="-0.7853981633974427 6.414614657916649e-16 -3.1415926535897905" />
            <geometry>
                <mesh filename="CAD/bracket_B.stl" scale="0.001 0.001 0.001" />
            </geometry>
            <material name="gray"/>
        </visual>
        <collision name="leg_4_coxa_bracket_B_collision">
            <origin xyz="0.022900003203435215 -0.0007071074322461791 -0.00636396339640176" rpy="-0.7853981633974427 6.414614657916649e-16 -3.1415926535897905" />
            <geometry>
                <mesh filename="CAD/bracket_B.stl" scale="0.001 0.001 0.001" />
            </geometry>
        </collision>
    </link>
    <link name="leg_4_coxa_bracket_A">
        <inertial>
            <origin xyz="0.01592641433317164 0.015926413504524888 -0.01095041540115921" rpy="0.0 -0.0 0.0" />
            <mass value="0.01302030082235085" />
            <inertia ixx="4.456492754704972e-06" iyy="4.456492754702397e-06" izz="2.221293081799556e-06" ixy="-6.781821716645765e-07" iyz="9.764098496075995e-07" ixz="9.76409849604872e-07" />
        </inertial>
        <visual name="leg_4_coxa_bracket_A_visual">
            <origin xyz="0.05554546963792019 0.05554546880927202 -0.04320260861218251" rpy="2.35619449019235 1.5707963267948941 0" />
            <geometry>
                <mesh filename="CAD/bracket_A.stl" scale="0.001 0.001 0.001" />
            </geometry>
            <material name="gray"/>
        </visual>
        <collision name="leg_4_coxa_bracket_A_collision">
            <origin xyz="0.05554546963792019 0.05554546880927202 -0.04320260861218251" rpy="2.35619449019235 1.5707963267948941 0" />
            <geometry>
                <mesh filename="CAD/bracket_A.stl" scale="0.001 0.001 0.001" />
            </geometry>
        </collision>
    </link>
    <link name="leg_4_femur_bracket_A">
        <inertial>
            <origin xyz="0.012675759106069525 0.0035546749845444124 0.005000003203434637" rpy="0.0 -0.0 0.0" />
            <mass value="0.01302030082235085" />
            <inertia ixx="1.6189497806714257e-06" iyy="4.380653884166929e-06" izz="5.134674926367897e-06" ixy="7.785087506199182e-07" iyz="4.692562527788826e-19" ixz="-2.3530575274724467e-18" />
        </inertial>
        <visual name="leg_4_femur_bracket_A_visual">
            <origin xyz="-0.049749040726331684 -0.013258635792550013 0.005000003203435339" rpy="1.5707963267948983 1.2896663962143636e-15 2.356194490192341" />
            <geometry>
                <mesh filename="CAD/bracket_A.stl" scale="0.001 0.001 0.001" />
            </geometry>
            <material name="gray"/>
        </visual>
        <collision name="leg_4_femur_bracket_A_collision">
            <origin xyz="-0.049749040726331684 -0.013258635792550013 0.005000003203435339" rpy="1.5707963267948983 1.2896663962143636e-15 2.356194490192341" />
            <geometry>
                <mesh filename="CAD/bracket_A.stl" scale="0.001 0.001 0.001" />
            </geometry>
        </collision>
    </link>
    <link name="leg_4_femur_bracket_B">
        <inertial>
            <origin xyz="-0.004999996796526911 0.013185412347156653 -0.008793909041036906" rpy="0.0 -0.0 0.0" />
            <mass value="0.004130529991365324" />
            <inertia ixx="5.500820140457555e-07" iyy="4.2873792291154736e-07" izz="4.5042420624536436e-07" ixy="-1.755052266710911e-18" iyz="2.6275728913726075e-07" ixz="1.456049636330143e-18" />
        </inertial>
        <visual name="leg_4_femur_bracket_B_visual">
            <origin xyz="-0.0049999967965648215 -0.019021167432246175 -0.013364313396401739" rpy="3.1415926535897913 -0.7853981633974443 1.5707963267948983" />
            <geometry>
                <mesh filename="CAD/bracket_B.stl" scale="0.001 0.001 0.001" />
            </geometry>
            <material name="gray"/>
        </visual>
        <collision name="leg_4_femur_bracket_B_collision">
            <origin xyz="-0.0049999967965648215 -0.019021167432246175 -0.013364313396401739" rpy="3.1415926535897913 -0.7853981633974443 1.5707963267948983" />
            <geometry>
                <mesh filename="CAD/bracket_B.stl" scale="0.001 0.001 0.001" />
            </geometry>
        </collision>
    </link>
    <link name="leg_4_femur_motor">
        <inertial>
            <origin xyz="5.4061232124258395e-09 0.02311781115196398 0.008979638200552564" rpy="-9.860761315262648e-32 -0.0 0.0" />
            <mass value="0.029139949883713843" />
            <inertia ixx="7.1920717004517265e-06" iyy="4.59904644896657e-06" izz="4.466305552685431e-06" ixy="-9.700703443109827e-13" iyz="5.435917854563981e-07" ixz="-3.6233184150507527e-13" />
        </inertial>
        <visual name="leg_4_femur_motor_visual">
            <origin xyz="-0.009749996796564728 0.043357111382347074 0.0005771540357197757" rpy="9.798572316089862e-15 -0.785398163397451 -1.5707963267948943" />
            <geometry>
                <mesh filename="CAD/MG996R.stl" scale="0.001 0.001 0.001" />
            </geometry>
            <material name="gray"/>
        </visual>
        <collision name="leg_4_femur_motor_collision">
            <origin xyz="-0.009749996796564728 0.043357111382347074 0.0005771540357197757" rpy="9.798572316089862e-15 -0.785398163397451 -1.5707963267948943" />
            <geometry>
                <mesh filename="CAD/MG996R.stl" scale="0.001 0.001 0.001" />
            </geometry>
        </collision>
    </link>
    <link name="leg_4_femur">
        <inertial>
            <origin xyz="0.04233945924970957 0.03233101795216527 -0.005249996796564788" rpy="0.0 -0.0 1.775240694593387e-60" />
            <mass value="0.021802151943504742" />
            <inertia ixx="1.507648830283701e-05" iyy="1.507648830283619e-05" izz="2.5188056838580056e-05" ixy="-1.2232457663466245e-05" iyz="2.0328790734103064e-20" ixz="2.3716922523120497e-20" />
        </inertial>
        <visual name="leg_4_femur_visual">
            <origin xyz="0.06738727909231963 0.04758828463716288 -0.0052499967965648695" rpy="1.5707963267948986 -1.580441427876639e-15 -2.3561944901923484" />
            <geometry>
                <mesh filename="CAD/femur.stl" scale="0.001 0.001 0.001" />
            </geometry>
            <material name="gray"/>
        </visual>
        <collision name="leg_4_femur_collision">
            <origin xyz="0.06738727909231963 0.04758828463716288 -0.0052499967965648695" rpy="1.5707963267948986 -1.580441427876639e-15 -2.3561944901923484" />
            <geometry>
                <mesh filename="CAD/femur.stl" scale="0.001 0.001 0.001" />
            </geometry>
        </collision>
    </link>
    <link name="leg_4_tibia_motor">
        <inertial>
            <origin xyz="-0.011368373950114297 0.02320518459759807 0.005249998999252789" rpy="0.0 -0.0 0.0" />
            <mass value="0.029139949883713843" />
            <inertia ixx="4.599046448966731e-06" iyy="4.466305552685429e-06" izz="7.192071700452265e-06" ixy="5.435917854563436e-07" iyz="3.623318415050744e-13" ixz="9.700703646397732e-13" />
        </inertial>
        <visual name="leg_4_tibia_motor_visual">
            <origin xyz="-0.03160767418049747 0.0316076687624307 -0.004500003203435128" rpy="1.5707963267948946 -1.457976747961905e-15 -0.7853981633974437" />
            <geometry>
                <mesh filename="CAD/MG996R.stl" scale="0.001 0.001 0.001" />
            </geometry>
            <material name="gray"/>
        </visual>
        <collision name="leg_4_tibia_motor_collision">
            <origin xyz="-0.03160767418049747 0.0316076687624307 -0.004500003203435128" rpy="1.5707963267948946 -1.457976747961905e-15 -0.7853981633974437" />
            <geometry>
                <mesh filename="CAD/MG996R.stl" scale="0.001 0.001 0.001" />
            </geometry>
        </collision>
    </link>
    <link name="leg_4_tibia_bracket_A">
        <inertial>
            <origin xyz="0.008183292217304867 0.02366952809577928 3.203435767762386e-09" rpy="0.0 -0.0 0.0" />
            <mass value="0.01302030082235085" />
            <inertia ixx="4.380653884166982e-06" iyy="1.6189497806713173e-06" izz="5.134674926367678e-06" ixy="7.78508750619918e-07" iyz="-2.3987973066241786e-18" ixz="5.183841637196317e-19" />
        </inertial>
        <visual name="leg_4_tibia_bracket_A_visual">
            <origin xyz="0.02499660299439981 0.08609432792818048 3.203434945087125e-09" rpy="-1.570796326794895 2.621644007682211e-15 2.356194490192342" />
            <geometry>
                <mesh filename="CAD/bracket_A.stl" scale="0.001 0.001 0.001" />
            </geometry>
            <material name="gray"/>
        </visual>
        <collision name="leg_4_tibia_bracket_A_collision">
            <origin xyz="0.02499660299439981 0.08609432792818048 3.203434945087125e-09" rpy="-1.570796326794895 2.621644007682211e-15 2.356194490192342" />
            <geometry>
                <mesh filename="CAD/bracket_A.stl" scale="0.001 0.001 0.001" />
            </geometry>
        </collision>
    </link>
    <link name="leg_4_tibia_bracket_B">
        <inertial>
            <origin xyz="-0.004999996796602591 -0.0087939118391877 0.01318540514530703" rpy="0.0 -0.0 0.0" />
            <mass value="0.004130529991365324" />
            <inertia ixx="5.500820140457146e-07" iyy="4.504242062453777e-07" izz="4.287379229115404e-07" ixy="-1.4602848010664138e-18" iyz="2.627572891372471e-07" ixz="1.748276003132876e-18" />
        </inertial>
        <visual name="leg_4_tibia_bracket_B_visual">
            <origin xyz="-0.004999996796564567 -0.013364316194552792 -0.019021174634095816" rpy="1.0249567968129637e-15 -0.7853981633974453 1.570796326794902" />
            <geometry>
                <mesh filename="CAD/bracket_B.stl" scale="0.001 0.001 0.001" />
            </geometry>
            <material name="gray"/>
        </visual>
        <collision name="leg_4_tibia_bracket_B_collision">
            <origin xyz="-0.004999996796564567 -0.013364316194552792 -0.019021174634095816" rpy="1.0249567968129637e-15 -0.7853981633974453 1.570796326794902" />
            <geometry>
                <mesh filename="CAD/bracket_B.stl" scale="0.001 0.001 0.001" />
            </geometry>
        </collision>
    </link>
    <link name="leg_4_tibia">
        <inertial>
            <origin xyz="-0.026965075006841345 -0.03403614583549203 -0.026581936859366603" rpy="0.0 -0.0 0.0" />
            <mass value="0.02243468417663065" />
            <inertia ixx="2.2026853670800792e-05" iyy="2.202685367080914e-05" izz="3.948923882044343e-05" ixy="-1.922353783767323e-05" iyz="-2.9439831431853745e-06" ixz="-2.9439831431894402e-06" />
        </inertial>
        <visual name="leg_4_tibia_visual">
            <origin xyz="-0.023334523050993105 -0.03040559387964162 -0.004999996871070658" rpy="2.1072934008282753e-15 -2.164998327842479e-15 -0.7853981633974515" />
            <geometry>
                <mesh filename="CAD/tibia.stl" scale="0.001 0.001 0.001" />
            </geometry>
            <material name="gray"/>
        </visual>
        <collision name="leg_4_tibia_collision">
            <origin xyz="-0.023334523050993105 -0.03040559387964162 -0.004999996871070658" rpy="2.1072934008282753e-15 -2.164998327842479e-15 -0.7853981633974515" />
            <geometry>
                <mesh filename="CAD/tibia.stl" scale="0.001 0.001 0.001" />
            </geometry>
        </collision>
    </link>

    <joint name="base_leg_4_base_coxa_motor" type="fixed">
        <origin xyz="-0.06338894593859754 -0.09617856676724434 0.0" rpy="0.0 -0.0 -3.141592653589793" />
        <parent link="base" />
        <child link="leg_4_coxa_motor" />
    </joint>
    <joint name="leg_4_coxa_bracket_A_leg_4_coxa_bracket" type="fixed">
        <origin xyz="0.017677670000000003 0.024748739999999998 -0.045300000000000014" rpy="2.127796654039258e-61 -1.5707963267948966 0" />
        <parent link="leg_4_coxa_bracket_A" />
        <child link="leg_4_coxa_bracket_B" />
    </joint>
    <joint name="leg_4_coxa" type="revolute">
        <origin xyz="-0.006505390000000002 -0.01393001 0.03106621" rpy="-1.97215226305253e-31 -1.9721522630525295e-31 -2.1277966540392582e-61" />
        <parent link="leg_4_coxa_motor" />
        <child link="leg_4_coxa_bracket_A" />
        <axis xyz="-1.9721522630525295e-31 1.9721522630525295e-31 -0.9999999999999999" />
        <limit lower="-1.570796" upper="1.570796" effort="1000000" velocity="1000000" />
    </joint>
    <joint name="leg_4_femur_bracket_A_leg_4_coxa_bracket_femur_bracket" type="fixed">
        <origin xyz="-0.01689984999999999 0.022556700000000002 0.01" rpy="1.972152263052529e-31 -1.5707963267948966 0" />
        <parent link="leg_4_femur_bracket_A" />
        <child link="leg_4_femur_bracket_B" />
    </joint>
    <joint name="leg_4_coxa_bracket_A_leg_4_femur_bracket" type="fixed">
        <origin xyz="0.027577169999999995 0.02050609999999999 -0.02740000000000001" rpy="3.0832069664396943e-30 -0.0 2.1277966540392582e-61" />
        <parent link="leg_4_coxa_bracket_A" />
        <child link="leg_4_femur_bracket_A" />
    </joint>
    <joint name="leg_4_femur" type="revolute">
        <origin xyz="0.03634529000000001 0.011737970000000023 0.004999999999999999" rpy="-6.661338147750937e-16 -1.5707963267948966 0" />
        <parent link="leg_4_femur_bracket_A" />
        <child link="leg_4_femur_motor" />
        <axis xyz="2.5942616843048273e-30 -0.7071069999999997 -0.7071070000000006" />
        <limit lower="-1.570796" upper="1.570796" effort="1000000" velocity="1000000" />
    </joint>
    <joint name="leg_4_femur_motor_leg_4_femur_motor_femur" type="fixed">
        <origin xyz="0.00525 0.011749439999999946 0.03218482999999999" rpy="-3.944304526105126e-31 1.570796326794896 0" />
        <parent link="leg_4_femur_motor" />
        <child link="leg_4_femur" />
    </joint>
    <joint name="leg_4_femur_leg_4_femur_tibia_motor" type="fixed">
        <origin xyz="0.07467048 0.07467047000000002 0.0" rpy="3.141592653589793 -1.5122655203048314e-30 1.97215226305253e-31" />
        <parent link="leg_4_femur" />
        <child link="leg_4_tibia_motor" />
    </joint>
    <joint name="leg_4_tibia_bracket_A_leg_4_tibia_bracket" type="fixed">
        <origin xyz="-0.010818739999999992 0.05324514000000001 0.005000000000000001" rpy="-0.0 -1.5707963267948966 0" />
        <parent link="leg_4_tibia_bracket_A" />
        <child link="leg_4_tibia_bracket_B" />
    </joint>
    <joint name="leg_4_tibia" type="revolute">
        <origin xyz="0.01174944 0.03218482000000002 0.00525" rpy="-3.141592653589793 4.759319555259376e-30 0.0" />
        <parent link="leg_4_tibia_motor" />
        <child link="leg_4_tibia_bracket_A" />
        <axis xyz="-0.707107 0.707107 1.0126468723405218e-29" />
        <limit lower="-2.181662" upper="-0.0" effort="1000000" velocity="1000000" />
    </joint>
    <joint name="leg_4_tibia_bracket_A_leg_4_tibia_bracket_tibia" type="fixed">
        <origin xyz="0.004666899999999998 0.043416360000000015 0.005000000000000001" rpy="-1.9721522630525295e-31 4.894350220025299e-30 0.0" />
        <parent link="leg_4_tibia_bracket_A" />
        <child link="leg_4_tibia" />
    </joint>

    <!-- Leg 5 -->

    <link name="leg_5_coxa_motor">
        <inertial>
            <origin xyz="-0.02444719596745717 -0.005249998969932374 0.008369892907608513" rpy="0.0 -0.0 0.0" />
            <mass value="0.029139949883713843" />
            <inertia ixx="3.989084215369667e-06" iyy="7.192071700451967e-06" izz="5.076267786282396e-06" ixy="-4.2973601251862395e-13" iyz="-9.421506252509996e-13" ixz="6.637044814053067e-08" />
        </inertial>
        <visual name="leg_5_coxa_motor_visual">
            <origin xyz="-0.04469999593859735 0.004500003232755534 -2.958437799684087e-17" rpy="-3.1415926535897922 -7.60697105547759e-16 -1.6653345369377427e-16" />
            <geometry>
                <mesh filename="CAD/MG996R.stl" scale="0.001 0.001 0.001" />
            </geometry>
            <material name="gray"/>
        </visual>
        <collision name="leg_5_coxa_motor_collision">
            <origin xyz="-0.04469999593859735 0.004500003232755534 -2.958437799684087e-17" rpy="-3.1415926535897922 -7.60697105547759e-16 -1.6653345369377427e-16" />
            <geometry>
                <mesh filename="CAD/MG996R.stl" scale="0.001 0.001 0.001" />
            </geometry>
        </collision>
    </link>
    <link name="leg_5_coxa_bracket_B">
        <inertial>
            <origin xyz="-0.003105251669849145 -0.004999996767282532 0.015541722986995535" rpy="0.0 -0.0 0.0" />
            <mass value="0.004130529991365324" />
            <inertia ixx="7.023383537157265e-07" iyy="5.50082014045762e-07" izz="1.7682377544119818e-07" ixy="-2.1510666393318974e-19" iyz="2.271001210707186e-18" ixz="1.0843141666916124e-08" />
        </inertial>
        <visual name="leg_5_coxa_bracket_B_visual">
            <origin xyz="0.022900003203435226 -0.004999996767244498 -0.004000004061402685" rpy="-3.330669073875465e-16 -1.53329900430526e-15 -3.141592653589791" />
            <geometry>
                <mesh filename="CAD/bracket_B.stl" scale="0.001 0.001 0.001" />
            </geometry>
            <material name="gray"/>
        </visual>
        <collision name="leg_5_coxa_bracket_B_collision">
            <origin xyz="0.022900003203435226 -0.004999996767244498 -0.004000004061402685" rpy="-3.330669073875465e-16 -1.53329900430526e-15 -3.141592653589791" />
            <geometry>
                <mesh filename="CAD/bracket_B.stl" scale="0.001 0.001 0.001" />
            </geometry>
        </collision>
    </link>
    <link name="leg_5_coxa_bracket_A">
        <inertial>
            <origin xyz="0.022523351200554886 3.2327563137535266e-09 -0.010950415401159206" rpy="0.0 -0.0 0.0" />
            <mass value="0.01302030082235085" />
            <inertia ixx="3.7783105830390803e-06" iyy="5.134674926368275e-06" izz="2.221293081799543e-06" ixy="-1.3078188705606397e-18" iyz="1.9369525921337713e-18" ixz="1.3808520517478153e-06" />
        </inertial>
        <visual name="leg_5_coxa_bracket_A_visual">
            <origin xyz="0.07855315654093899 3.2327555912758933e-09 -0.043202608612182496" rpy="-3.141592653589793 1.5707963267948941 0" />
            <geometry>
                <mesh filename="CAD/bracket_A.stl" scale="0.001 0.001 0.001" />
            </geometry>
            <material name="gray"/>
        </visual>
        <collision name="leg_5_coxa_bracket_A_collision">
            <origin xyz="0.07855315654093899 3.2327555912758933e-09 -0.043202608612182496" rpy="-3.141592653589793 1.5707963267948941 0" />
            <geometry>
                <mesh filename="CAD/bracket_A.stl" scale="0.001 0.001 0.001" />
            </geometry>
        </collision>
    </link>
    <link name="leg_5_femur_bracket_A">
        <inertial>
            <origin xyz="0.011476656922250169 -0.006449578162649977 0.005000003203434642" rpy="0.0 -0.0 0.0" />
            <mass value="0.01302030082235085" />
            <inertia ixx="3.7783105830391124e-06" iyy="2.2212930817992857e-06" izz="5.134674926367895e-06" ixy="1.380852051747768e-06" iyz="1.9970919313888266e-18" ixz="-1.328147661294743e-18" />
        </inertial>
        <visual name="leg_5_femur_bracket_A_visual">
            <origin xyz="-0.04455314841813406 0.02580261504837317 0.005000003203435345" rpy="1.5707963267948983 1.2896663962143616e-15 1.5707963267948977" />
            <geometry>
                <mesh filename="CAD/bracket_A.stl" scale="0.001 0.001 0.001" />
            </geometry>
            <material name="gray"/>
        </visual>
        <collision name="leg_5_femur_bracket_A_collision">
            <origin xyz="-0.04455314841813406 0.02580261504837317 0.005000003203435345" rpy="1.5707963267948983 1.2896663962143616e-15 1.5707963267948977" />
            <geometry>
                <mesh filename="CAD/bracket_A.stl" scale="0.001 0.001 0.001" />
            </geometry>
        </collision>
    </link>
    <link name="leg_5_femur_bracket_B">
        <inertial>
            <origin xyz="-0.004999996796526911 0.0031052581060398853 -0.015541731109800878" rpy="0.0 -0.0 0.0" />
            <mass value="0.004130529991365324" />
            <inertia ixx="5.500820140457553e-07" iyy="7.023383537157129e-07" izz="1.7682377544120856e-07" ixy="-2.1133472033994793e-19" iyz="1.0843141666922054e-08" ixz="2.2708953315887792e-18" />
        </inertial>
        <visual name="leg_5_femur_bracket_B_visual">
            <origin xyz="-0.0049999967965648215 -0.022899996767244496 0.003999995938597288" rpy="-3.1415926535897922 -9.992007221626417e-16 1.570796326794898" />
            <geometry>
                <mesh filename="CAD/bracket_B.stl" scale="0.001 0.001 0.001" />
            </geometry>
            <material name="gray"/>
        </visual>
        <collision name="leg_5_femur_bracket_B_collision">
            <origin xyz="-0.0049999967965648215 -0.022899996767244496 0.003999995938597288" rpy="-3.1415926535897922 -9.992007221626417e-16 1.570796326794898" />
            <geometry>
                <mesh filename="CAD/bracket_B.stl" scale="0.001 0.001 0.001" />
            </geometry>
        </collision>
    </link>
    <link name="leg_5_femur_motor">
        <inertial>
            <origin xyz="5.406123213536063e-09 0.022696323528582443 -0.009997204090262795" rpy="8.469737173967595e-64 -0.0 0.0" />
            <mass value="0.029139949883713843" />
            <inertia ixx="7.192071700452048e-06" iyy="5.0762677862824235e-06" izz="3.989084215369657e-06" ixy="-9.421506233451756e-13" iyz="-6.637044814052148e-08" ixz="4.2973602649466697e-13" />
        </inertial>
        <visual name="leg_5_femur_motor_visual">
            <origin xyz="-0.009749996796564731 0.031066216436191 -0.030250004061402953" rpy="-1.5707963267948937 -1.570796326794894 0" />
            <geometry>
                <mesh filename="CAD/MG996R.stl" scale="0.001 0.001 0.001" />
            </geometry>
            <material name="gray"/>
        </visual>
        <collision name="leg_5_femur_motor_collision">
            <origin xyz="-0.009749996796564731 0.031066216436191 -0.030250004061402953" rpy="-1.5707963267948937 -1.570796326794894 0" />
            <geometry>
                <mesh filename="CAD/MG996R.stl" scale="0.001 0.001 0.001" />
            </geometry>
        </collision>
    </link>
    <link name="leg_5_femur">
        <inertial>
            <origin xyz="0.052800004061420935 -0.007077037034494033 -0.005249996796564788" rpy="0.0 -0.0 6.19407286711598e-94" />
            <mass value="0.021802151943504742" />
            <inertia ixx="2.844030639370196e-06" iyy="2.730894596630288e-05" izz="2.5188056838579948e-05" ixy="-4.404571325722362e-19" iyz="-7.72917564369549e-21" ixz="2.7105054312137617e-20" />
        </inertial>
        <visual name="leg_5_femur_visual">
            <origin xyz="0.08130000406140293 -0.014000003563809024 -0.0052499967965648695" rpy="1.5707963267948986 -1.580441427876642e-15 -3.141592653589792" />
            <geometry>
                <mesh filename="CAD/femur.stl" scale="0.001 0.001 0.001" />
            </geometry>
            <material name="gray"/>
        </visual>
        <collision name="leg_5_femur_collision">
            <origin xyz="0.08130000406140293 -0.014000003563809024 -0.0052499967965648695" rpy="1.5707963267948986 -1.580441427876642e-15 -3.141592653589792" />
            <geometry>
                <mesh filename="CAD/femur.stl" scale="0.001 0.001 0.001" />
            </geometry>
        </collision>
    </link>
    <link name="leg_5_tibia_motor">
        <inertial>
            <origin xyz="-0.024447195967456564 0.008369896471417546 0.005249998999252784" rpy="0.0 -0.0 0.0" />
            <mass value="0.029139949883713843" />
            <inertia ixx="3.989084215369652e-06" iyy="5.0762677862824235e-06" izz="7.1920717004518315e-06" ixy="6.637044814052559e-08" iyz="9.421506352036367e-13" ixz="4.29736019718404e-13" />
        </inertial>
        <visual name="leg_5_tibia_motor_visual">
            <origin xyz="-0.044699995938596755 3.5638090034595394e-09 -0.004500003203435132" rpy="1.5707963267948946 -1.4579767479619067e-15 -3.330669073875487e-16" />
            <geometry>
                <mesh filename="CAD/MG996R.stl" scale="0.001 0.001 0.001" />
            </geometry>
            <material name="gray"/>
        </visual>
        <collision name="leg_5_tibia_motor_collision">
            <origin xyz="-0.044699995938596755 3.5638090034595394e-09 -0.004500003203435132" rpy="1.5707963267948946 -1.4579767479619067e-15 -3.330669073875487e-16" />
            <geometry>
                <mesh filename="CAD/MG996R.stl" scale="0.001 0.001 0.001" />
            </geometry>
        </collision>
    </link>
    <link name="leg_5_tibia_bracket_A">
        <inertial>
            <origin xyz="0.022523351200555517 0.01095042183735024 3.203435771093055e-09" rpy="0.0 -0.0 -2.107269615599639e-62" />
            <mass value="0.01302030082235085" />
            <inertia ixx="3.7783105830391976e-06" iyy="2.2212930817994483e-06" izz="5.134674926367895e-06" ixy="-1.3808520517478255e-06" iyz="-2.0604076441960856e-18" ixz="-1.3247595295057257e-18" />
        </inertial>
        <visual name="leg_5_tibia_bracket_A_visual">
            <origin xyz="0.07855315654093982 0.04320261504837358 3.203434947307571e-09" rpy="-1.570796326794895 2.6216440076822113e-15 1.5707963267948988" />
            <geometry>
                <mesh filename="CAD/bracket_A.stl" scale="0.001 0.001 0.001" />
            </geometry>
            <material name="gray"/>
        </visual>
        <collision name="leg_5_tibia_bracket_A_collision">
            <origin xyz="0.07855315654093982 0.04320261504837358 3.203434947307571e-09" rpy="-1.570796326794895 2.6216440076822113e-15 1.5707963267948988" />
            <geometry>
                <mesh filename="CAD/bracket_A.stl" scale="0.001 0.001 0.001" />
            </geometry>
        </collision>
    </link>
    <link name="leg_5_tibia_bracket_B">
        <inertial>
            <origin xyz="-0.004999996796602588 0.003105258106040103 0.015541722986995125" rpy="0.0 -0.0 0.0" />
            <mass value="0.004130529991365324" />
            <inertia ixx="5.500820140457417e-07" iyy="7.023383537157265e-07" izz="1.7682377544120263e-07" ixy="2.0413494028828638e-19" iyz="-1.0843141666911889e-08" ixz="2.270048298641525e-18" />
        </inertial>
        <visual name="leg_5_tibia_bracket_B_visual">
            <origin xyz="-0.004999996796564566 -0.022899996767244267 -0.004000004061403111" rpy="2.0884484115486532e-15 -1.8318679906315083e-15 1.5707963267949006" />
            <geometry>
                <mesh filename="CAD/bracket_B.stl" scale="0.001 0.001 0.001" />
            </geometry>
            <material name="gray"/>
        </visual>
        <collision name="leg_5_tibia_bracket_B_collision">
            <origin xyz="-0.004999996796564566 -0.022899996767244267 -0.004000004061403111" rpy="2.0884484115486532e-15 -1.8318679906315083e-15 1.5707963267949006" />
            <geometry>
                <mesh filename="CAD/bracket_B.stl" scale="0.001 0.001 0.001" />
            </geometry>
        </collision>
    </link>
    <link name="leg_5_tibia">
        <inertial>
            <origin xyz="-0.04313437175345925 -0.0049999967672459235 -0.026581936859366603" rpy="0.0 -0.0 -2.019102521551348e-94" />
            <mass value="0.02243468417663065" />
            <inertia ixx="2.8033158331316294e-06" iyy="4.125039150847836e-05" izz="3.948923882044343e-05" ixy="3.918374413998393e-18" iyz="2.862018449653874e-18" ixz="-4.163420888493417e-06" />
        </inertial>
        <visual name="leg_5_tibia_visual">
            <origin xyz="-0.03799999593859699 -0.0049999967672443735 -0.004999996871070658" rpy="2.1072934008282733e-15 -2.1649983278424766e-15 -1.570796326794895" />
            <geometry>
                <mesh filename="CAD/tibia.stl" scale="0.001 0.001 0.001" />
            </geometry>
            <material name="gray"/>
        </visual>
        <collision name="leg_5_tibia_collision">
            <origin xyz="-0.03799999593859699 -0.0049999967672443735 -0.004999996871070658" rpy="2.1072934008282733e-15 -2.1649983278424766e-15 -1.570796326794895" />
            <geometry>
                <mesh filename="CAD/tibia.stl" scale="0.001 0.001 0.001" />
            </geometry>
        </collision>
    </link>

    <joint name="base_leg_5_base_coxa_motor" type="fixed">
        <origin xyz="-0.08513499593859752 -0.00524999676724445 0.0" rpy="0.0 -0.0 -3.141592653589793" />
        <parent link="base" />
        <child link="leg_5_coxa_motor" />
    </joint>
    <joint name="leg_5_coxa_bracket_A_leg_5_coxa_bracket" type="fixed">
        <origin xyz="0.029999999999999992 0.005 -0.0453" rpy="2.465190328815662e-32 -1.5707963267948966 0" />
        <parent link="leg_5_coxa_bracket_A" />
        <child link="leg_5_coxa_bracket_B" />
    </joint>
    <joint name="leg_5_coxa" type="revolute">
        <origin xyz="-0.014449999999999994 -0.00525 0.03106621" rpy="0.0 -0.0 -2.465190328815662e-32" />
        <parent link="leg_5_coxa_motor" />
        <child link="leg_5_coxa_bracket_A" />
        <axis xyz="0.0 -0.0 -1.0" />
        <limit lower="-1.570796" upper="1.570796" effort="1000000" velocity="1000000" />
    </joint>
    <joint name="leg_5_femur_bracket_A_leg_5_coxa_bracket_femur_bracket" type="fixed">
        <origin xyz="0.0040000000000000036 0.0279 0.01" rpy="1.9721522630525295e-31 -1.5707963267948966 0" />
        <parent link="leg_5_femur_bracket_A" />
        <child link="leg_5_femur_bracket_B" />
    </joint>
    <joint name="leg_5_coxa_bracket_A_leg_5_femur_bracket" type="fixed">
        <origin xyz="0.033999999999999996 -0.005 -0.027400000000000004" rpy="1.7190554201182872e-33 1.9721522630525295e-31 2.465190328815662e-32" />
        <parent link="leg_5_coxa_bracket_A" />
        <child link="leg_5_femur_bracket_A" />
    </joint>
    <joint name="leg_5_femur" type="revolute">
        <origin xyz="0.034 -0.0174 0.005" rpy="-6.661338147750937e-16 -1.5707963267948966 0" />
        <parent link="leg_5_femur_bracket_A" />
        <child link="leg_5_femur_motor" />
        <axis xyz="-1.9721522630525295e-31 -1.0 -6.661338147750937e-16" />
        <limit lower="-1.570796" upper="1.570796" effort="1000000" velocity="1000000" />
    </joint>
    <joint name="leg_5_femur_motor_leg_5_femur_motor_femur" type="fixed">
        <origin xyz="0.00525 0.031066219999999988 0.01445000000000002" rpy="1.9721522630525295e-31 1.570796326794896 0" />
        <parent link="leg_5_femur_motor" />
        <child link="leg_5_femur" />
    </joint>
    <joint name="leg_5_femur_leg_5_femur_tibia_motor" type="fixed">
        <origin xyz="0.10559999999999999 0.0 0.0" rpy="3.141592653589793 4.598867427476946e-31 1.9721522630525295e-31" />
        <parent link="leg_5_femur" />
        <child link="leg_5_tibia_motor" />
    </joint>
    <joint name="leg_5_tibia_bracket_A_leg_5_tibia_bracket" type="fixed">
        <origin xyz="0.03 0.04529999999999999 0.005000000000000001" rpy="-5.9164567891575885e-31 -1.5707963267948966 0" />
        <parent link="leg_5_tibia_bracket_A" />
        <child link="leg_5_tibia_bracket_B" />
    </joint>
    <joint name="leg_5_tibia" type="revolute">
        <origin xyz="-0.014449999999999968 0.03106622 0.00525" rpy="-3.141592653589793 1.7406554366224627e-31 -1.9721522630525295e-31" />
        <parent link="leg_5_tibia_motor" />
        <child link="leg_5_tibia_bracket_A" />
        <axis xyz="1.9721522630525295e-31 1.0 -3.944304526105059e-31" />
        <limit lower="-2.181662" upper="-0.0" effort="1000000" velocity="1000000" />
    </joint>
    <joint name="leg_5_tibia_bracket_A_leg_5_tibia_bracket_tibia" type="fixed">
        <origin xyz="0.03399999999999999 0.027399999999999997 0.005000000000000001" rpy="-1.9721522630525295e-31 -8.533424418233808e-32 -5.9164567891575885e-31" />
        <parent link="leg_5_tibia_bracket_A" />
        <child link="leg_5_tibia" />
    </joint>

    <!-- Leg 6 -->

    <link name="leg_6_coxa_motor">
        <inertial>
            <origin xyz="-0.020999096654761695 0.013574470833849493 0.008369892907608513" rpy="0.0 -0.0 0.0" />
            <mass value="0.029139949883713843" />
            <inertia ixx="5.590577528174812e-06" iyy="5.59057838764681e-06" izz="5.076267786282396e-06" ixy="1.6014937425411153e-06" iyz="-4.693166015165066e-08" ixz="4.6930327749461454e-08" />
        </inertial>
        <visual name="leg_6_coxa_motor_visual">
            <origin xyz="-0.02842569617826518 0.03478965570556184 -2.958437799684086e-17" rpy="-3.1415926535897922 -7.60697105547759e-16 -0.7853981633974513" />
            <geometry>
                <mesh filename="CAD/MG996R.stl" scale="0.001 0.001 0.001" />
            </geometry>
            <material name="gray"/>
        </visual>
        <collision name="leg_6_coxa_motor_collision">
            <origin xyz="-0.02842569617826518 0.03478965570556184 -2.958437799684086e-17" rpy="-3.1415926535897922 -7.60697105547759e-16 -0.7853981633974513" />
            <geometry>
                <mesh filename="CAD/MG996R.stl" scale="0.001 0.001 0.001" />
            </geometry>
        </collision>
    </link>
    <link name="leg_6_coxa_bracket_B">
        <inertial>
            <origin xyz="-0.003105251669849145 0.0074541316097492686 0.01452519431564431" rpy="0.0 -0.0 0.0" />
            <mass value="0.004130529991365324" />
            <inertia ixx="7.023383537157197e-07" iyy="3.634528947457435e-07" izz="3.6345289474121016e-07" ixy="7.66725900188875e-09" iyz="-1.8662911930228182e-07" ixz="7.667259002194528e-09" />
        </inertial>
        <visual name="leg_6_coxa_bracket_B_visual">
            <origin xyz="0.022900003203435226 -0.006363956102242821 0.0007071066035985041" rpy="0.7853981633974506 -2.8098737128533416e-15 -3.1415926535897927" />
            <geometry>
                <mesh filename="CAD/bracket_B.stl" scale="0.001 0.001 0.001" />
            </geometry>
            <material name="gray"/>
        </visual>
        <collision name="leg_6_coxa_bracket_B_collision">
            <origin xyz="0.022900003203435226 -0.006363956102242821 0.0007071066035985041" rpy="0.7853981633974506 -2.8098737128533416e-15 -3.1415926535897927" />
            <geometry>
                <mesh filename="CAD/bracket_B.stl" scale="0.001 0.001 0.001" />
            </geometry>
        </collision>
    </link>
    <link name="leg_6_coxa_bracket_A">
        <inertial>
            <origin xyz="0.015926414333172618 -0.015926407039012762 -0.01095041540115921" rpy="0.0 -0.0 0.0" />
            <mass value="0.01302030082235085" />
            <inertia ixx="4.456492754702424e-06" iyy="4.456492754705013e-06" izz="2.22129308179961e-06" ixy="6.7818217166459e-07" iyz="-9.764098496048653e-07" ixz="9.764098496076063e-07" />
        </inertial>
        <visual name="leg_6_coxa_bracket_A_visual">
            <origin xyz="0.055545469637919835 -0.05554546234376124 -0.04320260861218251" rpy="-2.3561944901923417 1.5707963267948941 0" />
            <geometry>
                <mesh filename="CAD/bracket_A.stl" scale="0.001 0.001 0.001" />
            </geometry>
            <material name="gray"/>
        </visual>
        <collision name="leg_6_coxa_bracket_A_collision">
            <origin xyz="0.055545469637919835 -0.05554546234376124 -0.04320260861218251" rpy="-2.3561944901923417 1.5707963267948941 0" />
            <geometry>
                <mesh filename="CAD/bracket_A.stl" scale="0.001 0.001 0.001" />
            </geometry>
        </collision>
    </link>
    <link name="leg_6_femur_bracket_A">
        <inertial>
            <origin xyz="0.0035546758131921852 -0.012675761811910657 0.005000003203434644" rpy="0.0 -0.0 -5.6916151414570454e-61" />
            <mass value="0.01302030082235085" />
            <inertia ixx="4.380653884166928e-06" iyy="1.6189497806714257e-06" izz="5.134674926367895e-06" ixy="-7.78508750619918e-07" iyz="2.349669395683429e-18" ixz="4.726443845678996e-19" />
        </inertial>
        <visual name="leg_6_femur_bracket_A_visual">
            <origin xyz="-0.013258634963902375 0.04974903802049052 0.005000003203435347" rpy="1.5707963267948983 1.2896663962143644e-15 0.7853981633974464" />
            <geometry>
                <mesh filename="CAD/bracket_A.stl" scale="0.001 0.001 0.001" />
            </geometry>
            <material name="gray"/>
        </visual>
        <collision name="leg_6_femur_bracket_A_collision">
            <origin xyz="-0.013258634963902375 0.04974903802049052 0.005000003203435347" rpy="1.5707963267948983 1.2896663962143644e-15 0.7853981633974464" />
            <geometry>
                <mesh filename="CAD/bracket_A.stl" scale="0.001 0.001 0.001" />
            </geometry>
        </collision>
    </link>
    <link name="leg_6_femur_bracket_B">
        <inertial>
            <origin xyz="-0.0049999967965269135 -0.008793911746877933 -0.013185403175804317" rpy="-1.4471017969422533e-60 -0.0 0.0" />
            <mass value="0.004130529991365324" />
            <inertia ixx="5.500820140457555e-07" iyy="4.504242062453847e-07" izz="4.287379229115406e-07" ixy="1.456049636330143e-18" iyz="-2.62757289137254e-07" ixz="1.755052266710911e-18" />
        </inertial>
        <visual name="leg_6_femur_bracket_B_visual">
            <origin xyz="-0.004999996796564824 -0.013364316102242828 0.01902117660359851" rpy="-3.1415926535897896 0.7853981633974502 1.5707963267948983" />
            <geometry>
                <mesh filename="CAD/bracket_B.stl" scale="0.001 0.001 0.001" />
            </geometry>
            <material name="gray"/>
        </visual>
        <collision name="leg_6_femur_bracket_B_collision">
            <origin xyz="-0.004999996796564824 -0.013364316102242828 0.01902117660359851" rpy="-3.1415926535897896 0.7853981633974502 1.5707963267948983" />
            <geometry>
                <mesh filename="CAD/bracket_B.stl" scale="0.001 0.001 0.001" />
            </geometry>
        </collision>
    </link>
    <link name="leg_6_femur_motor">
        <inertial>
            <origin xyz="5.406123213536063e-09 0.00897963549471152 -0.02311781198061185" rpy="-9.860761315262648e-32 -0.0 0.0" />
            <mass value="0.029139949883713843" />
            <inertia ixx="7.192071700451943e-06" iyy="4.466305552685485e-06" izz="4.599046448966516e-06" ixy="-3.6233184828133885e-13" iyz="-5.435917854562355e-07" ixz="9.700703510872462e-13" />
        </inertial>
        <visual name="leg_6_femur_motor_visual">
            <origin xyz="-0.009749996796564728 0.0005771513298787489 -0.043357112210994926" rpy="3.141592653589789 -0.7853981633974477 1.5707963267948943" />
            <geometry>
                <mesh filename="CAD/MG996R.stl" scale="0.001 0.001 0.001" />
            </geometry>
            <material name="gray"/>
        </visual>
        <collision name="leg_6_femur_motor_collision">
            <origin xyz="-0.009749996796564728 0.0005771513298787489 -0.043357112210994926" rpy="3.141592653589789 -0.7853981633974477 1.5707963267948943" />
            <geometry>
                <mesh filename="CAD/MG996R.stl" scale="0.001 0.001 0.001" />
            </geometry>
        </collision>
    </link>
    <link name="leg_6_femur">
        <inertial>
            <origin xyz="0.03233101878081305 -0.0423394519555505 -0.005249996796564786" rpy="0.0 7.006492321624085e-46 -1.7752406945933872e-60" />
            <mass value="0.021802151943504742" />
            <inertia ixx="1.5076488302836042e-05" iyy="1.5076488302836794e-05" izz="2.518805683858018e-05" ixy="1.2232457663466143e-05" iyz="-3.388131789017184e-20" ixz="3.049318610115491e-20" />
        </inertial>
        <visual name="leg_6_femur_visual">
            <origin xyz="0.0475882854658107 -0.06738727179816055 -0.0052499967965648695" rpy="1.5707963267948986 -1.5804414278766377e-15 2.356194490192343" />
            <geometry>
                <mesh filename="CAD/femur.stl" scale="0.001 0.001 0.001" />
            </geometry>
            <material name="gray"/>
        </visual>
        <collision name="leg_6_femur_collision">
            <origin xyz="0.0475882854658107 -0.06738727179816055 -0.0052499967965648695" rpy="1.5707963267948986 -1.5804414278766377e-15 2.356194490192343" />
            <geometry>
                <mesh filename="CAD/femur.stl" scale="0.001 0.001 0.001" />
            </geometry>
        </collision>
    </link>
    <link name="leg_6_tibia_motor">
        <inertial>
            <origin xyz="-0.02320519376895019 -0.011368371244273305 0.00524999899925278" rpy="0.0 -0.0 1.9481407417666064e-90" />
            <mass value="0.029139949883713843" />
            <inertia ixx="4.466305552685429e-06" iyy="4.599046448966514e-06" izz="7.192071700452048e-06" ixy="-5.435917854563436e-07" iyz="9.700703781923004e-13" ixz="-3.623318415050744e-13" />
        </inertial>
        <visual name="leg_6_tibia_motor_visual">
            <origin xyz="-0.03160767793378287 -0.03160767147465645 -0.004500003203435137" rpy="1.5707963267948946 -1.4579767479619044e-15 0.7853981633974508" />
            <geometry>
                <mesh filename="CAD/MG996R.stl" scale="0.001 0.001 0.001" />
            </geometry>
            <material name="gray"/>
        </visual>
        <collision name="leg_6_tibia_motor_collision">
            <origin xyz="-0.03160767793378287 -0.03160767147465645 -0.004500003203435137" rpy="1.5707963267948946 -1.4579767479619044e-15 0.7853981633974508" />
            <geometry>
                <mesh filename="CAD/MG996R.stl" scale="0.001 0.001 0.001" />
            </geometry>
        </collision>
    </link>
    <link name="leg_6_tibia_bracket_A">
        <inertial>
            <origin xyz="0.02366952892442729 -0.008183294923145965 3.203435772203278e-09" rpy="0.0 -0.0 0.0" />
            <mass value="0.01302030082235085" />
            <inertia ixx="1.6189497806714257e-06" iyy="4.380653884167036e-06" izz="5.13467492636757e-06" ixy="-7.78508750619918e-07" iyz="-5.116079001415974e-19" ixz="-2.3954091748351614e-18" />
        </inertial>
        <visual name="leg_6_tibia_bracket_A_visual">
            <origin xyz="0.08609432875682856 -0.024996605700240763 3.203434949528017e-09" rpy="-1.570796326794895 2.621644007682213e-15 0.7853981633974475" />
            <geometry>
                <mesh filename="CAD/bracket_A.stl" scale="0.001 0.001 0.001" />
            </geometry>
            <material name="gray"/>
        </visual>
        <collision name="leg_6_tibia_bracket_A_collision">
            <origin xyz="0.08609432875682856 -0.024996605700240763 3.203434949528017e-09" rpy="-1.570796326794895 2.621644007682213e-15 0.7853981633974475" />
            <geometry>
                <mesh filename="CAD/bracket_A.stl" scale="0.001 0.001 0.001" />
            </geometry>
        </collision>
    </link>
    <link name="leg_6_tibia_bracket_B">
        <inertial>
            <origin xyz="-0.0049999967966025865 0.013185402439466145 0.008793911010539866" rpy="-1.5241149863310302e-61 8.758115402030107e-47 0.0" />
            <mass value="0.004130529991365324" />
            <inertia ixx="5.500820140457688e-07" iyy="4.2873792291151316e-07" izz="4.5042420624536415e-07" ixy="1.749970069027384e-18" iyz="-2.6275728913727415e-07" ixz="1.461131834013668e-18" />
        </inertial>
        <visual name="leg_6_tibia_bracket_B_visual">
            <origin xyz="-0.004999996796564563 -0.0190211773399367 0.013364315365904886" rpy="3.1519400262843607e-15 0.7853981633974492 1.570796326794902" />
            <geometry>
                <mesh filename="CAD/bracket_B.stl" scale="0.001 0.001 0.001" />
            </geometry>
            <material name="gray"/>
        </visual>
        <collision name="leg_6_tibia_bracket_B_collision">
            <origin xyz="-0.004999996796564563 -0.0190211773399367 0.013364315365904886" rpy="3.1519400262843607e-15 0.7853981633974492 1.570796326794902" />
            <geometry>
                <mesh filename="CAD/bracket_B.stl" scale="0.001 0.001 0.001" />
            </geometry>
        </collision>
    </link>
    <link name="leg_6_tibia">
        <inertial>
            <origin xyz="-0.034036145006844175 0.02696507230100039 -0.026581936859366603" rpy="0.0 -3.503246160812043e-46 6.160086635861049e-61" />
            <mass value="0.02243468417663065" />
            <inertia ixx="2.2026853670809032e-05" iyy="2.2026853670800894e-05" izz="3.948923882044343e-05" ixy="1.9223537837673444e-05" iyz="2.94398314318944e-06" ixz="-2.9439831431853813e-06" />
        </inertial>
        <visual name="leg_6_tibia_visual">
            <origin xyz="-0.03040559305099377 0.02333452034515215 -0.004999996871070658" rpy="2.1072934008282757e-15 -2.1649983278424747e-15 -2.356194490192346" />
            <geometry>
                <mesh filename="CAD/tibia.stl" scale="0.001 0.001 0.001" />
            </geometry>
            <material name="gray"/>
        </visual>
        <collision name="leg_6_tibia_collision">
            <origin xyz="-0.03040559305099377 0.02333452034515215 -0.004999996871070658" rpy="2.1072934008282757e-15 -2.1649983278424747e-15 -2.356194490192346" />
            <geometry>
                <mesh filename="CAD/tibia.stl" scale="0.001 0.001 0.001" />
            </geometry>
        </collision>
    </link>

    <joint name="base_leg_6_base_coxa_motor" type="fixed">
        <origin xyz="-0.07081356593859754 0.08875394323275541 0.0" rpy="0.0 -0.0 -3.141592653589793" />
        <parent link="base" />
        <child link="leg_6_coxa_motor" />
    </joint>
    <joint name="leg_6_coxa_bracket_A_leg_6_coxa_bracket" type="fixed">
        <origin xyz="0.024748739999999998 -0.01767767000000001 -0.045300000000000014" rpy="-3.944304526105059e-31 -1.5707963267948966 0" />
        <parent link="leg_6_coxa_bracket_A" />
        <child link="leg_6_coxa_bracket_B" />
    </joint>
    <joint name="leg_6_coxa" type="revolute">
        <origin xyz="-0.01393001 0.006505380000000009 0.03106621" rpy="0.0 -0.0 0.0" />
        <parent link="leg_6_coxa_motor" />
        <child link="leg_6_coxa_bracket_A" />
        <axis xyz="0.0 -0.0 -0.9999999999999999" />
        <limit lower="-1.570796" upper="1.570796" effort="1000000" velocity="1000000" />
    </joint>
    <joint name="leg_6_femur_bracket_A_leg_6_coxa_bracket_femur_bracket" type="fixed">
        <origin xyz="0.022556710000000004 0.01689985 0.01" rpy="5.9164567891575885e-31 -1.5707963267948966 0" />
        <parent link="leg_6_femur_bracket_A" />
        <child link="leg_6_femur_bracket_B" />
    </joint>
    <joint name="leg_6_coxa_bracket_A_leg_6_femur_bracket" type="fixed">
        <origin xyz="0.0205061 -0.027577160000000003 -0.02740000000000001" rpy="2.8859917401344424e-30 -1.97215226305253e-31 -3.944304526105059e-31" />
        <parent link="leg_6_coxa_bracket_A" />
        <child link="leg_6_femur_bracket_A" />
    </joint>
    <joint name="leg_6_femur" type="revolute">
        <origin xyz="0.011737970000000014 -0.03634529000000001 0.005" rpy="-6.661338147750934e-16 -1.5707963267948966 0" />
        <parent link="leg_6_femur_bracket_A" />
        <child link="leg_6_femur_motor" />
        <axis xyz="-2.733713951331856e-30 -0.7071070000000006 0.7071069999999997" />
        <limit lower="-1.570796" upper="1.570796" effort="1000000" velocity="1000000" />
    </joint>
    <joint name="leg_6_femur_motor_leg_6_femur_motor_femur" type="fixed">
        <origin xyz="0.00525 0.03218482000000002 -0.011749439999999983" rpy="5.916456789157522e-31 1.570796326794896 0" />
        <parent link="leg_6_femur_motor" />
        <child link="leg_6_femur" />
    </joint>
    <joint name="leg_6_femur_leg_6_femur_tibia_motor" type="fixed">
        <origin xyz="0.07467047999999998 -0.07467046999999999 2.220446049250313e-18" rpy="3.141592653589793 -1.5122655203048331e-30 -3.94430452610506e-31" />
        <parent link="leg_6_femur" />
        <child link="leg_6_tibia_motor" />
    </joint>
    <joint name="leg_6_tibia_bracket_A_leg_6_tibia_bracket" type="fixed">
        <origin xyz="0.05324514000000001 0.010818739999999992 0.005000000000000001" rpy="-3.94430452610506e-31 -1.5707963267948966 0" />
        <parent link="leg_6_tibia_bracket_A" />
        <child link="leg_6_tibia_bracket_B" />
    </joint>
    <joint name="leg_6_tibia" type="revolute">
        <origin xyz="-0.03218482999999999 0.01174944 0.00525" rpy="-3.141592653589793 4.759319555259378e-30 -1.9721522630525295e-31" />
        <parent link="leg_6_tibia_motor" />
        <child link="leg_6_tibia_bracket_A" />
        <axis xyz="0.707107 0.707107 -1.0126468723405222e-29" />
        <limit lower="-2.181662" upper="-0.0" effort="1000000" velocity="1000000" />
    </joint>
    <joint name="leg_6_tibia_bracket_A_leg_6_tibia_bracket_tibia" type="fixed">
        <origin xyz="0.043416360000000015 -0.004666899999999998 0.005000000000000001" rpy="-1.972152263052529e-31 4.8943502200252996e-30 -3.944304526105059e-31" />
        <parent link="leg_6_tibia_bracket_A" />
        <child link="leg_6_tibia" />
    </joint>

</robot>