<?xml version='1.0' encoding='utf-8'?>
<robot name="hexapod">

    <material name="black">
        <color rgba="0 0 0 1" />
    </material>

    <material name="gray">
        <color rgba="0.4 0.4 0.4 1" />
    </material>

    <!--Body links-->

    <link name="base">
        <inertial>
            <origin xyz="-6.645222106183918e-15 0.001534649235880559 0.007014957956835419" rpy="0.0 0.0 0.0" />
            <mass value="0.5452508805768645" />
            <inertia ixx="0.0019800694919493906" iyy="0.0015359484736764625" izz="0.0034983875742396545" ixy="-9.13028154590727e-18" iyz="-3.334559036663478e-06" ixz="-1.9616518902955917e-17" />
        </inertial>
        <visual name="base_visual">
            <origin xyz="0.0 0.0 0.0" rpy="0.0 0.0 0.0" />
            <geometry>
                <mesh filename="CAD/base.stl" scale="0.001 0.001 0.001" />
            </geometry>
            <material name="gray"/>
        </visual>
        <collision name="base_collision">
            <origin xyz="0.0 0.0 0.0" rpy="0.0 0.0 0.0" />
            <geometry>
                <mesh filename="CAD/base.stl" scale="0.001 0.001 0.001" />
            </geometry>
        </collision>
    </link>

    <!--Leg 1 links-->

    <link name="leg_1_MG996R_coxa">
        <inertial>
            <origin xyz="-0.013931981892568142 -0.02135659877749534 0.008369892907608575" rpy="0.0 -0.0 0.0" />
            <mass value="0.20795327871559424" />
            <inertia ixx="3.989640031184312e-05" iyy="3.9896394178338176e-05" izz="3.6226092838469864e-05" ixy="-1.1428841708134357e-05" iyz="-3.349118843938418e-07" ixz="-3.349213929004541e-07" />
        </inertial>
        <visual name="leg_1_MG996R_coxa_visual">
            <origin xyz="0.007283202979144226 -0.013929999253991908 8.881784197001374e-18" rpy="-3.141592653589793 -1.503107159385723e-15 -2.35619449019235" />
            <geometry>
                <mesh filename="CAD/MG996R.stl" scale="0.001 0.001 0.001" />
            </geometry>
            <material name="gray"/>
        </visual>
        <collision name="leg_1_MG996R_coxa_collision">
            <origin xyz="0.007283202979144226 -0.013929999253991908 8.881784197001374e-18" rpy="-3.141592653589793 -1.503107159385723e-15 -2.35619449019235" />
            <geometry>
                <mesh filename="CAD/MG996R.stl" scale="0.001 0.001 0.001" />
            </geometry>
        </collision>
    </link>

    <link name="leg_1_coxa">
        <inertial>
            <origin xyz="-0.021868759892857075 -0.020557643514970057 -0.020572897514840063" rpy="0.0 -0.0 0.0" />
            <mass value="0.23210805328252043" />
            <inertia ixx="0.00010185659819878613" iyy="0.00011376262401915834" izz="0.00011113698714724281" ixy="-3.3273760382541567e-06" iyz="-4.0683480606476625e-06" ixz="-4.350483533926249e-06" />
        </inertial>
        <visual name="leg_1_coxa_visual">
            <origin xyz="-0.14799063143944235 0.01478810526816348 -0.1314188537154779" rpy="-3.141592653589791 0.7853981633974431 -0.7853981633974517" />
            <geometry>
                <mesh filename="CAD/coxa.stl" scale="0.001 0.001 0.001" />
            </geometry>
            <material name="gray"/>
        </visual>
        <collision name="leg_1_coxa_collision">
            <origin xyz="-0.14799063143944235 0.01478810526816348 -0.1314188537154779" rpy="-3.141592653589791 0.7853981633974431 -0.7853981633974517" />
            <geometry>
                <mesh filename="CAD/coxa.stl" scale="0.001 0.001 0.001" />
            </geometry>
        </collision>
    </link>

    <link name="leg_1_MG996R_femur">
        <inertial>
            <origin xyz="-0.006349563295029999 0.02311780926644385 -0.006349555649617446" rpy="-4.930380657631324e-32 -0.0 0.0" />
            <mass value="0.20795327871559424" />
            <inertia ixx="4.159920715841651e-05" iyy="3.2820467840353494e-05" izz="4.15992123298805e-05" ixy="-2.7430522738539723e-06" iyz="-2.7430620641360475e-06" ixz="-9.726029209075528e-06" />
        </inertial>
        <visual name="leg_1_MG996R_femur_visual">
            <origin xyz="0.006486182910840199 0.04335710949682697 -0.007302394791956193" rpy="2.1862760354652675 0.5235987755982903 -2.1862760354652955" />
            <geometry>
                <mesh filename="CAD/MG996R.stl" scale="0.001 0.001 0.001" />
            </geometry>
            <material name="gray"/>
        </visual>
        <collision name="leg_1_MG996R_femur_collision">
            <origin xyz="0.006486182910840199 0.04335710949682697 -0.007302394791956193" rpy="2.1862760354652675 0.5235987755982903 -2.1862760354652955" />
            <geometry>
                <mesh filename="CAD/MG996R.stl" scale="0.001 0.001 0.001" />
            </geometry>
        </collision>
    </link>

    <link name="leg_1_femur">
        <inertial>
            <origin xyz="-0.042389884762423814 -0.03228058563361566 0.005250003203434872" rpy="0.0 -0.0 0.0" />
            <mass value="0.1615808293904576" />
            <inertia ixx="0.00011199064455003679" iyy="0.00011199064455002681" izz="0.00018820429701192458" ixy="-9.148253177655372e-05" iyz="-1.436567878543294e-18" ixz="-5.421010862427316e-19" />
        </inertial>
        <visual name="leg_1_femur_visual">
            <origin xyz="-0.06738727417201755 -0.047588282751642945 0.0052500032034344815" rpy="1.5707963267948846 -9.603429163007513e-15 0.785398163397445" />
            <geometry>
                <mesh filename="CAD/femur.stl" scale="0.001 0.001 0.001" />
            </geometry>
            <material name="gray"/>
        </visual>
        <collision name="leg_1_femur_collision">
            <origin xyz="-0.06738727417201755 -0.047588282751642945 0.0052500032034344815" rpy="1.5707963267948846 -9.603429163007513e-15 0.785398163397445" />
            <geometry>
                <mesh filename="CAD/femur.stl" scale="0.001 0.001 0.001" />
            </geometry>
        </collision>
    </link>

    <link name="leg_1_MG996R_tibia">
        <inertial>
            <origin xyz="0.011368368870416354 -0.023205186483118007 -0.005250001000746491" rpy="0.0 -0.0 -1.599831644569785e-58" />
            <mass value="0.20795327871559424" />
            <inertia ixx="3.282046784035177e-05" iyy="3.187318053507471e-05" izz="5.13252389532249e-05" ixy="3.87926865075619e-06" iyz="-2.5857318131268514e-12" ixz="-6.922773931796605e-12" />
        </inertial>
        <visual name="leg_1_MG996R_tibia_visual">
            <origin xyz="0.03160766910079932 -0.03160767064795067 -0.015000003203434654" rpy="1.5707963267949088 -9.492406860545008e-15 2.356194490192349" />
            <geometry>
                <mesh filename="CAD/MG996R.stl" scale="0.001 0.001 0.001" />
            </geometry>
            <material name="gray"/>
        </visual>
        <collision name="leg_1_MG996R_tibia_collision">
            <origin xyz="0.03160766910079932 -0.03160767064795067 -0.015000003203434654" rpy="1.5707963267949088 -9.492406860545008e-15 2.356194490192349" />
            <geometry>
                <mesh filename="CAD/MG996R.stl" scale="0.001 0.001 0.001" />
            </geometry>
        </collision>
    </link>

    <link name="leg_1_tibia">
        <inertial>
            <origin xyz="0.0130108984949468 -0.016293305911519555 -0.012514301101988546" rpy="0.0 -0.0 0.0" />
            <mass value="0.2763071087572843" />
            <inertia ixx="0.0002267575012691505" iyy="0.0002267638037081899" izz="0.00034998341011063805" ixy="-0.00012254451068291136" iyz="4.534317847601919e-05" ixz="4.9151539951400395e-05" />
        </inertial>
        <visual name="leg_1_tibia_visual">
            <origin xyz="0.02085964899297368 -0.009545941007024581 3.1289283908275677e-09" rpy="-9.553639200502557e-15 1.2878587085651928e-14 2.35619449019234" />
            <geometry>
                <mesh filename="CAD/tibia.stl" scale="0.001 0.001 0.001" />
            </geometry>
            <material name="gray"/>
        </visual>
        <collision name="leg_1_tibia_collision">
            <origin xyz="0.02085964899297368 -0.009545941007024581 3.1289283908275677e-09" rpy="-9.553639200502557e-15 1.2878587085651928e-14 2.35619449019234" />
            <geometry>
                <mesh filename="CAD/tibia.stl" scale="0.001 0.001 0.001" />
            </geometry>
        </collision>
    </link>

    <!--Leg 2 links-->

    <link name="leg_2_MG996R_coxa">
        <inertial>
            <origin xyz="-0.024952799971140128 0.005250002202687933 0.008369892907608556" rpy="0.0 -0.0 0.0" />
            <mass value="0.20795327871559424" />
            <inertia ixx="2.8467555536956196e-05" iyy="5.132523895322533e-05" izz="3.6226092838469756e-05" ixy="-3.066752559692828e-12" iyz="6.723529484646535e-12" ixz="-4.736436526392375e-07" />
        </inertial>
        <visual name="leg_2_MG996R_coxa_visual">
            <origin xyz="-0.004699999999999935 -0.004499999999999963 3.330669073875369e-18" rpy="-3.1415926535897927 -1.193362030990045e-15 -3.141592653589793" />
            <geometry>
                <mesh filename="CAD/MG996R.stl" scale="0.001 0.001 0.001" />
            </geometry>
            <material name="gray"/>
        </visual>
        <collision name="leg_2_MG996R_coxa_collision">
            <origin xyz="-0.004699999999999935 -0.004499999999999963 3.330669073875369e-18" rpy="-3.1415926535897927 -1.193362030990045e-15 -3.141592653589793" />
            <geometry>
                <mesh filename="CAD/MG996R.stl" scale="0.001 0.001 0.001" />
            </geometry>
        </collision>
    </link>

    <link name="leg_2_coxa">
        <inertial>
            <origin xyz="-0.030000000000000897 0.0009270992817276102 -0.020572897514840083" rpy="4.318084277547223e-78 -0.0 -6.842277657836118e-49" />
            <mass value="0.23210805328252054" />
            <inertia ixx="0.00010448223507070534" iyy="0.0001111369871472185" izz="0.00011113698714723628" ixy="5.953012910176689e-06" iyz="1.9949990636461146e-07" ixz="-5.953012910192502e-06" />
        </inertial>
        <visual name="leg_2_coxa_visual">
            <origin xyz="-0.09418841197586102 0.11510194855892608 -0.13141885371547798" rpy="-3.1415926535897927 0.7853981633974415 -1.570796326794894" />
            <geometry>
                <mesh filename="CAD/coxa.stl" scale="0.001 0.001 0.001" />
            </geometry>
            <material name="gray"/>
        </visual>
        <collision name="leg_2_coxa_collision">
            <origin xyz="-0.09418841197586102 0.11510194855892608 -0.13141885371547798" rpy="-3.1415926535897927 0.7853981633974415 -1.570796326794894" />
            <geometry>
                <mesh filename="CAD/coxa.stl" scale="0.001 0.001 0.001" />
            </geometry>
        </collision>
    </link>

    <link name="leg_2_MG996R_femur">
        <inertial>
            <origin xyz="0.007069084110578992 0.022696320295826734 0.007069091755991277" rpy="-4.930380657631324e-32 -0.0 0.0" />
            <mass value="0.20795327871559424" />
            <inertia ixx="3.9896400311842064e-05" iyy="3.6226092838469864e-05" izz="3.989639417833713e-05" ixy="3.3492139290067454e-07" iyz="3.349118843937143e-07" ixz="-1.1428841708133571e-05" />
        </inertial>
        <visual name="leg_2_MG996R_femur_visual">
            <origin xyz="0.028284268982291322 0.031066213203435503 0.014495691279494594" rpy="1.5707963267948857 0.7853981633974337 -3.141592653589787" />
            <geometry>
                <mesh filename="CAD/MG996R.stl" scale="0.001 0.001 0.001" />
            </geometry>
            <material name="gray"/>
        </visual>
        <collision name="leg_2_MG996R_femur_collision">
            <origin xyz="0.028284268982291322 0.031066213203435503 0.014495691279494594" rpy="1.5707963267948857 0.7853981633974337 -3.141592653589787" />
            <geometry>
                <mesh filename="CAD/MG996R.stl" scale="0.001 0.001 0.001" />
            </geometry>
        </collision>
    </link>

    <link name="leg_2_femur">
        <inertial>
            <origin xyz="-0.052800000000008965 0.007148349669587089 0.005250003203434775" rpy="0.0 -0.0 0.0" />
            <mass value="0.1615808293904576" />
            <inertia ixx="2.0508112773478013e-05" iyy="0.0002034731763265827" izz="0.0001882042970119211" ixy="-6.491660507756958e-18" iyz="-6.924494343803905e-19" ixz="-1.3552527156068807e-18" />
        </inertial>
        <visual name="leg_2_femur_visual">
            <origin xyz="-0.08130000000000034 0.013999996796564563 0.005250003203434375" rpy="1.570796326794883 -9.530885321133178e-15 3.080868893334806e-15" />
            <geometry>
                <mesh filename="CAD/femur.stl" scale="0.001 0.001 0.001" />
            </geometry>
            <material name="gray"/>
        </visual>
        <collision name="leg_2_femur_collision">
            <origin xyz="-0.08130000000000034 0.013999996796564563 0.005250003203434375" rpy="1.570796326794883 -9.530885321133178e-15 3.080868893334806e-15" />
            <geometry>
                <mesh filename="CAD/femur.stl" scale="0.001 0.001 0.001" />
            </geometry>
        </collision>
    </link>

    <link name="leg_2_MG996R_tibia">
        <inertial>
            <origin xyz="0.024447200028859372 -0.00836988970417307 -0.005250001000746411" rpy="0.0 -0.0 -5.656800834009513e-61" />
            <mass value="0.20795327871559424" />
            <inertia ixx="2.8467555536956346e-05" iyy="3.622609283846813e-05" izz="5.13252389532249e-05" ixy="4.736436526392443e-07" iyz="-6.723528863584907e-12" ixz="-3.0667519305277446e-12" />
        </inertial>
        <visual name="leg_2_MG996R_tibia_visual">
            <origin xyz="0.04469999999999942 3.2034352492882334e-09 -0.015000003203434567" rpy="1.5707963267949103 -9.653350001047915e-15 3.141592653589791" />
            <geometry>
                <mesh filename="CAD/MG996R.stl" scale="0.001 0.001 0.001" />
            </geometry>
            <material name="gray"/>
        </visual>
        <collision name="leg_2_MG996R_tibia_collision">
            <origin xyz="0.04469999999999942 3.2034352492882334e-09 -0.015000003203434567" rpy="1.5707963267949103 -9.653350001047915e-15 3.141592653589791" />
            <geometry>
                <mesh filename="CAD/MG996R.stl" scale="0.001 0.001 0.001" />
            </geometry>
        </collision>
    </link>

    <link name="leg_2_tibia">
        <inertial>
            <origin xyz="-0.002321012180105022 -0.020721202778112985 -0.012514301101988501" rpy="3.503246160812043e-46 -0.0 3.454467422037779e-77" />
            <mass value="0.2763071087572843" />
            <inertia ixx="0.00010421614180576068" iyy="0.00034930516317158145" izz="0.0003499834101106415" ixy="3.151219518860619e-09" iyz="-2.69291822445111e-06" ixz="6.68178561863418e-05" />
        </inertial>
        <visual name="leg_2_tibia_visual">
            <origin xyz="0.007999999999999617 -0.021500000000000453 3.1289284263547045e-09" rpy="-9.714582341005279e-15 1.448841047135834e-14 1.5707963267948988" />
            <geometry>
                <mesh filename="CAD/tibia.stl" scale="0.001 0.001 0.001" />
            </geometry>
            <material name="gray"/>
        </visual>
        <collision name="leg_2_tibia_collision">
            <origin xyz="0.007999999999999617 -0.021500000000000453 3.1289284263547045e-09" rpy="-9.714582341005279e-15 1.448841047135834e-14 1.5707963267948988" />
            <geometry>
                <mesh filename="CAD/tibia.stl" scale="0.001 0.001 0.001" />
            </geometry>
        </collision>
    </link>

    <!--Leg 3 links-->

    <link name="leg_3_MG996R_coxa">
        <inertial>
            <origin xyz="-0.013931978777496457 0.02135660189256684 0.00836989290760856" rpy="0.0 -0.0 0.0" />
            <mass value="0.20795327871559424" />
            <inertia ixx="3.989639417833861e-05" iyy="3.9896400311843446e-05" izz="3.6226092838469214e-05" ixy="1.1428841708134574e-05" iyz="3.349213929004541e-07" ixz="-3.349118843938418e-07" />
        </inertial>
        <visual name="leg_3_MG996R_coxa_visual">
            <origin xyz="-0.0065053792539929624 0.00014141702085445295 2.553512956637829e-17" rpy="-3.1415926535897927 -1.1656064553744155e-15 2.356194490192342" />
            <geometry>
                <mesh filename="CAD/MG996R.stl" scale="0.001 0.001 0.001" />
            </geometry>
            <material name="gray"/>
        </visual>
        <collision name="leg_3_MG996R_coxa_collision">
            <origin xyz="-0.0065053792539929624 0.00014141702085445295 2.553512956637829e-17" rpy="-3.1415926535897927 -1.1656064553744155e-15 2.356194490192342" />
            <geometry>
                <mesh filename="CAD/MG996R.stl" scale="0.001 0.001 0.001" />
            </geometry>
        </collision>
    </link>

    <link name="leg_3_coxa">
        <inertial>
            <origin xyz="-0.020557643514971594 0.0218687598928563 -0.020572897514840066" rpy="0.0 -0.0 -5.112611784615912e-75" />
            <mass value="0.23210805328252054" />
            <inertia ixx="0.00011376262401915959" iyy="0.00010185659819879952" izz="0.00011113698714721243" ixy="3.3273760382613107e-06" iyz="4.350483533925163e-06" ixz="-4.068348060652323e-06" />
        </inertial>
        <visual name="leg_3_coxa_visual">
            <origin xyz="0.014788105268161314 0.1479906314394418 -0.13141885371547804" rpy="-3.141592653589793 0.7853981633974385 -2.3561944901923457" />
            <geometry>
                <mesh filename="CAD/coxa.stl" scale="0.001 0.001 0.001" />
            </geometry>
            <material name="gray"/>
        </visual>
        <collision name="leg_3_coxa_collision">
            <origin xyz="0.014788105268161314 0.1479906314394418 -0.13141885371547804" rpy="-3.141592653589793 0.7853981633974385 -2.3561944901923457" />
            <geometry>
                <mesh filename="CAD/coxa.stl" scale="0.001 0.001 0.001" />
            </geometry>
        </collision>
    </link>

    <link name="leg_3_MG996R_femur">
        <inertial>
            <origin xyz="0.01634675587577469 0.008979633120855635 0.01634676352118694" rpy="4.9303806576313227e-32 -0.0 9.860761315262645e-32" />
            <mass value="0.20795327871559424" />
            <inertia ixx="4.2072860319564225e-05" iyy="3.187318053507514e-05" izz="4.2072846474014214e-05" ixy="2.7430589973838773e-06" iyz="2.7430553406067587e-06" ixz="-9.252385556436575e-06" />
        </inertial>
        <visual name="leg_3_MG996R_femur_visual">
            <origin xyz="0.037552394989253585 0.0005771489560230592 0.023763817286456865" rpy="0.9553166181244941 0.5235987755982886 2.186276035465294" />
            <geometry>
                <mesh filename="CAD/MG996R.stl" scale="0.001 0.001 0.001" />
            </geometry>
            <material name="gray"/>
        </visual>
        <collision name="leg_3_MG996R_femur_collision">
            <origin xyz="0.037552394989253585 0.0005771489560230592 0.023763817286456865" rpy="0.9553166181244941 0.5235987755982886 2.186276035465294" />
            <geometry>
                <mesh filename="CAD/MG996R.stl" scale="0.001 0.001 0.001" />
            </geometry>
        </collision>
    </link>
    
    <link name="leg_3_femur">
        <inertial>
            <origin xyz="-0.0322805856336173 0.04238988476242298 0.005250003203434788" rpy="0.0 -0.0 0.0" />
            <mass value="0.1615808293904576" />
            <inertia ixx="0.00011199064455002421" iyy="0.00011199064455003679" izz="0.0001882042970119211" ixy="9.148253177655328e-05" iyz="4.3368086899420047e-19" ixz="-1.4365678785432681e-18" />
        </inertial>
        <visual name="leg_3_femur_visual">
            <origin xyz="-0.04758828275164462 0.06738727417201662 0.005250003203434375" rpy="1.5707963267948812 -9.609801175747032e-15 -0.7853981633974488" />
            <geometry>
                <mesh filename="CAD/femur.stl" scale="0.001 0.001 0.001" />
            </geometry>
            <material name="gray"/>
        </visual>
        <collision name="leg_3_femur_collision">
            <origin xyz="-0.04758828275164462 0.06738727417201662 0.005250003203434375" rpy="1.5707963267948812 -9.609801175747032e-15 -0.7853981633974488" />
            <geometry>
                <mesh filename="CAD/femur.stl" scale="0.001 0.001 0.001" />
            </geometry>
        </collision>
    </link>

    <link name="leg_3_MG996R_tibia">
        <inertial>
            <origin xyz="0.02320518648311662 0.011368368870417384 -0.005250001000746447" rpy="0.0 -0.0 2.751346509768002e-86" />
            <mass value="0.20795327871559424" />
            <inertia ixx="3.1873180535075575e-05" iyy="3.2820467840353494e-05" izz="5.13252389532249e-05" ixy="-3.879268650757924e-06" iyz="-6.922774040216822e-12" ixz="2.5857316504965255e-12" />
        </inertial>
        <visual name="leg_3_MG996R_tibia_visual">
            <origin xyz="0.03160767064794936 0.031607669100800366 -0.015000003203434626" rpy="1.570796326794912 -9.73226585566182e-15 -2.3561944901923417" />
            <geometry>
                <mesh filename="CAD/MG996R.stl" scale="0.001 0.001 0.001" />
            </geometry>
            <material name="gray"/>
        </visual>
        <collision name="leg_3_MG996R_tibia_collision">
            <origin xyz="0.03160767064794936 0.031607669100800366 -0.015000003203434626" rpy="1.570796326794912 -9.73226585566182e-15 -2.3561944901923417" />
            <geometry>
                <mesh filename="CAD/MG996R.stl" scale="0.001 0.001 0.001" />
            </geometry>
        </collision>
    </link>

    <link name="leg_3_tibia">
        <inertial>
            <origin xyz="-0.016293305911521134 -0.013010898494947831 -0.012514301101988463" rpy="0.0 -2.2420775429197073e-44 0.0" />
            <mass value="0.2763071087572843" />
            <inertia ixx="0.00022676380370819163" iyy="0.00022675750126915217" izz="0.0003499834101106415" ixy="0.00012254451068291307" iyz="-4.915153995140009e-05" ixz="4.534317847601942e-05" />
        </inertial>
        <visual name="leg_3_tibia_visual">
            <origin xyz="-0.00954594100702609 -0.02085964899297462 3.1289284607716185e-09" rpy="-9.793498195619373e-15 1.626476731075843e-14 0.7853981633974472" />
            <geometry>
                <mesh filename="CAD/tibia.stl" scale="0.001 0.001 0.001" />
            </geometry>
            <material name="gray"/>
        </visual>
        <collision name="leg_3_tibia_collision">
            <origin xyz="-0.00954594100702609 -0.02085964899297462 3.1289284607716185e-09" rpy="-9.793498195619373e-15 1.626476731075843e-14 0.7853981633974472" />
            <geometry>
                <mesh filename="CAD/tibia.stl" scale="0.001 0.001 0.001" />
            </geometry>
        </collision>
    </link>

    <!--Leg 4 links-->

    <link name="leg_4_MG996R_coxa">
        <inertial>
            <origin xyz="0.021356601892567984 0.013931978777495626 0.008369892907608431" rpy="0.0 -0.0 0.0" />
            <mass value="0.20795327871559424" />
            <inertia ixx="3.989640031184334e-05" iyy="3.9896394178338176e-05" izz="3.6226092838468347e-05" ixy="-1.1428841708134357e-05" iyz="3.3491188439392313e-07" ixz="3.349213929005083e-07" />
        </inertial>
        <visual name="leg_4_MG996R_coxa_visual">
            <origin xyz="0.00014141702085558095 0.006505379253992185 -1.0436096431476481e-16" rpy="-3.1415926535897922 -1.4200236336338573e-15 0.7853981633974425" />
            <geometry>
                <mesh filename="CAD/MG996R.stl" scale="0.001 0.001 0.001" />
            </geometry>
            <material name="gray"/>
        </visual>
        <collision name="leg_4_MG996R_coxa_collision">
            <origin xyz="0.00014141702085558095 0.006505379253992185 -1.0436096431476481e-16" rpy="-3.1415926535897922 -1.4200236336338573e-15 0.7853981633974425" />
            <geometry>
                <mesh filename="CAD/MG996R.stl" scale="0.001 0.001 0.001" />
            </geometry>
        </collision>
    </link>

    <link name="leg_4_coxa">
        <inertial>
            <origin xyz="0.021868759892857463 0.02055764351497066 -0.02057289751484029" rpy="0.0 -0.0 -3.639458360361538e-94" />
            <mass value="0.23210805328252054" />
            <inertia ixx="0.00010185659819880385" iyy="0.00011376262401915113" izz="0.00011113698714720812" ixy="-3.3273760382550224e-06" iyz="4.068348060655847e-06" ixz="4.3504835339222905e-06" />
        </inertial>
        <visual name="leg_4_coxa_visual">
            <origin xyz="0.14799063143944277 -0.014788105268162469 -0.13141885371547835" rpy="-3.1415926535897922 0.7853981633974374 2.3561944901923426" />
            <geometry>
                <mesh filename="CAD/coxa.stl" scale="0.001 0.001 0.001" />
            </geometry>
            <material name="gray"/>
        </visual>
        <collision name="leg_4_coxa_collision">
            <origin xyz="0.14799063143944277 -0.014788105268162469 -0.13141885371547835" rpy="-3.1415926535897922 0.7853981633974374 2.3561944901923426" />
            <geometry>
                <mesh filename="CAD/coxa.stl" scale="0.001 0.001 0.001" />
            </geometry>
        </collision>
    </link>
    
    <link name="leg_4_MG996R_femur">
        <inertial>
            <origin xyz="0.006349555649617446 -0.023117809266444453 0.006349563295029368" rpy="0.0 -0.0 0.0" />
            <mass value="0.20795327871559424" />
            <inertia ixx="4.159921232988117e-05" iyy="3.2820467840353074e-05" izz="4.1599207158417576e-05" ixy="-2.743062064135874e-06" iyz="-2.743052273853535e-06" ixz="-9.726029209075528e-06" />
        </inertial>
        <visual name="leg_4_MG996R_femur_visual">
            <origin xyz="0.007302394791956069 -0.04335710949682765 -0.0064861829108407675" rpy="0.9553166181244949 -0.523598775598305 0.9553166181245125" />
            <geometry>
                <mesh filename="CAD/MG996R.stl" scale="0.001 0.001 0.001" />
            </geometry>
            <material name="gray"/>
        </visual>
        <collision name="leg_4_MG996R_femur_collision">
            <origin xyz="0.007302394791956069 -0.04335710949682765 -0.0064861829108407675" rpy="0.9553166181244949 -0.523598775598305 0.9553166181245125" />
            <geometry>
                <mesh filename="CAD/MG996R.stl" scale="0.001 0.001 0.001" />
            </geometry>
        </collision>
    </link>
    
    <link name="leg_4_femur">
        <inertial>
            <origin xyz="0.042389884762424224 0.032280585633616445 0.005250003203434553" rpy="0.0 -0.0 -7.232261714561531e-88" />
            <mass value="0.1615808293904576" />
            <inertia ixx="0.00011199064455003462" iyy="0.00011199064455002595" izz="0.0001882042970119211" ixy="-9.148253177655198e-05" iyz="1.6534083130403945e-18" ixz="4.878909776185066e-19" />
        </inertial>
        <visual name="leg_4_femur_visual">
            <origin xyz="0.06738727417201792 0.04758828275164369 0.005250003203434126" rpy="1.5707963267948801 -9.748148617451564e-15 -2.356194490192348" />
            <geometry>
                <mesh filename="CAD/femur.stl" scale="0.001 0.001 0.001" />
            </geometry>
            <material name="gray"/>
        </visual>
        <collision name="leg_4_femur_collision">
            <origin xyz="0.06738727417201792 0.04758828275164369 0.005250003203434126" rpy="1.5707963267948801 -9.748148617451564e-15 -2.356194490192348" />
            <geometry>
                <mesh filename="CAD/femur.stl" scale="0.001 0.001 0.001" />
            </geometry>
        </collision>
    </link>
    
    <link name="leg_4_MG996R_tibia">
        <inertial>
            <origin xyz="0.025259762829380784 -0.010028832666983796 -0.005250001000745914" rpy="0.0 -0.0 3.4039998179667605e-86" />
            <mass value="0.20795327871559424" />
            <inertia ixx="3.2820467840354375e-05" iyy="3.1873180535075575e-05" izz="5.13252389532249e-05" ixy="3.8792686507570576e-06" iyz="2.585731704706634e-12" ixz="6.922773986006714e-12" />
        </inertial>
        <visual name="leg_4_MG996R_tibia_visual">
            <origin xyz="0.005020462598997799 -0.001626348502151096 -0.015000003203434104" rpy="1.5707963267949132 -9.870613297366339e-15 -0.7853981633974425" />
            <geometry>
                <mesh filename="CAD/MG996R.stl" scale="0.001 0.001 0.001" />
            </geometry>
            <material name="gray"/>
        </visual>
        <collision name="leg_4_MG996R_tibia_collision">
            <origin xyz="0.005020462598997799 -0.001626348502151096 -0.015000003203434104" rpy="1.5707963267949132 -9.870613297366339e-15 -0.7853981633974425" />
            <geometry>
                <mesh filename="CAD/MG996R.stl" scale="0.001 0.001 0.001" />
            </geometry>
        </collision>
    </link>
    
    <link name="leg_4_tibia">
        <inertial>
            <origin xyz="-0.013010896795149716 0.01629330506162134 -0.012514301101988999" rpy="0.0 -0.0 6.147317420373909e-58" />
            <mass value="0.2763071087572843" />
            <inertia ixx="0.00022675750126915223" iyy="0.00022676380370819597" izz="0.00034998341011064846" ixy="-0.00012254451068291483" iyz="-4.5343178476019096e-05" ixz="-4.9151539951400165e-05" />
        </inertial>
        <visual name="leg_4_tibia_visual">
            <origin xyz="-0.020859647293176523 0.009545940157126296 3.12892792897479e-09" rpy="-9.931845637323421e-15 1.7430501486614835e-14 -0.7853981633974519" />
            <geometry>
                <mesh filename="CAD/tibia.stl" scale="0.001 0.001 0.001" />
            </geometry>
            <material name="gray"/>
        </visual>
        <collision name="leg_4_tibia_collision">
            <origin xyz="-0.020859647293176523 0.009545940157126296 3.12892792897479e-09" rpy="-9.931845637323421e-15 1.7430501486614835e-14 -0.7853981633974519" />
            <geometry>
                <mesh filename="CAD/tibia.stl" scale="0.001 0.001 0.001" />
            </geometry>
        </collision>
    </link>
    
    <!--Leg 5 links-->

    <link name="leg_5_MG996R_coxa">
        <inertial>
            <origin xyz="0.024952799971140163 -0.005250002202687914 0.00836989290760853" rpy="0.0 -0.0 0.0" />
            <mass value="0.20795327871559424" />
            <inertia ixx="2.846755553695643e-05" iyy="5.132523895322544e-05" izz="3.622609283846878e-05" ixy="-3.0667525713577936e-12" iyz="-6.723529465673595e-12" ixz="4.736436526392104e-07" />
        </inertial>
        <visual name="leg_5_MG996R_coxa_visual">
            <origin xyz="0.004699999999999935 0.0044999999999999945 2.220446049250414e-18" rpy="-3.1415926535897922 -9.093296690514655e-16 8.326672684688699e-17" />
            <geometry>
                <mesh filename="CAD/MG996R.stl" scale="0.001 0.001 0.001" />
            </geometry>
            <material name="gray"/>
        </visual>
        <collision name="leg_5_MG996R_coxa_collision">
            <origin xyz="0.004699999999999935 0.0044999999999999945 2.220446049250414e-18" rpy="-3.1415926535897922 -9.093296690514655e-16 8.326672684688699e-17" />
            <geometry>
                <mesh filename="CAD/MG996R.stl" scale="0.001 0.001 0.001" />
            </geometry>
        </collision>
    </link>

    <link name="leg_5_coxa">
        <inertial>
            <origin xyz="0.03000000000000104 -0.0009270992817275214 -0.020572897514840132" rpy="0.0 -0.0 0.0" />
            <mass value="0.23210805328252054" />
            <inertia ixx="0.00010448223507071912" iyy="0.00011113698714723327" izz="0.00011113698714720985" ixy="5.953012910174854e-06" iyz="-1.9949990636118653e-07" ixz="5.953012910191229e-06" />
        </inertial>
        <visual name="leg_5_coxa_visual">
            <origin xyz="0.09418841197586111 -0.11510194855892598 -0.13141885371547815" rpy="-3.141592653589791 0.7853981633974384 1.5707963267949006" />
            <geometry>
                <mesh filename="CAD/coxa.stl" scale="0.001 0.001 0.001" />
            </geometry>
            <material name="gray"/>
        </visual>
        <collision name="leg_5_coxa_collision">
            <origin xyz="0.09418841197586111 -0.11510194855892598 -0.13141885371547815" rpy="-3.141592653589791 0.7853981633974384 1.5707963267949006" />
            <geometry>
                <mesh filename="CAD/coxa.stl" scale="0.001 0.001 0.001" />
            </geometry>
        </collision>
    </link>
    
    <link name="leg_5_MG996R_femur">
        <inertial>
            <origin xyz="-0.0070690917559914366 -0.02269632029582686 -0.007069084110579098" rpy="-4.930380657631324e-32 -0.0 -4.930380657631324e-32" />
            <mass value="0.20795327871559424" />
            <inertia ixx="3.989639417833662e-05" iyy="3.6226092838469864e-05" izz="3.98964003118419e-05" ixy="3.3491188439370073e-07" iyz="3.34921392900621e-07" ixz="-1.142884170813304e-05" />
        </inertial>
        <visual name="leg_5_MG996R_femur_visual">
            <origin xyz="-0.01449569127949495 -0.03106621320343564 -0.028284268982291378" rpy="1.5707963267948784 -0.7853981633974544 5.730837474195829e-15" />
            <geometry>
                <mesh filename="CAD/MG996R.stl" scale="0.001 0.001 0.001" />
            </geometry>
            <material name="gray"/>
        </visual>
        <collision name="leg_5_MG996R_femur_collision">
            <origin xyz="-0.01449569127949495 -0.03106621320343564 -0.028284268982291378" rpy="1.5707963267948784 -0.7853981633974544 5.730837474195829e-15" />
            <geometry>
                <mesh filename="CAD/MG996R.stl" scale="0.001 0.001 0.001" />
            </geometry>
        </collision>
    </link>
    
    <link name="leg_5_femur">
        <inertial>
            <origin xyz="0.052800000000009034 -0.007148349669586955 0.005250003203434624" rpy="0.0 -0.0 4.7983281690828655e-61" />
            <mass value="0.1615808293904576" />
            <inertia ixx="2.0508112773477925e-05" iyy="0.00020347317632658183" izz="0.0001882042970119211" ixy="-6.491660507756958e-18" iyz="8.089164646278567e-19" ixz="1.5720931501039814e-18" />
        </inertial>
        <visual name="leg_5_femur_visual">
            <origin xyz="0.08130000000000039 -0.013999996796564438 0.0052500032034341615" rpy="1.570796326794881 -1.1201229588897236e-14 -3.141592653589791" />
            <geometry>
                <mesh filename="CAD/femur.stl" scale="0.001 0.001 0.001" />
            </geometry>
            <material name="gray"/>
        </visual>
        <collision name="leg_5_femur_collision">
            <origin xyz="0.08130000000000039 -0.013999996796564438 0.0052500032034341615" rpy="1.570796326794881 -1.1201229588897236e-14 -3.141592653589791" />
            <geometry>
                <mesh filename="CAD/femur.stl" scale="0.001 0.001 0.001" />
            </geometry>
        </collision>
    </link>
    
    <link name="leg_5_MG996R_tibia">
        <inertial>
            <origin xyz="0.024952799971140287 0.008369889704173064 -0.005250001000746001" rpy="0.0 -0.0 0.0" />
            <mass value="0.20795327871559424" />
            <inertia ixx="2.8467555536956237e-05" iyy="3.6226092838469864e-05" izz="5.132523895322316e-05" ixy="4.7364365263960343e-07" iyz="6.723528870784687e-12" ixz="3.066752038947962e-12" />
        </inertial>
        <visual name="leg_5_MG996R_tibia_visual">
            <origin xyz="0.004700000000000202 -3.203435311460723e-09 -0.015000003203434214" rpy="1.5707963267949123 -1.132369426881202e-14 -1.3877787807814537e-17" />
            <geometry>
                <mesh filename="CAD/MG996R.stl" scale="0.001 0.001 0.001" />
            </geometry>
            <material name="gray"/>
        </visual>
        <collision name="leg_5_MG996R_tibia_collision">
            <origin xyz="0.004700000000000202 -3.203435311460723e-09 -0.015000003203434214" rpy="1.5707963267949123 -1.132369426881202e-14 -1.3877787807814537e-17" />
            <geometry>
                <mesh filename="CAD/MG996R.stl" scale="0.001 0.001 0.001" />
            </geometry>
        </collision>
    </link>
    
    <link name="leg_5_tibia">
        <inertial>
            <origin xyz="0.0023210121801044183 0.020721202778113006 -0.012514301101988944" rpy="0.0 -1.7105694144590052e-49 -2.2360048880579473e-94" />
            <mass value="0.2763071087572843" />
            <inertia ixx="0.00010421614180576054" iyy="0.0003493051631715832" izz="0.0003499834101106449" ixy="3.151219519158775e-09" iyz="2.6929182244511917e-06" ixz="-6.681785618634146e-05" />
        </inertial>
        <visual name="leg_5_tibia_visual">
            <origin xyz="-0.008000000000000184 0.02150000000000045 3.1289279989188403e-09" rpy="-1.1384926608769353e-14 1.6431300764452345e-14 -1.5707963267948948" />
            <geometry>
                <mesh filename="CAD/tibia.stl" scale="0.001 0.001 0.001" />
            </geometry>
            <material name="gray"/>
        </visual>
        <collision name="leg_5_tibia_collision">
            <origin xyz="-0.008000000000000184 0.02150000000000045 3.1289279989188403e-09" rpy="-1.1384926608769353e-14 1.6431300764452345e-14 -1.5707963267948948" />
            <geometry>
                <mesh filename="CAD/tibia.stl" scale="0.001 0.001 0.001" />
            </geometry>
        </collision>
    </link>
    
    <!--Leg 6 links-->
    
    <link name="leg_6_MG996R_coxa">
        <inertial>
            <origin xyz="0.013931978777496652 -0.02135660189256688 0.008369892907608477" rpy="0.0 -0.0 0.0" />
            <mass value="0.20795327871559424" />
            <inertia ixx="3.9896394178338826e-05" iyy="3.989640031184366e-05" izz="3.6226092838467696e-05" ixy="1.142884170813479e-05" iyz="-3.34921392900427e-07" ixz="3.349118843938689e-07" />
        </inertial>
        <visual name="leg_6_MG996R_coxa_visual">
            <origin xyz="0.006505379253993113 -0.00014141702085441744 -4.996003610813174e-17" rpy="-3.1415926535897922 -9.158348820863758e-16 -0.7853981633974509" />
            <geometry>
                <mesh filename="CAD/MG996R.stl" scale="0.001 0.001 0.001" />
            </geometry>
            <material name="gray"/>
        </visual>
        <collision name="leg_6_MG996R_coxa_collision">
            <origin xyz="0.006505379253993113 -0.00014141702085441744 -4.996003610813174e-17" rpy="-3.1415926535897922 -9.158348820863758e-16 -0.7853981633974509" />
            <geometry>
                <mesh filename="CAD/MG996R.stl" scale="0.001 0.001 0.001" />
            </geometry>
        </collision>
    </link>

    <link name="leg_6_coxa">
        <inertial>
            <origin xyz="0.02055764351497186 -0.021868759892856193 -0.020572897514840153" rpy="4.3790577010150533e-47 -0.0 3.111507638930571e-61" />
            <mass value="0.23210805328252054" />
            <inertia ixx="0.00011376262401917257" iyy="0.00010185659819881814" izz="0.00011113698714718728" ixy="3.327376038250251e-06" iyz="-4.350483533920608e-06" ixz="4.068348060653271e-06" />
        </inertial>
        <visual name="leg_6_coxa_visual">
            <origin xyz="-0.014788105268161118 -0.14799063143944197 -0.13141885371547823" rpy="-3.141592653589791 0.785398163397437 0.785398163397449" />
            <geometry>
                <mesh filename="CAD/coxa.stl" scale="0.001 0.001 0.001" />
            </geometry>
            <material name="gray"/>
        </visual>
        <collision name="leg_6_coxa_collision">
            <origin xyz="-0.014788105268161118 -0.14799063143944197 -0.13141885371547823" rpy="-3.141592653589791 0.785398163397437 0.785398163397449" />
            <geometry>
                <mesh filename="CAD/coxa.stl" scale="0.001 0.001 0.001" />
            </geometry>
        </collision>
    </link>
    
    <link name="leg_6_MG996R_femur">
        <inertial>
            <origin xyz="-0.016346763521187226 -0.008979633120855812 -0.016346755875774895" rpy="0.0 -0.0 0.0" />
            <mass value="0.20795327871559424" />
            <inertia ixx="4.207284647401336e-05" iyy="3.1873180535074274e-05" izz="4.207286031956373e-05" ixy="2.7430553406061446e-06" iyz="2.743058997383261e-06" ixz="-9.252385556434607e-06" />
        </inertial>
        <visual name="leg_6_MG996R_femur_visual">
            <origin xyz="-0.02376381728645736 -0.000577148956023219 -0.03755239498925375" rpy="2.1862760354652693 -0.5235987755983055 -0.9553166181245129" />
            <geometry>
                <mesh filename="CAD/MG996R.stl" scale="0.001 0.001 0.001" />
            </geometry>
            <material name="gray"/>
        </visual>
        <collision name="leg_6_MG996R_femur_collision">
            <origin xyz="-0.02376381728645736 -0.000577148956023219 -0.03755239498925375" rpy="2.1862760354652693 -0.5235987755983055 -0.9553166181245129" />
            <geometry>
                <mesh filename="CAD/MG996R.stl" scale="0.001 0.001 0.001" />
            </geometry>
        </collision>
    </link>
    
    <link name="leg_6_tibia">
        <inertial>
            <origin xyz="0.016293311336470922 0.013010903069998747 -0.012514301101988977" rpy="0.0 -0.0 6.632569297679744e-58" />
            <mass value="0.2763071087572843" />
            <inertia ixx="0.0002267638037081899" iyy="0.0002267575012691556" izz="0.000349983410110645" ixy="0.00012254451068291133" iyz="4.9151539951400165e-05" ixz="-4.53431784760193e-05" />
        </inertial>
        <visual name="leg_6_tibia_visual">
            <origin xyz="0.009545946431975878 0.020859653568025573 3.1289279645019262e-09" rpy="-1.1147498751977139e-14 1.6708856520608726e-14 -2.3561944901923457" />
            <geometry>
                <mesh filename="CAD/tibia.stl" scale="0.001 0.001 0.001" />
            </geometry>
            <material name="gray"/>
        </visual>
        <collision name="leg_6_tibia_collision">
            <origin xyz="0.009545946431975878 0.020859653568025573 3.1289279645019262e-09" rpy="-1.1147498751977139e-14 1.6708856520608726e-14 -2.3561944901923457" />
            <geometry>
                <mesh filename="CAD/tibia.stl" scale="0.001 0.001 0.001" />
            </geometry>
        </collision>
    </link>
    
    <link name="leg_6_MG996R_tibia">
        <inertial>
            <origin xyz="0.011725888941833294 0.023562706554531784 -0.005250001000745981" rpy="0.0 -0.0 -4.856228185289247e-58" />
            <mass value="0.20795327871559424" />
            <inertia ixx="3.187318053507384e-05" iyy="3.282046784035436e-05" izz="5.132523895322316e-05" ixy="-3.879268650757057e-06" iyz="6.922774040216821e-12" ixz="-2.5857316504965255e-12" />
        </inertial>
        <visual name="leg_6_MG996R_tibia_visual">
            <origin xyz="0.003323404777000523 0.0033234063241487635 -0.015000003203434194" rpy="1.5707963267949125 -1.1086266412020033e-14 0.7853981633974512" />
            <geometry>
                <mesh filename="CAD/MG996R.stl" scale="0.001 0.001 0.001" />
            </geometry>
            <material name="gray"/>
        </visual>
        <collision name="leg_6_MG996R_tibia_collision">
            <origin xyz="0.003323404777000523 0.0033234063241487635 -0.015000003203434194" rpy="1.5707963267949125 -1.1086266412020033e-14 0.7853981633974512" />
            <geometry>
                <mesh filename="CAD/MG996R.stl" scale="0.001 0.001 0.001" />
            </geometry>
        </collision>
    </link>
    
    <link name="leg_6_femur">
        <inertial>
            <origin xyz="0.03228058563361788 -0.04238988476242286 0.005250003203434654" rpy="0.0 -0.0 -1.0664120914407192e-87" />
            <mass value="0.1615808293904576" />
            <inertia ixx="0.00011199064455002464" iyy="0.00011199064455003641" izz="0.0001882042970119185" ixy="9.1482531776552e-05" iyz="-5.4210108624275135e-19" ixz="1.707618421664701e-18" />
        </inertial>
        <visual name="leg_6_femur_visual">
            <origin xyz="0.047588282751645235 -0.06738727417201658 0.005250003203434197" rpy="1.5707963267948808 -1.096380173210526e-14 2.356194490192345" />
            <geometry>
                <mesh filename="CAD/femur.stl" scale="0.001 0.001 0.001" />
            </geometry>
            <material name="gray"/>
        </visual>
        <collision name="leg_6_femur_collision">
            <origin xyz="0.047588282751645235 -0.06738727417201658 0.005250003203434197" rpy="1.5707963267948808 -1.096380173210526e-14 2.356194490192345" />
            <geometry>
                <mesh filename="CAD/femur.stl" scale="0.001 0.001 0.001" />
            </geometry>
        </collision>
    </link>
    
    <!--Leg 1 joints-->

    <joint name="base_leg_1" type="fixed">
        <origin xyz="0.03687244 0.05481281999999997 -3.3306690738754402e-18" rpy="1.5777218104420236e-30 3.155443620884054e-30 3.141592653589793" />
        <parent link="base" />
        <child link="leg_1_MG996R_coxa" />
    </joint>

    <joint name="leg_1_coxa" type="continuous">
        <origin xyz="-0.02100107 -0.028425689999999993 0.03106621" rpy="9.860761315262648e-32 -0.0 9.80394874699742e-31" />
        <parent link="leg_1_MG996R_coxa" />
        <child link="leg_1_coxa" />
        <axis xyz="-0.0 -9.860761315262648e-32 -1.0" />
    </joint>
    
    <joint name="leg_1_femur" type="continuous">
        <origin xyz="-0.057629200000000005 -0.027223610000000013 -0.0215" rpy="-7.942107605087364e-16 0.7853981633974434 3.1415926535897927" />
        <parent link="leg_1_coxa" />
        <child link="leg_1_MG996R_femur" />
        <axis xyz="0.5000001547244789 -0.7071069999999999 0.5000001547244733" />
    </joint>
    
    <joint name="leg_leg_1_MG996R_femur" type="fixed">
        <origin xyz="-0.01904579387203917 0.011749440000000017 -0.02647041507449769" rpy="-5.248374545410791e-16 0.7853981633974433 -3.141592653589793" />
        <parent link="leg_1_MG996R_femur" />
        <child link="leg_1_femur" />
    </joint>
    
    <joint name="leg_leg_1_femur_MG996R" type="fixed">
        <origin xyz="-0.07467046999999999 -0.07467047000000002 0.0" rpy="-3.141592653589793 7.056345106627914e-30 1.5777218104420236e-30" />
        <parent link="leg_1_femur" />
        <child link="leg_1_MG996R_tibia" />
    </joint>
    
    <joint name="leg_1_tibia" type="continuous">
        <origin xyz="-0.011749440000000017 -0.03218482000000002 -0.005250000000000001" rpy="3.141592653589793 -2.455971556515381e-28 1.5777218104420236e-30" />
        <parent link="leg_1_MG996R_tibia" />
        <child link="leg_1_tibia" />
        <axis xyz="0.707107 -0.707107 -2.4656518234403854e-29" />
    </joint>

    <!--Leg 2 joints-->

    <joint name="base_leg_2" type="fixed">
        <origin xyz="0.03713499999999998 0.005249999999999989 -3.3306690738753613e-18" rpy="1.5777218104420236e-30 3.155443620884054e-30 3.141592653589793" />
        <parent link="base" />
        <child link="leg_2_MG996R_coxa" />
    </joint>
    
    <joint name="leg_2_coxa" type="continuous">
        <origin xyz="-0.03495 0.00525 0.03106621" rpy="0.0 1.9721522630525295e-31 5.593936126472314e-33" />
        <parent link="leg_2_MG996R_coxa" />
        <child link="leg_2_coxa" />
        <axis xyz="1.9721522630525295e-31 0.0 -0.9999999999999999" />
    </joint>
    
    <joint name="leg_2_femur" type="continuous">
        <origin xyz="-0.06000000000000001 0.0215 -0.021500000000000005" rpy="-7.422322462533451e-16 0.7853981633974433 3.1415926535897927" />
        <parent link="leg_2_coxa" />
        <child link="leg_2_MG996R_femur" />
        <axis xyz="3.711161231266726e-16 -1.0 -3.711161231266763e-16" />
    </joint>
    
    <joint name="leg_leg_2_MG996R_femur" type="fixed">
        <origin xyz="-0.006505382386916309 0.03106621 -0.013930003589374955" rpy="-5.248374545410663e-16 0.7853981633974433 3.141592653589793" />
        <parent link="leg_2_MG996R_femur" />
        <child link="leg_2_femur" />
    </joint>
    
    <joint name="leg_leg_2_femur_MG996R" type="fixed">
        <origin xyz="-0.10559999999999999 0.0 0.0" rpy="-3.141592653589793 -1.135287644644703e-30 -1.5777218104420236e-30" />
        <parent link="leg_2_femur" />
        <child link="leg_2_MG996R_tibia" />
    </joint>
    
    <joint name="leg_2_tibia" type="continuous">
        <origin xyz="0.014450000000000003 -0.03106621 -0.005250000000000001" rpy="-3.141592653589793 -1.977608157853436e-31 -1.5777218104420236e-30" />
        <parent link="leg_2_MG996R_tibia" />
        <child link="leg_2_tibia" />
        <axis xyz="0.0 -0.9999999999999999 -1.5777218104420236e-30" />
    </joint>

    <!--Leg 3 joints-->
    
    <joint name="base_leg_3" type="fixed">
        <origin xyz="0.03687243999999997 -0.054812819999999984 -3.3306690738752677e-18" rpy="1.5777218104420236e-30 3.155443620884054e-30 3.141592653589793" />
        <parent link="base" />
        <child link="leg_3_MG996R_coxa" />
    </joint>

    <joint name="leg_3_coxa" type="continuous">
        <origin xyz="-0.02100107 0.028425689999999993 0.03106621" rpy="0.0 -1.9721522630525295e-31 -3.390661277973094e-45" />
        <parent link="leg_3_MG996R_coxa" />
        <child link="leg_3_coxa" />
        <axis xyz="-1.9721522630525295e-31 0.0 -0.9999999999999999" />
    </joint>
    
    <joint name="leg_3_femur" type="continuous">
        <origin xyz="-0.027223610000000002 0.05762920000000001 -0.02150000000000001" rpy="-7.080538306756965e-16 0.7853981633974434 3.1415926535897927" />
        <parent link="leg_3_coxa" />
        <child link="leg_3_MG996R_femur" />
        <axis xyz="-0.5000001547244785 -0.707107 -0.5000001547244738" />
    </joint>
    
    <joint name="leg_leg_3_MG996R_femur" type="fixed">
        <origin xyz="0.012020419300373853 0.032184819999999996 0.004595798097915056" rpy="-4.693263033098109e-16 0.7853981633974433 -3.141592653589793" />
        <parent link="leg_3_MG996R_femur" />
        <child link="leg_3_femur" />
    </joint>
    
    <joint name="leg_leg_3_femur_MG996R" type="fixed">
        <origin xyz="-0.07467047000000002 0.07467047000000002 0.0" rpy="3.141592653589793 9.509787901705745e-30 -1.5777218104420236e-30" />
        <parent link="leg_3_femur" />
        <child link="leg_3_MG996R_tibia" />
    </joint>
    
    <joint name="leg_3_tibia" type="continuous">
        <origin xyz="0.03218482000000002 -0.01174944 -0.00525" rpy="-3.141592653589793 -3.1507118818835715e-28 -1.577721810442024e-30" />
        <parent link="leg_3_MG996R_tibia" />
        <child link="leg_3_tibia" />
        <axis xyz="-0.707107 -0.7071069999999999 3.247757628198293e-29" />
    </joint>
    
    <!--Leg 4 joints-->

    <joint name="base_leg_4" type="fixed">
        <origin xyz="-0.02944782 -0.06223743999999996 -3.330669073875465e-18" rpy="1.5777218104420236e-30 3.155443620884054e-30 3.141592653589793" />
        <parent link="base" />
        <child link="leg_4_MG996R_coxa" />
    </joint>

    <joint name="leg_4_coxa" type="continuous">
        <origin xyz="0.028425690000000003 0.021001069999999997 0.03106621" rpy="-1.9721522630525295e-31 -1.9721522630525295e-31 -1.4971863295389187e-31" />
        <parent link="leg_4_MG996R_coxa" />
        <child link="leg_4_coxa" />
        <axis xyz="-1.9721522630525295e-31 1.9721522630525295e-31 -1.0" />
    </joint>
    
    <joint name="leg_4_femur" type="continuous">
        <origin xyz="0.057629200000000005 0.027223610000000013 -0.0215" rpy="-6.469461358014946e-16 0.7853981633974433 3.1415926535897927" />
        <parent link="leg_4_coxa" />
        <child link="leg_4_MG996R_femur" />
        <axis xyz="-0.500000154724479 0.707107 -0.5000001547244732" />
    </joint>
    
    <joint name="leg_leg_4_MG996R_femur" type="fixed">
        <origin xyz="0.026470415074497888 -0.01174944 0.019045793872038887" rpy="-4.693263033098162e-16 0.7853981633974433 3.141592653589793" />
        <parent link="leg_4_MG996R_femur" />
        <child link="leg_4_femur" />
    </joint>
    
    <joint name="leg_leg_4_femur_MG996R" type="fixed">
        <origin xyz="0.04030507999999999 0.040305080000000014 0.0" rpy="-3.141592653589793 1.4056744540022418e-29 -3.1554436208840472e-30" />
        <parent link="leg_4_femur" />
        <child link="leg_4_MG996R_tibia" />
    </joint>
    
    <joint name="leg_4_tibia" type="continuous">
        <origin xyz="0.048377570000000016 -0.001049199999999999 -0.005250000000000001" rpy="3.141592653589793 -3.392272815550781e-28 -4.592132580746781e-86" />
        <parent link="leg_4_MG996R_tibia" />
        <child link="leg_4_tibia" />
        <axis xyz="-0.707107 0.707107 4.337944936001927e-29" />
    </joint>
    
    <!--Leg 5 joints-->

    <joint name="base_leg_5" type="fixed">
        <origin xyz="-0.03713499999999998 -0.005249999999999989 -3.3306690738755793e-18" rpy="1.5777218104420236e-30 3.155443620884054e-30 3.141592653589793" />
        <parent link="base" />
        <child link="leg_5_MG996R_coxa" />
    </joint>

    <joint name="leg_5_coxa" type="continuous">
        <origin xyz="0.03495 -0.00525 0.03106621" rpy="-9.860761315262648e-32 -0.0 1.0138806576528696e-32" />
        <parent link="leg_5_MG996R_coxa" />
        <child link="leg_5_coxa" />
        <axis xyz="0.0 9.860761315262648e-32 -1.0" />
    </joint>
    
    <joint name="leg_5_femur" type="continuous">
        <origin xyz="0.06000000000000001 -0.0215 -0.0215" rpy="-7.422322462533452e-16 0.7853981633974433 3.1415926535897927" />
        <parent link="leg_5_coxa" />
        <child link="leg_5_MG996R_femur" />
        <axis xyz="-3.711161231266728e-16 1.0 3.711161231266763e-16" />
    </joint>
    
    <joint name="leg_leg_5_MG996R_femur" type="fixed">
        <origin xyz="0.013930003589375026 -0.031066209999999997 0.006505382386916168" rpy="-5.248374545410629e-16 0.7853981633974433 3.141592653589793" />
        <parent link="leg_5_MG996R_femur" />
        <child link="leg_5_femur" />
    </joint>
    
    <joint name="leg_leg_5_femur_MG996R" type="fixed">
        <origin xyz="0.056999999999999995 0.0 0.0" rpy="3.141592653589793 2.505999984693438e-31 1.5777218104420236e-30" />
        <parent link="leg_5_femur" />
        <child link="leg_5_MG996R_tibia" />
    </joint>
    
    <joint name="leg_5_tibia" type="continuous">
        <origin xyz="0.03495000000000001 0.03106621 -0.005250000000000001" rpy="-3.141592653589793 9.729700613564994e-32 1.5777218104420236e-30" />
        <parent link="leg_5_MG996R_tibia" />
        <child link="leg_5_tibia" />
        <axis xyz="-1.5777218104420236e-30 0.9999999999999999 0.0" />
    </joint>

    <!--Leg 6 joints-->

    <joint name="base_leg_6" type="fixed">
        <origin xyz="-0.03687243999999997 0.054812819999999984 -3.330669073875673e-18" rpy="1.5777218104420236e-30 3.155443620884054e-30 3.141592653589793" />
        <parent link="base" />
        <child link="leg_6_MG996R_coxa" />
    </joint>
    
    <joint name="leg_6_coxa" type="continuous">
        <origin xyz="0.02100107 -0.028425689999999993 0.03106621" rpy="1.97215226305253e-31 -0.0 1.6819919341129893e-45" />
        <parent link="leg_6_MG996R_coxa" />
        <child link="leg_6_coxa" />
        <axis xyz="0.0 -1.9721522630525295e-31 -0.9999999999999999" />
    </joint>

    <joint name="leg_6_femur" type="continuous">
        <origin xyz="0.027223610000000002 -0.05762920000000003 -0.021500000000000005" rpy="-6.349165004021658e-16 0.7853981633974433 3.1415926535897927" />
        <parent link="leg_6_coxa" />
        <child link="leg_6_MG996R_femur" />
        <axis xyz="0.5000001547244782 0.707107 0.5000001547244738" />
    </joint>
    
    <joint name="leg_leg_6_MG996R_femur" type="fixed">
        <origin xyz="-0.004595798097915136 -0.032184819999999996 -0.012020419300373826" rpy="-4.693263033098209e-16 0.7853981633974433 -3.141592653589793" />
        <parent link="leg_6_MG996R_femur" />
        <child link="leg_6_femur" />
    </joint>
    
    <joint name="leg_leg_6_femur_MG996R" type="fixed">
        <origin xyz="0.04030507999999999 -0.04030507999999998 0.0" rpy="3.141592653589793 1.1441314436637283e-29 -1.5777218104420233e-30" />
        <parent link="leg_6_femur" />
        <child link="leg_6_MG996R_tibia" />
    </joint>
    
    <joint name="leg_6_tibia" type="continuous">
        <origin xyz="0.0027462500000000035 0.04668052000000001 -0.005250000000000001" rpy="-3.141592653589793 -3.640945256296552e-28 -1.577721810442024e-30" />
        <parent link="leg_6_MG996R_tibia" />
        <child link="leg_6_tibia" />
        <axis xyz="0.707107 0.7071069999999999 -4.4724723353636215e-29" />
    </joint>

</robot>