<?xml version='1.0' encoding='utf-8'?>
<robot name="hexapod">

    <material name="black">
        <color rgba="0 0 0 1" />
    </material>

    <material name="gray">
        <color rgba="0.4 0.4 0.4 1" />
    </material>

    <material name="white">
        <color rgba="1 1 1 1" />
    </material>

    <material name="orange">
        <color rgba="0.902 0.345 0 1" />
    </material>

    <!--Body links-->

    <link name="base">
        <inertial>
            <origin xyz="-1.762648324756278e-14 -5.050033455416569e-14 0.00698680031349181" rpy="0.0 0.0 0.0" />
            <mass value="0.6789580603579961" />
            <inertia ixx="0.0024074595101577626" iyy="0.002204354035625284" izz="0.004589855549230958" ixy="5.568836058961683e-16" iyz="-1.2787511591555878e-18" ixz="-2.581826811457711e-18" />
        </inertial>
        <visual name="base_visual">
            <origin xyz="0.0 0.0 0.0" rpy="0.0 0.0 0.0" />
            <geometry>
                <mesh filename="CAD/base.stl" scale="0.001 0.001 0.001" />
            </geometry>
            <material name="gray"/>
        </visual>
        <collision name="base_collision">
            <origin xyz="0.0 0.0 0.0" rpy="0.0 0.0 0.0" />
            <geometry>
                <mesh filename="CAD/base.stl" scale="0.001 0.001 0.001" />
            </geometry>
        </collision>
    </link>

    <!--Leg 1 links-->
    <link name="leg_1_MG996R_c">
        <inertial>
            <origin xyz="-0.0213566016347122 0.013931984749781528 0.00836989290746161" rpy="0.0 -0.0 0.0" />
            <mass value="0.207953278714177" />
            <inertia ixx="3.989639417761133e-05" iyy="3.989640031111844e-05" izz="3.6226092838335206e-05" ixy="1.1428841708080039e-05" iyz="3.349213930771384e-07" ixz="-3.349118845850951e-07" />
        </inertial>
        <visual name="leg_1_MG996R_c_visual">
            <origin xyz="-0.013930002111251416 -0.007283200121891475 2.2204460492503132e-17" rpy="3.141592653589793 1.245344534372108e-16 2.356194490192345" />
            <geometry>
                <mesh filename="CAD/MG996R.stl" scale="0.001 0.001 0.001" />
            </geometry>
            <material name="gray"/>
        </visual>
        <collision name="leg_1_MG996R_c_collision">
            <origin xyz="-0.013930002111251416 -0.007283200121891475 2.2204460492503132e-17" rpy="3.141592653589793 1.245344534372108e-16 2.356194490192345" />
            <geometry>
                <mesh filename="CAD/MG996R.stl" scale="0.001 0.001 0.001" />
            </geometry>
        </collision>
    </link>

    <link name="leg_1_MG996R_f">
        <inertial>
            <origin xyz="0.024952796767646526 0.009630716290236095 0.0022060948384998546" rpy="0.0 -0.0 0.0" />
            <mass value="0.207953278714177" />
            <inertia ixx="2.846755553628441e-05" iyy="4.377565917187119e-05" izz="4.377567261890959e-05" ixy="3.349144703087767e-07" iyz="-7.549573057054858e-06" ixz="3.349188073535178e-07" />
        </inertial>
        <visual name="leg_1_MG996R_f_visual">
            <origin xyz="0.004699996796564361 0.01060660093167094 -0.01060660586827753" rpy="2.3561944901923453 3.410597503508584e-17 1.540743955509788e-32" />
            <geometry>
                <mesh filename="CAD/MG996R.stl" scale="0.001 0.001 0.001" />
            </geometry>
            <material name="gray"/>
        </visual>
        <collision name="leg_1_MG996R_f_collision">
            <origin xyz="0.004699996796564361 0.01060660093167094 -0.01060660586827753" rpy="2.3561944901923453 3.410597503508584e-17 1.540743955509788e-32" />
            <geometry>
                <mesh filename="CAD/MG996R.stl" scale="0.001 0.001 0.001" />
            </geometry>
        </collision>
    </link>

    <link name="leg_1_MG996R_t">
        <inertial>
            <origin xyz="0.008979632074602933 -0.02311780679666102 4.09182035809863e-09" rpy="0.0 -0.0 7.002961686799377e-34" />
            <mass value="0.207953278714177" />
            <inertia ixx="3.187318053441031e-05" iyy="3.282046784020779e-05" izz="5.1325238952446006e-05" ixy="-3.879268651024205e-06" iyz="6.92276835135608e-12" ixz="-2.5857237346299217e-12" />
        </inertial>
        <visual name="leg_1_MG996R_t_visual">
            <origin xyz="0.0005771479097073318 -0.043357107026899176 -0.009749998110869998" rpy="1.5707963267948968 -2.529221735498422e-16 0.7853981633974484" />
            <geometry>
                <mesh filename="CAD/MG996R.stl" scale="0.001 0.001 0.001" />
            </geometry>
            <material name="gray"/>
        </visual>
        <collision name="leg_1_MG996R_t_collision">
            <origin xyz="0.0005771479097073318 -0.043357107026899176 -0.009749998110869998" rpy="1.5707963267948968 -2.529221735498422e-16 0.7853981633974484" />
            <geometry>
                <mesh filename="CAD/MG996R.stl" scale="0.001 0.001 0.001" />
            </geometry>
        </collision>
    </link>

    <link name="leg_1_coxa_a">
        <inertial>
            <origin xyz="0.008150925434592561 0.01830499415619695 0.0006271852210843588" rpy="0.0 -0.0 0.0" />
            <mass value="0.03329037594662584" />
            <inertia ixx="4.131218918157248e-06" iyy="4.292509549727152e-06" izz="8.13497513364118e-06" ixy="-3.4675873338201415e-06" iyz="-4.436065358599036e-08" ixz="-4.967608887462187e-08" />
        </inertial>
        <visual name="leg_1_coxa_a_visual">
            <origin xyz="-0.008308500528462624 0.0015909894715424855 -0.001750003203435586" rpy="-1.245344534372106e-16 1.5023172683244996e-16 -0.7853981633974481" />
            <geometry>
                <mesh filename="CAD/coxa_a_right.stl" scale="0.001 0.001 0.001" />
            </geometry>
            <material name="gray"/>
        </visual>
        <collision name="leg_1_coxa_a_collision">
            <origin xyz="-0.008308500528462624 0.0015909894715424855 -0.001750003203435586" rpy="-1.245344534372106e-16 1.5023172683244996e-16 -0.7853981633974481" />
            <geometry>
                <mesh filename="CAD/coxa_a_right.stl" scale="0.001 0.001 0.001" />
            </geometry>
        </collision>
    </link>

    <link name="leg_1_coxa_b">
        <inertial>
            <origin xyz="-0.016082730051457803 -0.015894011955612512 -0.005835649360206568" rpy="0.0 -0.0 0.0" />
            <mass value="0.04490836615745227" />
            <inertia ixx="7.570806724760545e-06" iyy="7.815179248384845e-06" izz="1.486969927151291e-05" ixy="-6.737300382606579e-06" iyz="-1.0459627444581849e-07" ixz="-1.0048041289742698e-07" />
        </inertial>
        <visual name="leg_1_coxa_b_visual">
            <origin xyz="-0.037476660528462616 -0.037476660528457516 0.04149999679656438" rpy="-1.245344534372106e-16 1.5023172683245e-16 -0.7853981633974481" />
            <geometry>
                <mesh filename="CAD/coxa_b_right.stl" scale="0.001 0.001 0.001" />
            </geometry>
            <material name="gray"/>
        </visual>
        <collision name="leg_1_coxa_b_collision">
            <origin xyz="-0.037476660528462616 -0.037476660528457516 0.04149999679656438" rpy="-1.245344534372106e-16 1.5023172683245e-16 -0.7853981633974481" />
            <geometry>
                <mesh filename="CAD/coxa_b_right.stl" scale="0.001 0.001 0.001" />
            </geometry>
        </collision>
    </link>

    <link name="leg_1_femur_a">
        <inertial>
            <origin xyz="-0.007313766969440483 -0.0018738117298011225 0.03907114287949463" rpy="0.0 -0.0 0.0" />
            <mass value="0.06532641332455354" />
            <inertia ixx="4.0924780174512575e-05" iyy="4.0827509479549485e-05" izz="8.434001460605163e-06" ixy="-3.990162260728773e-06" iyz="7.2994033516955215e-06" ixz="7.334386903970892e-06" />
        </inertial>
        <visual name="leg_1_femur_a_visual">
            <origin xyz="-0.0007071020514142746 0.0007071066182250796 -3.203435625653839e-09" rpy="1.5707963267948966 -0.6108652381980162 -2.356194490192345" />
            <geometry>
                <mesh filename="CAD/femur_a_right.stl" scale="0.001 0.001 0.001" />
            </geometry>
            <material name="gray"/>
        </visual>
        <collision name="leg_1_femur_a_collision">
            <origin xyz="-0.0007071020514142746 0.0007071066182250796 -3.203435625653839e-09" rpy="1.5707963267948966 -0.6108652381980162 -2.356194490192345" />
            <geometry>
                <mesh filename="CAD/femur_a_right.stl" scale="0.001 0.001 0.001" />
            </geometry>
        </collision>
    </link>
    
    <link name="leg_1_femur_b">
        <inertial>
            <origin xyz="0.015606805962859537 0.015152340349115861 -0.0052004379221506185" rpy="0.0 -0.0 -7.002961686799377e-34" />
            <mass value="0.0800214310563922" />
            <inertia ixx="9.693159673782297e-06" iyy="9.69315967378208e-06" izz="1.3901924233197978e-05" ixy="-5.667417293105776e-06" iyz="-1.3985747771352728e-07" ixz="1.398574777137448e-07" />
        </inertial>
        <visual name="leg_1_femur_b_visual">
            <origin xyz="-2.051414238479765e-09 3.3817748779085832e-09 0.04770578320343561" rpy="-1.5707963267948968 0.6108652381980162 2.356194490192345" />
            <geometry>
                <mesh filename="CAD/femur_b_right.stl" scale="0.001 0.001 0.001" />
            </geometry>
            <material name="gray"/>
        </visual>
        <collision name="leg_1_femur_b_collision">
            <origin xyz="-2.051414238479765e-09 3.3817748779085832e-09 0.04770578320343561" rpy="-1.5707963267948968 0.6108652381980162 2.356194490192345" />
            <geometry>
                <mesh filename="CAD/femur_b_right.stl" scale="0.001 0.001 0.001" />
            </geometry>
        </collision>
    </link>

    <link name="leg_1_femur_c">
        <inertial>
            <origin xyz="-0.0010886446390956995 -0.004918304334164514 -0.006733416303654849" rpy="0.0 -0.0 7.002961686799377e-34" />
            <mass value="0.048399072148255506" />
            <inertia ixx="2.2465407655417502e-05" iyy="2.259983189186051e-05" izz="4.141692185716337e-06" ixy="-1.929776213000357e-06" iyz="3.2931885882197726e-06" ixz="3.246172654049007e-06" />
        </inertial>
        <visual name="leg_1_femur_c_visual">
            <origin xyz="-0.030759142051414213 0.03075914661822509 -0.04770578320343558" rpy="1.5707963267948966 -0.6108652381980162 -2.356194490192345" />
            <geometry>
                <mesh filename="CAD/femur_c_right.stl" scale="0.001 0.001 0.001" />
            </geometry>
            <material name="gray"/>
        </visual>
        <collision name="leg_1_femur_c_collision">
            <origin xyz="-0.030759142051414213 0.03075914661822509 -0.04770578320343558" rpy="1.5707963267948966 -0.6108652381980162 -2.356194490192345" />
            <geometry>
                <mesh filename="CAD/femur_c_right.stl" scale="0.001 0.001 0.001" />
            </geometry>
        </collision>
    </link>

    <link name="leg_1_tibia">
        <inertial>
            <origin xyz="-0.04085132676876166 0.025253080823863953 -0.009277024870086095" rpy="0.0 -0.0 -1.6038036517675087e-64" />
            <mass value="0.10828707727885009" />
            <inertia ixx="5.5437188486367334e-05" iyy="6.147434583849689e-05" izz="0.0001071830159033978" ixy="5.173583962738001e-05" iyz="-2.259988236504463e-06" ixz="1.476543947169463e-06" />
        </inertial>
        <visual name="leg_1_tibia_visual">
            <origin xyz="-0.03719381938681872 0.026870057867797073 0.004749998110869997" rpy="2.356194490192345 1.5707963267948963 0" />
            <geometry>
                <mesh filename="CAD/tibia_right.stl" scale="0.001 0.001 0.001" />
            </geometry>
            <material name="gray"/>
        </visual>
        <collision name="leg_1_tibia_collision">
            <origin xyz="-0.03719381938681872 0.026870057867797073 0.004749998110869997" rpy="2.356194490192345 1.5707963267948963 0" />
            <geometry>
                <mesh filename="CAD/tibia_right.stl" scale="0.001 0.001 0.001" />
            </geometry>
        </collision>
    </link>

    <!-- Leg 2 links -->
    <link name="leg_2_MG996R_c">
        <inertial>
            <origin xyz="-0.024952799971082146 0.005250002202690392 0.008369892907461582" rpy="0.0 -0.0 0.0" />
            <mass value="0.207953278714177" />
            <inertia ixx="2.8467555536284703e-05" iyy="5.132523895244492e-05" izz="3.6226092838336074e-05" ixy="-3.0667533548436243e-12" iyz="6.723519192224986e-12" ixz="-4.736436528994054e-07" />
        </inertial>
        <visual name="leg_2_MG996R_c_visual">
            <origin xyz="-0.004700000000000069 -0.004499999999999934 -4.440892098500626e-18" rpy="3.141592653589793 1.2514850379350087e-16 3.141592653589793" />
            <geometry>
                <mesh filename="CAD/MG996R.stl" scale="0.001 0.001 0.001" />
            </geometry>
            <material name="gray"/>
        </visual>
        <collision name="leg_2_MG996R_c_collision">
            <origin xyz="-0.004700000000000069 -0.004499999999999934 -4.440892098500626e-18" rpy="3.141592653589793 1.2514850379350087e-16 3.141592653589793" />
            <geometry>
                <mesh filename="CAD/MG996R.stl" scale="0.001 0.001 0.001" />
            </geometry>
        </collision>
    </link>

    <link name="leg_2_MG996R_f">
        <inertial>
            <origin xyz="0.024952796767646605 0.008369892907461447 0.005250002202690141" rpy="0.0 -0.0 0.0" />
            <mass value="0.207953278714177" />
            <inertia ixx="2.8467555536284845e-05" iyy="3.622609283833412e-05" izz="5.1325238952444346e-05" ixy="4.7364365289941395e-07" iyz="6.723519520811499e-12" ixz="3.0667537330138564e-12" />
        </inertial>
        <visual name="leg_2_MG996R_f_visual">
            <origin xyz="0.004699996796564441 -1.176836406102666e-16 -0.004500000000000206" rpy="1.570796326794899 3.106065884736969e-17 -3.1060658847369654e-17" />
            <geometry>
                <mesh filename="CAD/MG996R.stl" scale="0.001 0.001 0.001" />
            </geometry>
            <material name="gray"/>
        </visual>
        <collision name="leg_2_MG996R_f_collision">
            <origin xyz="0.004699996796564441 -1.176836406102666e-16 -0.004500000000000206" rpy="1.570796326794899 3.106065884736969e-17 -3.1060658847369654e-17" />
            <geometry>
                <mesh filename="CAD/MG996R.stl" scale="0.001 0.001 0.001" />
            </geometry>
        </collision>
    </link>

    <link name="leg_2_MG996R_t">
        <inertial>
            <origin xyz="-0.009997198350766468 -0.022696317092538602 4.091820313689709e-09" rpy="0.0 -0.0 0.0" />
            <mass value="0.207953278714177" />
            <inertia ixx="2.846755553628441e-05" iyy="3.622609283833629e-05" izz="5.1325238952446006e-05" ixy="4.7364365289906656e-07" iyz="6.723519185386452e-12" ixz="3.066753448410786e-12" />
        </inertial>
        <visual name="leg_2_MG996R_t_visual">
            <origin xyz="-0.030249998321848538 -0.03106621000000017 -0.00974999811087005" rpy="1.5707963267948968 -5.562433471528925e-16 1.6653345369377316e-16" />
            <geometry>
                <mesh filename="CAD/MG996R.stl" scale="0.001 0.001 0.001" />
            </geometry>
            <material name="gray"/>
        </visual>
        <collision name="leg_2_MG996R_t_collision">
            <origin xyz="-0.030249998321848538 -0.03106621000000017 -0.00974999811087005" rpy="1.5707963267948968 -5.562433471528925e-16 1.6653345369377316e-16" />
            <geometry>
                <mesh filename="CAD/MG996R.stl" scale="0.001 0.001 0.001" />
            </geometry>
        </collision>
    </link>

    <link name="leg_2_coxa_a">
        <inertial>
            <origin xyz="0.018707157766217345 0.00718001434038852 0.0006271852210843853" rpy="0.0 -0.0 0.0" />
            <mass value="0.03329037594662584" />
            <inertia ixx="7.442769001220687e-07" iyy="7.67945156776226e-06" izz="8.134975133641234e-06" ixy="8.064531578484873e-08" iyz="3.7585803375684765e-09" ixz="-6.649401827460747e-08" />
        </inertial>
        <visual name="leg_2_coxa_a_visual">
            <origin xyz="-0.0047499999999997475 0.006999999999999875 -0.0017500032034355596" rpy="-1.3218501401405977e-16 1.5665418669671956e-16 -1.5707963267948943" />
            <geometry>
                <mesh filename="CAD/coxa_a_right.stl" scale="0.001 0.001 0.001" />
            </geometry>
            <material name="gray"/>
        </visual>
        <collision name="leg_2_coxa_a_collision">
            <origin xyz="-0.0047499999999997475 0.006999999999999875 -0.0017500032034355596" rpy="-1.3218501401405977e-16 1.5665418669671956e-16 -1.5707963267948943" />
            <geometry>
                <mesh filename="CAD/coxa_a_right.stl" scale="0.001 0.001 0.001" />
            </geometry>
        </collision>
    </link>

    <link name="leg_2_coxa_b">
        <inertial>
            <origin xyz="-0.022610969521651363 0.000133443845301142 -0.005835649360206497" rpy="0.0 -0.0 0.0" />
            <mass value="0.04490836615745227" />
            <inertia ixx="9.55692603965828e-07" iyy="1.4430293369179057e-05" izz="1.4869699271513235e-05" ixy="1.221862618118398e-07" iyz="-2.9103536113086024e-09" ixz="-1.4501111628368105e-07" />
        </inertial>
        <visual name="leg_2_coxa_b_visual">
            <origin xyz="-0.05299999999999983 -7.105427357601002e-17 0.04149999679656445" rpy="-1.3218501401405972e-16 1.5665418669671956e-16 -1.5707963267948943" />
            <geometry>
                <mesh filename="CAD/coxa_b_right.stl" scale="0.001 0.001 0.001" />
            </geometry>
            <material name="gray"/>
        </visual>
        <collision name="leg_2_coxa_b_collision">
            <origin xyz="-0.05299999999999983 -7.105427357601002e-17 0.04149999679656445" rpy="-1.3218501401405972e-16 1.5665418669671956e-16 -1.5707963267948943" />
            <geometry>
                <mesh filename="CAD/coxa_b_right.stl" scale="0.001 0.001 0.001" />
            </geometry>
        </collision>
    </link>

    <link name="leg_2_femur_a">
        <inertial>
            <origin xyz="-0.006496602430141571 0.0038466359024208695 0.039071142879494716" rpy="0.0 -0.0 0.0" />
            <mass value="0.06532641332455354" />
            <inertia ixx="3.6885982566301823e-05" iyy="4.486630708775948e-05" izz="8.434001460604947e-06" ixy="-4.863534748184343e-08" iyz="-2.473710704388476e-08" ixz="1.0347652324243302e-05" />
        </inertial>
        <visual name="leg_2_femur_a_visual">
            <origin xyz="1.4210854715202004e-16 0.0010000032034353757 -3.203435545717781e-09" rpy="1.5707963267948966 -0.6108652381980165 3.141592653589793" />
            <geometry>
                <mesh filename="CAD/femur_a_right.stl" scale="0.001 0.001 0.001" />
            </geometry>
            <material name="gray"/>
        </visual>
        <collision name="leg_2_femur_a_collision">
            <origin xyz="1.4210854715202004e-16 0.0010000032034353757 -3.203435545717781e-09" rpy="1.5707963267948966 -0.6108652381980165 3.141592653589793" />
            <geometry>
                <mesh filename="CAD/femur_a_right.stl" scale="0.001 0.001 0.001" />
            </geometry>
        </collision>
    </link>
    
    <link name="leg_2_femur_b">
        <inertial>
            <origin xyz="0.00032135955913933147 0.021749996796564624 -0.005200437922150671" rpy="0.0 -0.0 0.0" />
            <mass value="0.0800214310563922" />
            <inertia ixx="1.536057696688715e-05" iyy="4.025742380675979e-06" izz="1.3901924233198412e-05" ixy="6.844026213814747e-19" iyz="1.3213713977167085e-19" ixz="1.9778834178156915e-07" />
        </inertial>
        <visual name="leg_2_femur_b_visual">
            <origin xyz="1.7763568394002506e-16 -3.203435303689162e-09 0.04770578320343555" rpy="-1.5707963267948966 0.6108652381980165 -3.141592653589793" />
            <geometry>
                <mesh filename="CAD/femur_b_right.stl" scale="0.001 0.001 0.001" />
            </geometry>
            <material name="gray"/>
        </visual>
        <collision name="leg_2_femur_b_collision">
            <origin xyz="1.7763568394002506e-16 -3.203435303689162e-09 0.04770578320343555" rpy="-1.5707963267948966 0.6108652381980165 -3.141592653589793" />
            <geometry>
                <mesh filename="CAD/femur_b_right.stl" scale="0.001 0.001 0.001" />
            </geometry>
        </collision>
    </link>

    <link name="leg_2_femur_c">
        <inertial>
            <origin xyz="-0.004247557582456559 -0.0027079742218780512 -0.016733416303654804" rpy="0.0 -0.0 0.0" />
            <mass value="0.048399072148255506" />
            <inertia ixx="2.0602843560638297e-05" iyy="2.4462395986639147e-05" izz="4.141692185716554e-06" ixy="6.721211822085377e-08" iyz="3.3245285875999574e-08" ixz="4.624026679036694e-06" />
        </inertial>
        <visual name="leg_2_femur_c_visual">
            <origin xyz="1.9539925233402755e-16 0.043500003203435327 -0.05770578320343554" rpy="1.5707963267948966 -0.6108652381980164 3.1415926535897927" />
            <geometry>
                <mesh filename="CAD/femur_c_right.stl" scale="0.001 0.001 0.001" />
            </geometry>
            <material name="gray"/>
        </visual>
        <collision name="leg_2_femur_c_collision">
            <origin xyz="1.9539925233402755e-16 0.043500003203435327 -0.05770578320343554" rpy="1.5707963267948966 -0.6108652381980164 3.1415926535897927" />
            <geometry>
                <mesh filename="CAD/femur_c_right.stl" scale="0.001 0.001 0.001" />
            </geometry>
        </collision>
    </link>

    <link name="leg_2_tibia">
        <inertial>
            <origin xyz="0.0028571288389278495 0.011029623704799596 0.00927702487008597" rpy="0.0 -0.0 4.125340265343691e-64" />
            <mass value="0.10828707727885009" />
            <inertia ixx="6.719927535051777e-06" iyy="0.00011019160678981191" izz="0.00010718301590339737" ixy="3.0185786760642376e-06" iyz="-5.539787696705092e-07" ixz="-2.642127245197634e-06" />
        </inertial>
        <visual name="leg_2_tibia_visual">
            <origin xyz="0.0043000016781514815 0.007299999999999815 -0.004749998110870122" rpy="-1.5707963267948966 -1.5707963267948961 0" />
            <geometry>
                <mesh filename="CAD/tibia_right.stl" scale="0.001 0.001 0.001" />
            </geometry>
            <material name="gray"/>
        </visual>
        <collision name="leg_2_tibia_collision">
            <origin xyz="0.0043000016781514815 0.007299999999999815 -0.004749998110870122" rpy="-1.5707963267948966 -1.5707963267948961 0" />
            <geometry>
                <mesh filename="CAD/tibia_right.stl" scale="0.001 0.001 0.001" />
            </geometry>
        </collision>
    </link>

    <!-- Leg 3 links -->
    <link name="leg_3_MG996R_c">
        <inertial>
            <origin xyz="-0.013931984749787879 -0.02135660163470809 0.008369892907461584" rpy="0.0 -0.0 0.0" />
            <mass value="0.207953278714177" />
            <inertia ixx="3.989640031111866e-05" iyy="3.989639417761111e-05" izz="3.6226092838336074e-05" ixy="-1.1428841708080147e-05" iyz="-3.349118845850544e-07" ixz="-3.349213930771926e-07" />
        </inertial>
        <visual name="leg_3_MG996R_c_visual">
            <origin xyz="0.007283200121885134 -0.013930002111247317 -6.661338147750939e-18" rpy="3.1415926535897927 1.586806286402691e-16 -2.356194490192345" />
            <geometry>
                <mesh filename="CAD/MG996R.stl" scale="0.001 0.001 0.001" />
            </geometry>
            <material name="gray"/>
        </visual>
        <collision name="leg_3_MG996R_c_collision">
            <origin xyz="0.007283200121885134 -0.013930002111247317 -6.661338147750939e-18" rpy="3.1415926535897927 1.586806286402691e-16 -2.356194490192345" />
            <geometry>
                <mesh filename="CAD/MG996R.stl" scale="0.001 0.001 0.001" />
            </geometry>
        </collision>
    </link>

    <link name="leg_3_MG996R_f">
        <inertial>
            <origin xyz="0.024952796767646567 0.0022060948384957334 -0.009630716290229949" rpy="0.0 -0.0 0.0" />
            <mass value="0.207953278714177" />
            <inertia ixx="2.8467555536283544e-05" iyy="4.377567261890894e-05" izz="4.377565917186967e-05" ixy="3.349188073535652e-07" iyz="7.5495730570552914e-06" ixz="-3.3491447030884445e-07" />
        </inertial>
        <visual name="leg_3_MG996R_f_visual">
            <origin xyz="0.004699996796564403 -0.010606605868281669 -0.010606600931664793" rpy="0.7853981633974482 -1.7256332301709629e-31 -2.386633879938858e-16" />
            <geometry>
                <mesh filename="CAD/MG996R.stl" scale="0.001 0.001 0.001" />
            </geometry>
            <material name="gray"/>
        </visual>
        <collision name="leg_3_MG996R_f_collision">
            <origin xyz="0.004699996796564403 -0.010606605868281669 -0.010606600931664793" rpy="0.7853981633974482 -1.7256332301709629e-31 -2.386633879938858e-16" />
            <geometry>
                <mesh filename="CAD/MG996R.stl" scale="0.001 0.001 0.001" />
            </geometry>
        </collision>
    </link>

    <link name="leg_3_MG996R_t">
        <inertial>
            <origin xyz="-0.02311780679666722 -0.00897963207460709 4.09182025151722e-09" rpy="-3.0814879110195774e-33 -0.0 4.9780954463047874e-34" />
            <mass value="0.207953278714177" />
            <inertia ixx="3.282046784020779e-05" iyy="3.187318053441116e-05" izz="5.132523895244599e-05" ixy="3.879268651025068e-06" iyz="2.5857233037326132e-12" ixz="6.922768561105084e-12" />
        </inertial>
        <visual name="leg_3_MG996R_t_visual">
            <origin xyz="-0.04335710702690537 -0.0005771479097114707 -0.009749998110870121" rpy="1.5707963267948977 -4.813217404829715e-16 -0.7853981633974486" />
            <geometry>
                <mesh filename="CAD/MG996R.stl" scale="0.001 0.001 0.001" />
            </geometry>
            <material name="gray"/>
        </visual>
        <collision name="leg_3_MG996R_t_collision">
            <origin xyz="-0.04335710702690537 -0.0005771479097114707 -0.009749998110870121" rpy="1.5707963267948977 -4.813217404829715e-16 -0.7853981633974486" />
            <geometry>
                <mesh filename="CAD/MG996R.stl" scale="0.001 0.001 0.001" />
            </geometry>
        </collision>
    </link>

    <link name="leg_3_coxa_a">
        <inertial>
            <origin xyz="0.01830499415619089 -0.008150925434596666 0.0006271852210843631" rpy="0.0 -0.0 -6.566986231973194e-63" />
            <mass value="0.03329037594662584" />
            <inertia ixx="4.292509549727098e-06" iyy="4.131218918157248e-06" izz="8.13497513364118e-06" ixy="3.4675873338200873e-06" iyz="4.967608887466253e-08" ixz="-4.436065358600391e-08" />
        </inertial>
        <visual name="leg_3_coxa_a_visual">
            <origin xyz="0.001590989471536428 0.00830850052845852 -0.0017500032034355774" rpy="-2.4306087867598536e-16 7.892504736715235e-16 -2.356194490192345" />
            <geometry>
                <mesh filename="CAD/coxa_a_right.stl" scale="0.001 0.001 0.001" />
            </geometry>
            <material name="gray"/>
        </visual>
        <collision name="leg_3_coxa_a_collision">
            <origin xyz="0.001590989471536428 0.00830850052845852 -0.0017500032034355774" rpy="-2.4306087867598536e-16 7.892504736715235e-16 -2.356194490192345" />
            <geometry>
                <mesh filename="CAD/coxa_a_right.stl" scale="0.001 0.001 0.001" />
            </geometry>
        </collision>
    </link>

    <link name="leg_3_coxa_b">
        <inertial>
            <origin xyz="-0.015894011955618632 0.01608273005145376 -0.005835649360206514" rpy="0.0 -0.0 -3.0385816786431342e-64" />
            <mass value="0.04490836615745227" />
            <inertia ixx="7.815179248384956e-06" iyy="7.570806724760494e-06" izz="1.4869699271513133e-05" ixy="6.737300382606636e-06" iyz="1.0048041289748125e-07" ixz="-1.0459627444577788e-07" />
        </inertial>
        <visual name="leg_3_coxa_b_visual">
            <origin xyz="-0.03747666052846363 0.037476660528458564 0.04149999679656442" rpy="-2.430608786759849e-16 7.892504736715233e-16 -2.356194490192345" />
            <geometry>
                <mesh filename="CAD/coxa_b_right.stl" scale="0.001 0.001 0.001" />
            </geometry>
            <material name="gray"/>
        </visual>
        <collision name="leg_3_coxa_b_collision">
            <origin xyz="-0.03747666052846363 0.037476660528458564 0.04149999679656442" rpy="-2.430608786759849e-16 7.892504736715233e-16 -2.356194490192345" />
            <geometry>
                <mesh filename="CAD/coxa_b_right.stl" scale="0.001 0.001 0.001" />
            </geometry>
        </collision>
    </link>

    <link name="leg_3_femur_a">
        <inertial>
            <origin xyz="-0.0018738117298073664 0.007313766969436255 0.039071142879494695" rpy="0.0 -0.0 -6.566986231973194e-63" />
            <mass value="0.06532641332455354" />
            <inertia ixx="4.0827509479549485e-05" iyy="4.0924780174512575e-05" izz="8.434001460605163e-06" ixy="3.9901622607286646e-06" iyz="-7.334386903970838e-06" ixz="7.299403351695576e-06" />
        </inertial>
        <visual name="leg_3_femur_a_visual">
            <origin xyz="0.0007071066182188535 0.0007071020514100468 -3.203435556820011e-09" rpy="1.5707963267948954 -0.6108652381980157 2.356194490192345" />
            <geometry>
                <mesh filename="CAD/femur_a_right.stl" scale="0.001 0.001 0.001" />
            </geometry>
            <material name="gray"/>
        </visual>
        <collision name="leg_3_femur_a_collision">
            <origin xyz="0.0007071066182188535 0.0007071020514100468 -3.203435556820011e-09" rpy="1.5707963267948954 -0.6108652381980157 2.356194490192345" />
            <geometry>
                <mesh filename="CAD/femur_a_right.stl" scale="0.001 0.001 0.001" />
            </geometry>
        </collision>
    </link>

    <link name="leg_3_femur_b">
        <inertial>
            <origin xyz="-0.01515234034912214 0.015606805962863747 -0.005200437922150627" rpy="-3.0814879110195774e-33 -0.0 -4.9780954463047874e-34" />
            <mass value="0.0800214310563922" />
            <inertia ixx="9.69315967378208e-06" iyy="9.693159673782294e-06" izz="1.3901924233198408e-05" ixy="5.667417293105668e-06" iyz="1.3985747771374653e-07" ixz="1.3985747771342154e-07" />
        </inertial>
        <visual name="leg_3_femur_b_visual">
            <origin xyz="-3.381781095157521e-09 -2.0514100640411924e-09 0.0477057832034356" rpy="-1.5707963267948981 0.6108652381980159 -2.356194490192345" />
            <geometry>
                <mesh filename="CAD/femur_b_right.stl" scale="0.001 0.001 0.001" />
            </geometry>
            <material name="gray"/>
        </visual>
        <collision name="leg_3_femur_b_collision">
            <origin xyz="-3.381781095157521e-09 -2.0514100640411924e-09 0.0477057832034356" rpy="-1.5707963267948981 0.6108652381980159 -2.356194490192345" />
            <geometry>
                <mesh filename="CAD/femur_b_right.stl" scale="0.001 0.001 0.001" />
            </geometry>
        </collision>
    </link>

    <link name="leg_3_femur_c">
        <inertial>
            <origin xyz="-0.004918304334170714 0.0010886446390916049 -0.006733416303654902" rpy="0.0 -0.0 1.0492855462980036e-33" />
            <mass value="0.048399072148255506" />
            <inertia ixx="2.259983189186062e-05" iyy="2.2465407655417502e-05" izz="4.141692185716335e-06" ixy="1.9297762130003584e-06" iyz="-3.246172654048922e-06" ixz="3.293188588219827e-06" />
        </inertial>
        <visual name="leg_3_femur_c_visual">
            <origin xyz="0.030759146618218953 0.03075914205141009 -0.04770578320343557" rpy="1.5707963267948948 -0.6108652381980161 2.3561944901923457" />
            <geometry>
                <mesh filename="CAD/femur_c_right.stl" scale="0.001 0.001 0.001" />
            </geometry>
            <material name="gray"/>
        </visual>
        <collision name="leg_3_femur_c_collision">
            <origin xyz="0.030759146618218953 0.03075914205141009 -0.04770578320343557" rpy="1.5707963267948948 -0.6108652381980161 2.3561944901923457" />
            <geometry>
                <mesh filename="CAD/femur_c_right.stl" scale="0.001 0.001 0.001" />
            </geometry>
        </collision>
    </link>

    <link name="leg_3_tibia">
        <inertial>
            <origin xyz="0.009819416807214943 0.005778831687367969 -0.001222975129914019" rpy="0.0 -0.0 -1.0333099986636088e-92" />
            <mass value="0.10828707727885009" />
            <inertia ixx="6.147434583849689e-05" iyy="5.5437188486367334e-05" izz="0.00010718301590339693" ixy="5.173583962737958e-05" iyz="1.4765439471692461e-06" ixz="-2.259988236504246e-06" />
        </inertial>
        <visual name="leg_3_tibia_visual">
            <origin xyz="0.008202439763281824 0.002121324305425034 -0.015249998110870121" rpy="-2.3561944901923453 -1.5707963267948961 0" />
            <geometry>
                <mesh filename="CAD/tibia_right.stl" scale="0.001 0.001 0.001" />
            </geometry>
            <material name="gray"/>
        </visual>
        <collision name="leg_3_tibia_collision">
            <origin xyz="0.008202439763281824 0.002121324305425034 -0.015249998110870121" rpy="-2.3561944901923453 -1.5707963267948961 0" />
            <geometry>
                <mesh filename="CAD/tibia_right.stl" scale="0.001 0.001 0.001" />
            </geometry>
        </collision>
    </link>

    <!-- Leg 4 links -->
    <link name="leg_4_MG996R_c">
        <inertial>
            <origin xyz="0.0139319816347132 -0.021356604749782716 0.008369892907461587" rpy="0.0 -0.0 0.0" />
            <mass value="0.207953278714177" />
            <inertia ixx="3.9896394177610676e-05" iyy="3.989640031111909e-05" izz="3.622609283833586e-05" ixy="1.1428841708080689e-05" iyz="-3.349213930772468e-07" ixz="3.349118845849731e-07" />
        </inertial>
        <visual name="leg_4_MG996R_c_visual">
            <origin xyz="0.0065053821112524895 -0.0001414198781096676 -8.881784197001253e-18" rpy="3.1415926535897922 3.934719975559736e-16 -0.785398163397451" />
            <geometry>
                <mesh filename="CAD/MG996R.stl" scale="0.001 0.001 0.001" />
            </geometry>
            <material name="gray"/>
        </visual>
        <collision name="leg_4_MG996R_c_collision">
            <origin xyz="0.0065053821112524895 -0.0001414198781096676 -8.881784197001253e-18" rpy="3.1415926535897922 3.934719975559736e-16 -0.785398163397451" />
            <geometry>
                <mesh filename="CAD/MG996R.stl" scale="0.001 0.001 0.001" />
            </geometry>
        </collision>
    </link>

    <link name="leg_4_MG996R_f">
        <inertial>
            <origin xyz="0.024952796767646453 -0.002206091723421242 -0.009630719405304689" rpy="2.736911063134407e-48 -0.0 0.0" />
            <mass value="0.207953278714177" />
            <inertia ixx="2.846755553628441e-05" iyy="4.377565917187142e-05" izz="4.377567261890917e-05" ixy="-3.349144703086209e-07" iyz="-7.549573057054861e-06" ixz="-3.3491880735336197e-07" />
        </inertial>
        <visual name="leg_4_MG996R_f_visual">
            <origin xyz="0.004699996796564283 -0.0031819763648561405 0.0031819813014726784" rpy="-0.7853981633974395 -5.329965436152269e-16 -4.450087234578097e-16" />
            <geometry>
                <mesh filename="CAD/MG996R.stl" scale="0.001 0.001 0.001" />
            </geometry>
            <material name="gray"/>
        </visual>
        <collision name="leg_4_MG996R_f_collision">
            <origin xyz="0.004699996796564283 -0.0031819763648561405 0.0031819813014726784" rpy="-0.7853981633974395 -5.329965436152269e-16 -4.450087234578097e-16" />
            <geometry>
                <mesh filename="CAD/MG996R.stl" scale="0.001 0.001 0.001" />
            </geometry>
        </collision>
    </link>

    <link name="leg_4_MG996R_t">
        <inertial>
            <origin xyz="0.02311780679666713 -0.008979632074606787 -3.135605020077037e-10" rpy="0.0 -0.0 0.0" />
            <mass value="0.207953278714177" />
            <inertia ixx="3.282046784020951e-05" iyy="3.187318053441031e-05" izz="5.1325238952446006e-05" ixy="-3.879268651025939e-06" iyz="-2.5857237368583637e-12" ixz="6.92276835090207e-12" />
        </inertial>
        <visual name="leg_4_MG996R_t_visual">
            <origin xyz="0.0433571070269053 -0.0005771479097110977 0.009750001889129835" rpy="-1.5707963267948954 -1.2413395815914948e-15 -2.356194490192342" />
            <geometry>
                <mesh filename="CAD/MG996R.stl" scale="0.001 0.001 0.001" />
            </geometry>
            <material name="gray"/>
        </visual>
        <collision name="leg_4_MG996R_t_collision">
            <origin xyz="0.0433571070269053 -0.0005771479097110977 0.009750001889129835" rpy="-1.5707963267948954 -1.2413395815914948e-15 -2.356194490192342" />
            <geometry>
                <mesh filename="CAD/MG996R.stl" scale="0.001 0.001 0.001" />
            </geometry>
        </collision>
    </link>

    <link name="leg_4_coxa_a">
        <inertial>
            <origin xyz="-0.018304994156190926 -0.008150925434596737 0.0006271852210842211" rpy="5.473822126268817e-48 -0.0 1.0804103758398477e-62" />
            <mass value="0.03329037594662584" />
            <inertia ixx="4.292509549727261e-06" iyy="4.13121891815725e-06" izz="8.134975133641183e-06" ixy="-3.467587333820305e-06" iyz="4.9676088874608346e-08" ixz="4.436065358600392e-08" />
        </inertial>
        <visual name="leg_4_coxa_a_visual">
            <origin xyz="-0.001590989471536517 0.008308500528458503 -0.0017500032034357372" rpy="3.1415926535897927 -1.267482847470117e-15 -0.7853981633974424" />
            <geometry>
                <mesh filename="CAD/coxa_a_left.stl" scale="0.001 0.001 0.001" />
            </geometry>
            <material name="gray"/>
        </visual>
        <collision name="leg_4_coxa_a_collision">
            <origin xyz="-0.001590989471536517 0.008308500528458503 -0.0017500032034357372" rpy="3.1415926535897927 -1.267482847470117e-15 -0.7853981633974424" />
            <geometry>
                <mesh filename="CAD/coxa_a_left.stl" scale="0.001 0.001 0.001" />
            </geometry>
        </collision>
    </link>

    <link name="leg_4_coxa_b">
        <inertial>
            <origin xyz="0.015894011955610923 0.016082730051461224 -0.0058356493602066606" rpy="0.0 -0.0 -1.349401336733507e-79" />
            <mass value="0.044908366157452306" />
            <inertia ixx="7.815179248057144e-06" iyy="7.57080672445339e-06" izz="1.4869699270877784e-05" ixy="-6.737300381971778e-06" iyz="1.0048041289651896e-07" ixz="1.0459627444679427e-07" />
        </inertial>
        <visual name="leg_4_coxa_b_visual">
            <origin xyz="0.03747666052846345 0.037476660528458564 0.0414999967965643" rpy="3.141592653589793 -1.2674828474701173e-15 -0.7853981633974424" />
            <geometry>
                <mesh filename="CAD/coxa_b_left.stl" scale="0.001 0.001 0.001" />
            </geometry>
            <material name="gray"/>
        </visual>
        <collision name="leg_4_coxa_b_collision">
            <origin xyz="0.03747666052846345 0.037476660528458564 0.0414999967965643" rpy="3.141592653589793 -1.2674828474701173e-15 -0.7853981633974424" />
            <geometry>
                <mesh filename="CAD/coxa_b_left.stl" scale="0.001 0.001 0.001" />
            </geometry>
        </collision>
    </link>

    <link name="leg_4_femur_a">
        <inertial>
            <origin xyz="0.0018738117298147028 0.007313766969443912 0.039071142879501995" rpy="5.473822126268817e-48 -0.0 1.0804103758398477e-62" />
            <mass value="0.06532641332455366" />
            <inertia ixx="4.08275094788376e-05" iyy="4.092478017380569e-05" izz="8.434001460452945e-06" ixy="-3.990162260653205e-06" iyz="-7.334386904503293e-06" ixz="-7.2994033522306854e-06" />
        </inertial>
        <visual name="leg_4_femur_a_visual">
            <origin xyz="-0.0007071066182189601 0.0007071020514102066 -3.203435718912573e-09" rpy="1.5707963267948952 -0.6108652381980154 0.7853981633974507" />
            <geometry>
                <mesh filename="CAD/femur_a_left.stl" scale="0.001 0.001 0.001" />
            </geometry>
            <material name="gray"/>
        </visual>
        <collision name="leg_4_femur_a_collision">
            <origin xyz="-0.0007071066182189601 0.0007071020514102066 -3.203435718912573e-09" rpy="1.5707963267948952 -0.6108652381980154 0.7853981633974507" />
            <geometry>
                <mesh filename="CAD/femur_a_left.stl" scale="0.001 0.001 0.001" />
            </geometry>
        </collision>
    </link>

    <link name="leg_4_femur_b">
        <inertial>
            <origin xyz="0.015152340349122202 0.015606805962863445 -0.005200437922150476" rpy="0.0 -0.0 0.0" />
            <mass value="0.0800214310563922" />
            <inertia ixx="9.693159673782727e-06" iyy="9.69315967378067e-06" izz="1.3901924233198195e-05" ixy="-5.667417293104799e-06" iyz="1.3985747771331174e-07" ixz="-1.3985747771380042e-07" />
        </inertial>
        <visual name="leg_4_femur_b_visual">
            <origin xyz="3.381781041866816e-09 -2.0514102416768765e-09 0.04770578320343582" rpy="-1.5707963267948983 0.6108652381980155 -0.785398163397451" />
            <geometry>
                <mesh filename="CAD/femur_b_left.stl" scale="0.001 0.001 0.001" />
            </geometry>
            <material name="gray"/>
        </visual>
        <collision name="leg_4_femur_b_collision">
            <origin xyz="3.381781041866816e-09 -2.0514102416768765e-09 0.04770578320343582" rpy="-1.5707963267948983 0.6108652381980155 -0.785398163397451" />
            <geometry>
                <mesh filename="CAD/femur_b_left.stl" scale="0.001 0.001 0.001" />
            </geometry>
        </collision>
    </link>

    <link name="leg_4_femur_c">
        <inertial>
            <origin xyz="0.004918304334170997 0.001088644639091907 -0.006733416303654894" rpy="0.0 -0.0 1.7105694144590052e-49" />
            <mass value="0.04839907214825549" />
            <inertia ixx="2.259983189186778e-05" iyy="2.246540765542314e-05" izz="4.1416921857185054e-06" ixy="-1.9297762130023104e-06" iyz="-3.2461726540463755e-06" ixz="-3.2931885882167364e-06" />
        </inertial>
        <visual name="leg_4_femur_c_visual">
            <origin xyz="-0.030759146618218897 0.030759142051410216 -0.04770578320343568" rpy="1.5707963267948948 -0.6108652381980154 0.7853981633974509" />
            <geometry>
                <mesh filename="CAD/femur_c_left.stl" scale="0.001 0.001 0.001" />
            </geometry>
            <material name="gray"/>
        </visual>
        <collision name="leg_4_femur_c_collision">
            <origin xyz="-0.030759146618218897 0.030759142051410216 -0.04770578320343568" rpy="1.5707963267948948 -0.6108652381980154 0.7853981633974509" />
            <geometry>
                <mesh filename="CAD/femur_c_left.stl" scale="0.001 0.001 0.001" />
            </geometry>
        </collision>
    </link>

    <link name="leg_4_tibia">
        <inertial>
            <origin xyz="-0.009819416807214924 0.005778831687368147 0.009277024870085917" rpy="0.0 -0.0 0.0" />
            <mass value="0.10828707727885012" />
            <inertia ixx="6.14743458385034e-05" iyy="5.543718848637254e-05" izz="0.00010718301590340821" ixy="-5.173583962738565e-05" iyz="1.4765439471690293e-06" ixz="2.259988236504463e-06" />
        </inertial>
        <visual name="leg_4_tibia_visual">
            <origin xyz="-0.008202439763281806 0.002121324305425212 -0.004749998110870184" rpy="2.356194490192348 -1.570796326794895 0" />
            <geometry>
                <mesh filename="CAD/tibia_left.stl" scale="0.001 0.001 0.001" />
            </geometry>
            <material name="gray"/>
        </visual>
        <collision name="leg_4_tibia_collision">
            <origin xyz="-0.008202439763281806 0.002121324305425212 -0.004749998110870184" rpy="2.356194490192348 -1.570796326794895 0" />
            <geometry>
                <mesh filename="CAD/tibia_left.stl" scale="0.001 0.001 0.001" />
            </geometry>
        </collision>
    </link>

    <!-- Leg 5 links -->
    <link name="leg_5_MG996R_c">
        <inertial>
            <origin xyz="0.02495279997108206 0.005249997797309771 0.008369892907461604" rpy="0.0 -0.0 0.0" />
            <mass value="0.207953278714177" />
            <inertia ixx="2.8467555536284428e-05" iyy="5.132523895244492e-05" izz="3.6226092838336074e-05" ixy="-3.0667541208093948e-12" iyz="-6.723519136278067e-12" ixz="4.736436528994054e-07" />
        </inertial>
        <visual name="leg_5_MG996R_c_visual">
            <origin xyz="0.0046999999999999 0.015000000000000114 0.0" rpy="-3.141592653589793 6.040509016842693e-17 0.0" />
            <geometry>
                <mesh filename="CAD/MG996R.stl" scale="0.001 0.001 0.001" />
            </geometry>
            <material name="gray"/>
        </visual>
        <collision name="leg_5_MG996R_c_collision">
            <origin xyz="0.0046999999999999 0.015000000000000114 0.0" rpy="-3.141592653589793 6.040509016842693e-17 0.0" />
            <geometry>
                <mesh filename="CAD/MG996R.stl" scale="0.001 0.001 0.001" />
            </geometry>
        </collision>
    </link>

        <link name="leg_5_MG996R_f">
        <inertial>
            <origin xyz="0.024952796767646532 -0.008369892907461363 -0.005250002202690496" rpy="0.0 -0.0 0.0" />
            <mass value="0.207953278714177" />
            <inertia ixx="2.8467555536284845e-05" iyy="3.622609283833499e-05" izz="5.132523895244451e-05" ixy="-4.736436528993941e-07" iyz="6.7235187076598694e-12" ixz="-3.066753800776492e-12" />
        </inertial>
        <visual name="leg_5_MG996R_f_visual">
            <origin xyz="0.0046999967965643185 1.6209256159527285e-16 0.004499999999999869" rpy="-1.5707963267948934 -6.024789561960091e-17 6.221678429513369e-17" />
            <geometry>
                <mesh filename="CAD/MG996R.stl" scale="0.001 0.001 0.001" />
            </geometry>
            <material name="gray"/>
        </visual>
        <collision name="leg_5_MG996R_f_collision">
            <origin xyz="0.0046999967965643185 1.6209256159527285e-16 0.004499999999999869" rpy="-1.5707963267948934 -6.024789561960091e-17 6.221678429513369e-17" />
            <geometry>
                <mesh filename="CAD/MG996R.stl" scale="0.001 0.001 0.001" />
            </geometry>
        </collision>
    </link>

    <link name="leg_5_MG996R_t">
        <inertial>
            <origin xyz="0.009997198350766717 -0.022696317092538557 -3.13560244435962e-10" rpy="0.0 -0.0 0.0" />
            <mass value="0.207953278714177" />
            <inertia ixx="2.8467555536283978e-05" iyy="3.6226092838331954e-05" izz="5.132523895244427e-05" ixy="-4.736436528999267e-07" iyz="-6.723519121011948e-12" ixz="3.0667543157725237e-12" />
        </inertial>
        <visual name="leg_5_MG996R_t_visual">
            <origin xyz="0.03024999832184889 -0.031066210000000136 0.009750001889130094" rpy="-1.5707963267948968 -9.966247464938834e-16 3.141592653589793" />
            <geometry>
                <mesh filename="CAD/MG996R.stl" scale="0.001 0.001 0.001" />
            </geometry>
            <material name="gray"/>
        </visual>
        <collision name="leg_5_MG996R_t_collision">
            <origin xyz="0.03024999832184889 -0.031066210000000136 0.009750001889130094" rpy="-1.5707963267948968 -9.966247464938834e-16 3.141592653589793" />
            <geometry>
                <mesh filename="CAD/MG996R.stl" scale="0.001 0.001 0.001" />
            </geometry>
        </collision>
    </link>

    <link name="leg_5_coxa_a">
        <inertial>
            <origin xyz="-0.018707157766217328 0.007180014340388445 0.0006271852210843454" rpy="0.0 -0.0 0.0" />
            <mass value="0.03329037594662584" />
            <inertia ixx="7.442769001220721e-07" iyy="7.679451567762314e-06" izz="8.134975133641342e-06" ixy="-8.064531578499612e-08" iyz="3.75858033756395e-09" ixz="6.649401827460747e-08" />
        </inertial>
        <visual name="leg_5_coxa_a_visual">
            <origin xyz="0.004749999999999819 0.006999999999999804 -0.0017500032034356084" rpy="3.141592653589793 3.4387371404817264e-17 -1.5707963267948934" />
            <geometry>
                <mesh filename="CAD/coxa_a_left.stl" scale="0.001 0.001 0.001" />
            </geometry>
            <material name="gray"/>
        </visual>
        <collision name="leg_5_coxa_a_collision">
            <origin xyz="0.004749999999999819 0.006999999999999804 -0.0017500032034356084" rpy="3.141592653589793 3.4387371404817264e-17 -1.5707963267948934" />
            <geometry>
                <mesh filename="CAD/coxa_a_left.stl" scale="0.001 0.001 0.001" />
            </geometry>
        </collision>
    </link>

    <link name="leg_5_coxa_b">
        <inertial>
            <origin xyz="0.022610969521651255 0.000133443845311788 -0.005835649360206625" rpy="0.0 -0.0 0.0" />
            <mass value="0.044908366157452306" />
            <inertia ixx="9.55692604283296e-07" iyy="1.4430293368226043e-05" izz="1.4869699270877838e-05" ixy="-1.2218626180183283e-07" iyz="-2.910353612427321e-09" ixz="1.4501111628370815e-07" />
        </inertial>
        <visual name="leg_5_coxa_b_visual">
            <origin xyz="0.0529999999999998 -1.1546319456101628e-16 0.04149999679656442" rpy="-3.141592653589793 3.43873714048172e-17 -1.5707963267948934" />
            <geometry>
                <mesh filename="CAD/coxa_b_left.stl" scale="0.001 0.001 0.001" />
            </geometry>
            <material name="gray"/>
        </visual>
        <collision name="leg_5_coxa_b_collision">
            <origin xyz="0.0529999999999998 -1.1546319456101628e-16 0.04149999679656442" rpy="-3.141592653589793 3.43873714048172e-17 -1.5707963267948934" />
            <geometry>
                <mesh filename="CAD/coxa_b_left.stl" scale="0.001 0.001 0.001" />
            </geometry>
        </collision>
    </link>

    <link name="leg_5_femur_a">
        <inertial>
            <origin xyz="0.006496602430152141 0.0038466359024208565 0.03907114287950222" rpy="0.0 -0.0 0.0" />
            <mass value="0.06532641332455366" />
            <inertia ixx="3.688598256566843e-05" iyy="4.486630708697365e-05" izz="8.434001460452941e-06" ixy="4.8635347484093146e-08" iyz="-2.4737107041702803e-08" ixz="-1.034765232499834e-05" />
        </inertial>
        <visual name="leg_5_femur_a_visual">
            <origin xyz="-1.0658141036401502e-16 0.0010000032034353668 -3.203435590126702e-09" rpy="1.5707963267948968 -0.6108652381980164 -2.2392425002089054e-16" />
            <geometry>
                <mesh filename="CAD/femur_a_left.stl" scale="0.001 0.001 0.001" />
            </geometry>
            <material name="gray"/>
        </visual>
        <collision name="leg_5_femur_a_collision">
            <origin xyz="-1.0658141036401502e-16 0.0010000032034353668 -3.203435590126702e-09" rpy="1.5707963267948968 -0.6108652381980164 -2.2392425002089054e-16" />
            <geometry>
                <mesh filename="CAD/femur_a_left.stl" scale="0.001 0.001 0.001" />
            </geometry>
        </collision>
    </link>

    <link name="leg_5_femur_b">
        <inertial>
            <origin xyz="-0.00032135955913910054 0.021749996796564634 -0.005200437922150734" rpy="0.0 -0.0 0.0" />
            <mass value="0.0800214310563922" />
            <inertia ixx="1.5360576966887043e-05" iyy="4.0257423806755455e-06" izz="1.3901924233198412e-05" ixy="9.289773199076096e-19" iyz="1.3551429210213564e-19" ixz="-1.9778834178156915e-07" />
        </inertial>
        <visual name="leg_5_femur_b_visual">
            <origin xyz="-5.329070518200751e-17 -3.2034353392162987e-09 0.04770578320343563" rpy="-1.5707963267948968 0.6108652381980164 -2.96418646694404e-17" />
            <geometry>
                <mesh filename="CAD/femur_b_left.stl" scale="0.001 0.001 0.001" />
            </geometry>
            <material name="gray"/>
        </visual>
        <collision name="leg_5_femur_b_collision">
            <origin xyz="-5.329070518200751e-17 -3.2034353392162987e-09 0.04770578320343563" rpy="-1.5707963267948968 0.6108652381980164 -2.96418646694404e-17" />
            <geometry>
                <mesh filename="CAD/femur_b_left.stl" scale="0.001 0.001 0.001" />
            </geometry>
        </collision>
    </link>

    <link name="leg_5_femur_c">
        <inertial>
            <origin xyz="0.004247557582456967 -0.002707974221878071 -0.016733416303654762" rpy="0.0 -0.0 -1.2154326714572548e-63" />
            <mass value="0.04839907214825549" />
            <inertia ixx="2.0602843560643996e-05" iyy="2.446239598664751e-05" izz="4.141692185719156e-06" ixy="-6.721211822218058e-08" iyz="3.324528587597925e-08" ixz="-4.6240266790329005e-06" />
        </inertial>
        <visual name="leg_5_femur_c_visual">
            <origin xyz="-5.329070518200751e-17 0.043500003203435375 -0.057705783203435564" rpy="1.5707963267948966 -0.6108652381980165 -2.2537258856938963e-16" />
            <geometry>
                <mesh filename="CAD/femur_c_left.stl" scale="0.001 0.001 0.001" />
            </geometry>
            <material name="gray"/>
        </visual>
        <collision name="leg_5_femur_c_collision">
            <origin xyz="-5.329070518200751e-17 0.043500003203435375 -0.057705783203435564" rpy="1.5707963267948966 -0.6108652381980165 -2.2537258856938963e-16" />
            <geometry>
                <mesh filename="CAD/femur_c_left.stl" scale="0.001 0.001 0.001" />
            </geometry>
        </collision>
    </link>

    <link name="leg_5_tibia">
        <inertial>
            <origin xyz="0.04674287116107255 -0.011029623704799651 -0.009277024870086201" rpy="0.0 -0.0 7.868944956231646e-108" />
            <mass value="0.10828707727885012" />
            <inertia ixx="6.719927535051885e-06" iyy="0.00011019160678982232" izz="0.00010718301590340908" ixy="3.018578676065051e-06" iyz="-5.53978769670516e-07" ixz="-2.642127245197851e-06" />
        </inertial>
        <visual name="leg_5_tibia_visual">
            <origin xyz="0.04529999832184892 -0.007299999999999869 0.0047499981108699175" rpy="-1.5707963267948966 1.5707963267948957 0" />
            <geometry>
                <mesh filename="CAD/tibia_left.stl" scale="0.001 0.001 0.001" />
            </geometry>
            <material name="gray"/>
        </visual>
        <collision name="leg_5_tibia_collision">
            <origin xyz="0.04529999832184892 -0.007299999999999869 0.0047499981108699175" rpy="-1.5707963267948966 1.5707963267948957 0" />
            <geometry>
                <mesh filename="CAD/tibia_left.stl" scale="0.001 0.001 0.001" />
            </geometry>
        </collision>
    </link>

    <!-- Leg 6 links -->
    <link name="leg_6_MG996R_c">
        <inertial>
            <origin xyz="0.021356604749801736 0.013931981634710731 0.008369892907461604" rpy="0.0 -0.0 0.0" />
            <mass value="0.207953278714177" />
            <inertia ixx="3.9896400311118874e-05" iyy="3.989639417761035e-05" izz="3.622609283833629e-05" ixy="-1.1428841708080472e-05" iyz="3.349118845851222e-07" ixz="3.349213930771113e-07" />
        </inertial>
        <visual name="leg_6_MG996R_c_visual">
            <origin xyz="0.0001414198781287057 0.006505382111249958 4.440892098500626e-18" rpy="-3.141592653589793 2.0112649739774984e-16 0.7853981633974471" />
            <geometry>
                <mesh filename="CAD/MG996R.stl" scale="0.001 0.001 0.001" />
            </geometry>
            <material name="gray"/>
        </visual>
        <collision name="leg_6_MG996R_c_collision">
            <origin xyz="0.0001414198781287057 0.006505382111249958 4.440892098500626e-18" rpy="-3.141592653589793 2.0112649739774984e-16 0.7853981633974471" />
            <geometry>
                <mesh filename="CAD/MG996R.stl" scale="0.001 0.001 0.001" />
            </geometry>
        </collision>
    </link>

    <link name="leg_6_MG996R_f">
        <inertial>
            <origin xyz="0.024952796767646505 -0.009630719405307088 0.00220609172344032" rpy="0.0 -0.0 0.0" />
            <mass value="0.207953278714177" />
            <inertia ixx="2.846755553628441e-05" iyy="4.377567261890787e-05" izz="4.3775659171870984e-05" ixy="-3.349188073534975e-07" iyz="7.549573057055295e-06" ixz="3.349144703087564e-07" />
        </inertial>
        <visual name="leg_6_MG996R_f_visual">
            <origin xyz="0.004699996796564301 0.0031819813014702623 0.0031819763648752364" rpy="-2.3561944901923395 1.3922145338705843e-18 -1.3922145338712252e-18" />
            <geometry>
                <mesh filename="CAD/MG996R.stl" scale="0.001 0.001 0.001" />
            </geometry>
            <material name="gray"/>
        </visual>
        <collision name="leg_6_MG996R_f_collision">
            <origin xyz="0.004699996796564301 0.0031819813014702623 0.0031819763648752364" rpy="-2.3561944901923395 1.3922145338705843e-18 -1.3922145338712252e-18" />
            <geometry>
                <mesh filename="CAD/MG996R.stl" scale="0.001 0.001 0.001" />
            </geometry>
        </collision>
    </link>

    <link name="leg_6_MG996R_t">
        <inertial>
            <origin xyz="-0.008979632074587993 -0.023117806796664572 -3.1356040430807753e-10" rpy="-1.232595164407831e-32 -1.2325951644078312e-32 -1.1599674393591448e-33" />
            <mass value="0.207953278714177" />
            <inertia ixx="3.187318053440943e-05" iyy="3.282046784020951e-05" izz="5.1325238952446874e-05" ixy="3.879268651024635e-06" iyz="-6.92276878432721e-12" ixz="-2.58572416608766e-12" />
        </inertial>
        <visual name="leg_6_MG996R_t_visual">
            <origin xyz="-0.0005771479096923749 -0.04335710702690275 0.009750001889129951" rpy="-1.5707963267948966 -8.698363882287291e-16 2.3561944901923435" />
            <geometry>
                <mesh filename="CAD/MG996R.stl" scale="0.001 0.001 0.001" />
            </geometry>
            <material name="gray"/>
        </visual>
        <collision name="leg_6_MG996R_t_collision">
            <origin xyz="-0.0005771479096923749 -0.04335710702690275 0.009750001889129951" rpy="-1.5707963267948966 -8.698363882287291e-16 2.3561944901923435" />
            <geometry>
                <mesh filename="CAD/MG996R.stl" scale="0.001 0.001 0.001" />
            </geometry>
        </collision>
    </link>

    <link name="leg_6_coxa_a">
        <inertial>
            <origin xyz="-0.008150925434577462 -0.018304994156193324 -0.000627185221084341" rpy="0.0 -0.0 -4.032124600414999e-68" />
            <mass value="0.03329037594662584" />
            <inertia ixx="4.131218918157248e-06" iyy="4.292509549727152e-06" izz="8.134975133641397e-06" ixy="-3.4675873338201415e-06" iyz="-4.4360653585976805e-08" ixz="-4.967608887462187e-08" />
        </inertial>
        <visual name="leg_6_coxa_a_visual">
            <origin xyz="0.008308500528477704 -0.001590989471538844 0.0017500032034356038" rpy="2.6334328169288294e-16 1.0633403582450601e-16 2.3561944901923435" />
            <geometry>
                <mesh filename="CAD/coxa_a_left.stl" scale="0.001 0.001 0.001" />
            </geometry>
            <material name="gray"/>
        </visual>
        <collision name="leg_6_coxa_a_collision">
            <origin xyz="0.008308500528477704 -0.001590989471538844 0.0017500032034356038" rpy="2.6334328169288294e-16 1.0633403582450601e-16 2.3561944901923435" />
            <geometry>
                <mesh filename="CAD/coxa_a_left.stl" scale="0.001 0.001 0.001" />
            </geometry>
        </collision>
    </link>

    <link name="leg_6_coxa_b">
        <inertial>
            <origin xyz="0.016082730051480344 -0.01589401195560855 -0.0058356493602066475" rpy="0.0 -0.0 0.0" />
            <mass value="0.044908366157452306" />
            <inertia ixx="7.570806724452794e-06" iyy="7.81517924805644e-06" izz="1.4869699270878e-05" ixy="6.737300381971345e-06" iyz="-1.0459627444668585e-07" ixz="1.0048041289666804e-07" />
        </inertial>
        <visual name="leg_6_coxa_b_visual">
            <origin xyz="0.03747666052847764 -0.03747666052846109 0.04149999679656441" rpy="-3.141592653589793 -1.0633403582450606e-16 -2.356194490192341" />
            <geometry>
                <mesh filename="CAD/coxa_b_left.stl" scale="0.001 0.001 0.001" />
            </geometry>
            <material name="gray"/>
        </visual>
        <collision name="leg_6_coxa_b_collision">
            <origin xyz="0.03747666052847764 -0.03747666052846109 0.04149999679656441" rpy="-3.141592653589793 -1.0633403582450606e-16 -2.356194490192341" />
            <geometry>
                <mesh filename="CAD/coxa_b_left.stl" scale="0.001 0.001 0.001" />
            </geometry>
        </collision>
    </link>

    <link name="leg_6_femur_a">
        <inertial>
            <origin xyz="0.007313766969462936 -0.0018738117298121894 0.03907114287950212" rpy="0.0 -0.0 4.032124600414999e-68" />
            <mass value="0.06532641332455366" />
            <inertia ixx="4.092478017380524e-05" iyy="4.082750947883695e-05" izz="8.434001460453158e-06" ixy="3.99016226065277e-06" iyz="7.299403352230955e-06" ixz="-7.334386904503235e-06" />
        </inertial>
        <visual name="leg_6_femur_a_visual">
            <origin xyz="0.0007071020514292847 0.0007071066182214736 -3.20343568116499e-09" rpy="1.5707963267948966 -0.6108652381980165 -0.78539816339745" />
            <geometry>
                <mesh filename="CAD/femur_a_left.stl" scale="0.001 0.001 0.001" />
            </geometry>
            <material name="gray"/>
        </visual>
        <collision name="leg_6_femur_a_collision">
            <origin xyz="0.0007071020514292847 0.0007071066182214736 -3.20343568116499e-09" rpy="1.5707963267948966 -0.6108652381980165 -0.78539816339745" />
            <geometry>
                <mesh filename="CAD/femur_a_left.stl" scale="0.001 0.001 0.001" />
            </geometry>
        </collision>
    </link>

    <link name="leg_6_femur_b">
        <inertial>
            <origin xyz="-0.015606805962844509 0.01515234034911952 0.004799562077849391" rpy="-1.232595164407831e-32 1.2325951644078312e-32 1.1599674393591448e-33" />
            <mass value="0.0800214310563922" />
            <inertia ixx="9.693159673780342e-06" iyy="9.693159673782077e-06" izz="1.3901924233198412e-05" ixy="5.6674172931058834e-06" iyz="-1.3985747771331253e-07" ixz="-1.398574777135294e-07" />
        </inertial>
        <visual name="leg_6_femur_b_visual">
            <origin xyz="2.051429248695058e-09 3.3817785016765357e-09 0.057705783203435744" rpy="-1.5707963267948966 0.6108652381980164 0.7853981633974499" />
            <geometry>
                <mesh filename="CAD/femur_b_left.stl" scale="0.001 0.001 0.001" />
            </geometry>
            <material name="gray"/>
        </visual>
        <collision name="leg_6_femur_b_collision">
            <origin xyz="2.051429248695058e-09 3.3817785016765357e-09 0.057705783203435744" rpy="-1.5707963267948966 0.6108652381980164 0.7853981633974499" />
            <geometry>
                <mesh filename="CAD/femur_b_left.stl" scale="0.001 0.001 0.001" />
            </geometry>
        </collision>
    </link>
    
    <link name="leg_6_femur_c">
        <inertial>
            <origin xyz="0.0010886446391108872 -0.0049183043341680666 -0.016733416303654974" rpy="0.0 -0.0 0.0" />
            <mass value="0.04839907214825549" />
            <inertia ixx="2.2465407655423682e-05" iyy="2.2599831891867822e-05" izz="4.14169218571959e-06" ixy="1.9297762130017666e-06" iyz="3.2931885882170625e-06" ixz="-3.2461726540463213e-06" />
        </inertial>
        <visual name="leg_6_femur_c_visual">
            <origin xyz="0.03075914205142933 0.030759146618221607 -0.05770578320343578" rpy="1.5707963267948966 -0.6108652381980165 -0.7853981633974499" />
            <geometry>
                <mesh filename="CAD/femur_c_left.stl" scale="0.001 0.001 0.001" />
            </geometry>
            <material name="gray"/>
        </visual>
        <collision name="leg_6_femur_c_collision">
            <origin xyz="0.03075914205142933 0.030759146618221607 -0.05770578320343578" rpy="1.5707963267948966 -0.6108652381980165 -0.7853981633974499" />
            <geometry>
                <mesh filename="CAD/femur_c_left.stl" scale="0.001 0.001 0.001" />
            </geometry>
        </collision>
    </link>

    <link name="leg_6_tibia">
        <inertial>
            <origin xyz="0.005778831687387029 0.009819416807217537 -0.0012229751299139657" rpy="0.0 -0.0 1.255085382316192e-62" />
            <mass value="0.10828707727885012" />
            <inertia ixx="5.543718848637254e-05" iyy="6.147434583850256e-05" izz="0.00010718301590340908" ixy="5.173583962738523e-05" iyz="-2.2599882365042464e-06" ixz="1.476543947169463e-06" />
        </inertial>
        <visual name="leg_6_tibia_visual">
            <origin xyz="0.0021213243054440944 0.008202439763284417 -0.015249998110870093" rpy="0.7853981633974483 -1.5707963267948957 0" />
            <geometry>
                <mesh filename="CAD/tibia_left.stl" scale="0.001 0.001 0.001" />
            </geometry>
            <material name="gray"/>
        </visual>
        <collision name="leg_6_tibia_collision">
            <origin xyz="0.0021213243054440944 0.008202439763284417 -0.015249998110870093" rpy="0.7853981633974483 -1.5707963267948957 0" />
            <geometry>
                <mesh filename="CAD/tibia_left.stl" scale="0.001 0.001 0.001" />
            </geometry>
        </collision>
    </link>

    <!-- Leg 1 joints -->
    <joint name="base_leg_1_MG996R_c" type="fixed">
        <origin xyz="-0.03264053 -0.060065150000000005 0.013999999999999999" rpy="3.141592653589793 -0.0 0.0" />
        <parent link="base" />
        <child link="leg_1_MG996R_c" />
    </joint>

    <joint name="leg_1_coxa_joint" type="revolute">
        <origin xyz="-0.028425689999999997 0.021001069999999997 0.031066209999999997" rpy="3.141592653589793 -0.0 3.0033433937731107e-33" />
        <parent link="leg_1_MG996R_c" />
        <child link="leg_1_coxa_b" />
        <axis xyz="0.0 0.0 1.0" />
        <limit lower="-1.570796" upper="1.570796" effort="1000000" velocity="1000000" />
    </joint>

    <joint name="leg_1_coxa_b_MG996R_f" type="fixed">
        <origin xyz="-0.02916816000000001 -0.03906765 -0.00535" rpy="6.626416783217546e-33 -1.5707963267948966 0" />
        <parent link="leg_1_coxa_b" />
        <child link="leg_1_MG996R_f" />
    </joint>

    <joint name="leg_1_MG996R_f_coxa_a" type="fixed">
        <origin xyz="0.0494 0.0 0.0" rpy="6.704561300464011e-33 1.5707963267948966 0" />
        <parent link="leg_1_MG996R_f" />
        <child link="leg_1_coxa_a" />
    </joint>

    <joint name="leg_1_femur_joint" type="revolute">
        <origin xyz="0.03495 0.025679440000000008 0.01825481999999999" rpy="6.704561300464011e-33 1.5707963267948966 0" />
        <parent link="leg_1_MG996R_f" />
        <child link="leg_1_femur_a" />
        <axis xyz="0.707107 -0.707107 1.999343393356845e-32" />
        <limit lower="-0.785398" upper="2.356194" effort="1000000" velocity="1000000" />
    </joint>

    <joint name="leg_1_femur_a_femur_b" type="fixed">
        <origin xyz="-0.0007071000000000005 0.000707109999999993 0.04770578" rpy="-3.141592653589793 1.6337250741359954e-17 -5.551115123125783e-17" />
        <parent link="leg_1_femur_a" />
        <child link="leg_1_femur_b" />
    </joint>
    
    <joint name="leg_1_femur_b_femur_c" type="fixed">
        <origin xyz="0.03075914000000001 0.030759150000000002 0.0" rpy="3.141592653589793 -0.0 -7.002961686799377e-34" />
        <parent link="leg_1_femur_b" />
        <child link="leg_1_femur_c" />
    </joint>

    <joint name="leg_1_tibia_joint" type="revolute">
        <origin xyz="-0.020918530000000005 -0.020918540000000013 0.06344154" rpy="4.0156312877350055e-17 1.6337250741359954e-17 -5.551115123125783e-17" />
        <parent link="leg_1_femur_a" />
        <child link="leg_1_MG996R_t" />
        <axis xyz="-0.707107 0.707107 -1.8398022027031245e-17" />
        <limit lower="-1.570796" upper="1.570796" effort="1000000" velocity="1000000" />
    </joint>

    <joint name="leg_1_MG996R_t_tibia" type="fixed">
        <origin xyz="0.033881879999999996 -0.013446489999999986 -0.005250000000000004" rpy="3.141592653589793 -1.6337250741359945e-17 5.551115123125788e-17" />
        <parent link="leg_1_MG996R_t" />
        <child link="leg_1_tibia" />
    </joint>

    <!-- Leg 2 joints -->
    <joint name="base_leg_2_MG996R_c" type="fixed">
        <origin xyz="-0.046200000000000005 0.00525 0.013999999999999999" rpy="3.141592653589793 -0.0 0.0" />
        <parent link="base" />
        <child link="leg_2_MG996R_c" />
    </joint>

    <joint name="leg_2_coxa_joint" type="revolute">
        <origin xyz="-0.03495 0.00525 0.031066209999999997" rpy="3.141592653589793 -0.0 2.7658489543714626e-32" />
        <parent link="leg_2_MG996R_c" />
        <child link="leg_2_coxa_b" />
        <axis xyz="0.0 0.0 1.0" />
        <limit lower="-1.570796" upper="1.570796" effort="1000000" velocity="1000000" />
    </joint>

    <joint name="leg_2_coxa_b_MG996R_f" type="fixed">
        <origin xyz="-0.037750000000000006 -0.006999999999999999 -0.00535" rpy="-3.619061808167923e-31 -1.5707963267948966 0" />
        <parent link="leg_2_coxa_b" />
        <child link="leg_2_MG996R_f" />
    </joint>

    <joint name="leg_2_MG996R_f_coxa_a" type="fixed">
        <origin xyz="0.0494 0.0 0.01049999999999999" rpy="-3.8956467036050695e-31 1.5707963267948966 0" />
        <parent link="leg_2_MG996R_f" />
        <child link="leg_2_coxa_a" />
    </joint>
    
    <joint name="leg_2_femur_joint" type="revolute">
        <origin xyz="0.03495 0.031066209999999997 0.005249999999999986" rpy="-3.8956467036050695e-31 1.5707963267948966 0" />
        <parent link="leg_2_MG996R_f" />
        <child link="leg_2_femur_a" />
        <axis xyz="0.0 -1.0 -3.8956467036050695e-31" />
        <limit lower="-0.785398" upper="2.356194" effort="1000000" velocity="1000000" />
    </joint>

    <joint name="leg_2_femur_a_femur_b" type="fixed">
        <origin xyz="0.0 0.0010000000000000009 0.04770578" rpy="-3.141592653589793 -4.930380657631324e-32 -1.920702115641966e-62" />
        <parent link="leg_2_femur_a" />
        <child link="leg_2_femur_b" />
    </joint>

    <joint name="leg_2_femur_b_femur_c" type="fixed">
        <origin xyz="0.0 0.0435 -0.01" rpy="3.141592653589793 -4.930380657631324e-32 1.0938894043115288e-62" />
        <parent link="leg_2_femur_b" />
        <child link="leg_2_femur_c" />
    </joint>

    <joint name="leg_2_tibia_joint" type="revolute">
        <origin xyz="-0.029583280000000017 0.0 0.06344154" rpy="4.105753625025497e-33 -4.930380657631324e-32 -1.920702115641966e-62" />
        <parent link="leg_2_femur_a" />
        <child link="leg_2_MG996R_t" />
        <axis xyz="0.0 1.0 -2.2186712959340957e-31" />
        <limit lower="-1.570796" upper="1.570796" effort="1000000" velocity="1000000" />
    </joint>

    <joint name="leg_2_MG996R_t_tibia" type="fixed">
        <origin xyz="-0.03495000000000001 -0.031066209999999997 -0.005250000000000004" rpy="6.162975822039155e-33 8.277254298276836e-32 9.860761315262648e-32" />
        <parent link="leg_2_MG996R_t" />
        <child link="leg_2_tibia" />
    </joint>

    <!-- Leg 3 joints -->
    <joint name="base_leg_3_MG996R_c" type="fixed">
        <origin xyz="-0.04006515 0.05264053 0.013999999999999999" rpy="3.141592653589793 -0.0 0.0" />
        <parent link="base" />
        <child link="leg_3_MG996R_c" />
    </joint>

    <joint name="leg_3_coxa_joint" type="revolute">
        <origin xyz="-0.021001069999999997 -0.028425690000000003 0.031066209999999997" rpy="-3.141592653589793 -2.4651903288156613e-32 1.3389511120490542e-32" />
        <parent link="leg_3_MG996R_c" />
        <child link="leg_3_coxa_b" />
        <axis xyz="-2.465190328815662e-32 9.860761315262648e-32 1.0000000000000002" />
        <limit lower="-1.570796" upper="1.570796" effort="1000000" velocity="1000000" />
    </joint>

    <joint name="leg_3_coxa_b_MG996R_f" type="fixed">
        <origin xyz="-0.03906765 0.02916816000000001 -0.00535" rpy="1.4658381573891182e-31 -1.5707963267948966 0" />
        <parent link="leg_3_coxa_b" />
        <child link="leg_3_MG996R_f" />
    </joint>

    <joint name="leg_3_MG996R_f_coxa_a" type="fixed">
        <origin xyz="0.0494 0.0 0.0" rpy="1.0854240133026478e-31 1.5707963267948966 0" />
        <parent link="leg_3_MG996R_f" />
        <child link="leg_3_coxa_a" />
    </joint>

    <joint name="leg_3_femur_joint" type="revolute">
        <origin xyz="0.03495 0.01825481999999999 -0.025679439999999998" rpy="1.0854240133026478e-31 1.5707963267948966 0" />
        <parent link="leg_3_MG996R_f" />
        <child link="leg_3_femur_a" />
        <axis xyz="-0.707107 -0.707107 9.418262515581811e-32" />
        <limit lower="-0.785398" upper="2.356194" effort="1000000" velocity="1000000" />
    </joint>

    <joint name="leg_3_femur_a_femur_b" type="fixed">
        <origin xyz="0.0007071100000000019 0.0007071000000000005 0.04770578" rpy="-3.141592653589793 1.5085330968733485e-17 -5.551115123125785e-17" />
        <parent link="leg_3_femur_a" />
        <child link="leg_3_femur_b" />
    </joint>

    <joint name="leg_3_femur_b_femur_c" type="fixed">
        <origin xyz="-0.030759150000000013 0.03075914000000001 -8.881784197001253e-18" rpy="3.141592653589793 4.173065908753796e-19 -1.6653345369377353e-16" />
        <parent link="leg_3_femur_b" />
        <child link="leg_3_femur_c" />
    </joint>

    <joint name="leg_3_tibia_joint" type="revolute">
        <origin xyz="-0.020918540000000006 0.020918530000000005 0.06344154" rpy="1.801271842119308e-17 1.5085330968733485e-17 -5.551115123125785e-17" />
        <parent link="leg_3_femur_a" />
        <child link="leg_3_MG996R_t" />
        <axis xyz="0.707107 0.7071069999999999 -4.656802568901692e-17" />
        <limit lower="-1.570796" upper="1.570796" effort="1000000" velocity="1000000" />
    </joint>

    <joint name="leg_3_MG996R_t_tibia" type="fixed">
        <origin xyz="-0.04668051 0.0027462499999999857 0.005250000000000004" rpy="-1.8012718421193043e-17 -1.5085330968733362e-17 5.551115123125774e-17" />
        <parent link="leg_3_MG996R_t" />
        <child link="leg_3_tibia" />
    </joint>

    <!-- Leg 4 joints -->
    <joint name="base_leg_4_MG996R_c" type="fixed">
        <origin xyz="0.04006515 0.05264053 0.013999999999999999" rpy="3.141592653589793 -0.0 0.0" />
        <parent link="base" />
        <child link="leg_4_MG996R_c" />
    </joint>

    <joint name="leg_4_coxa_joint" type="revolute">
        <origin xyz="0.021001069999999997 -0.028425690000000003 0.031066209999999997" rpy="3.141592653589793 -4.930380657631324e-32 2.4249584075869093e-48" />
        <parent link="leg_4_MG996R_c" />
        <child link="leg_4_coxa_b" />
        <axis xyz="-4.930380657631324e-32 0.0 1.0" />
        <limit lower="-1.570796" upper="1.570796" effort="1000000" velocity="1000000" />
    </joint>

    <joint name="leg_4_coxa_b_MG996R_f" type="fixed">
        <origin xyz="0.03906765 0.02916816000000001 -0.00535" rpy="-3.141592653589793 -1.5707963267948966 0" />
        <parent link="leg_4_coxa_b" />
        <child link="leg_4_MG996R_f" />
    </joint>

    <joint name="leg_4_MG996R_f_coxa_a" type="fixed">
        <origin xyz="0.0494 -1.7763568394002505e-17 1.7763568394002505e-17" rpy="3.141592653589793 -1.5707963267948966 0" />
        <parent link="leg_4_MG996R_f" />
        <child link="leg_4_coxa_a" />
    </joint>

    <joint name="leg_4_femur_joint" type="revolute">
        <origin xyz="0.03495 -0.01825481999999999 -0.02567943999999998" rpy="3.141592653589793 -1.5707963267948966 0" />
        <parent link="leg_4_MG996R_f" />
        <child link="leg_4_femur_a" />
        <axis xyz="0.707107 -0.7071070000000002 -4.803503751454446e-31" />
        <limit lower="-2.356194" upper="0.785398" effort="1000000" velocity="1000000" />
    </joint>

    <joint name="leg_4_femur_a_femur_b" type="fixed">
        <origin xyz="-0.0007071100000000019 0.0007070999999999828 0.04770577999999999" rpy="3.141592653589793 -3.225719489184397e-17 9.860761315262642e-32" />
        <parent link="leg_4_femur_a" />
        <child link="leg_4_femur_b" />
    </joint>

    <joint name="leg_4_femur_b_femur_c" type="fixed">
        <origin xyz="0.030759150000000002 0.03075914000000001 8.881784197001253e-18" rpy="-3.141592653589793 -1.5502637559609293e-17 7.224469708134766e-36" />
        <parent link="leg_4_femur_b" />
        <child link="leg_4_femur_c" />
    </joint>

    <joint name="leg_4_tibia_joint" type="revolute">
        <origin xyz="0.020918540000000006 0.020918529999999987 0.06344153999999999" rpy="-1.742027637138999e-17 -3.225719489184397e-17 9.860761315262642e-32" />
        <parent link="leg_4_femur_a" />
        <child link="leg_4_MG996R_t" />
        <axis xyz="0.7071069999999999 -0.707107 2.3796817056033812e-17" />
        <limit lower="-1.570796" upper="1.570796" effort="1000000" velocity="1000000" />
    </joint>

    <joint name="leg_4_MG996R_t_tibia" type="fixed">
        <origin xyz="0.04668051000000002 0.0027462499999999857 -0.0052500000000000125" rpy="1.742027637139001e-17 3.225719489184374e-17 -1.5032353460464818e-35" />
        <parent link="leg_4_MG996R_t" />
        <child link="leg_4_tibia" />
    </joint>

    <!-- Leg 5 joints -->
    <joint name="base_leg_5_MG996R_c" type="fixed">
        <origin xyz="0.046200000000000005 0.00525 0.013999999999999999" rpy="3.141592653589793 -0.0 0.0" />
        <parent link="base" />
        <child link="leg_5_MG996R_c" />
    </joint>

    <joint name="leg_5_coxa_joint" type="revolute">
        <origin xyz="0.03495 0.00525 0.031066209999999997" rpy="3.141592653589793 -0.0 0.0" />
        <parent link="leg_5_MG996R_c" />
        <child link="leg_5_coxa_b" />
        <axis xyz="0.0 0.0 1.0" />
        <limit lower="-1.570796" upper="1.570796" effort="1000000" velocity="1000000" />
    </joint>

    <joint name="leg_5_coxa_b_MG996R_f" type="fixed">
        <origin xyz="0.048249999999999994 -0.006999999999999999 -0.00535" rpy="3.141592653589793 -1.5707963267948966 0" />
        <parent link="leg_5_coxa_b" />
        <child link="leg_5_MG996R_f" />
    </joint>

    <joint name="leg_5_MG996R_f_coxa_a" type="fixed">
        <origin xyz="0.0494 0.0 0.0" rpy="-3.141592653589793 -1.5707963267948966 0" />
        <parent link="leg_5_MG996R_f" />
        <child link="leg_5_coxa_a" />
    </joint>

    <joint name="leg_5_femur_joint" type="revolute">
        <origin xyz="0.03495 -0.031066209999999997 -0.005250000000000004" rpy="-3.141592653589793 -1.5707963267948966 0" />
        <parent link="leg_5_MG996R_f" />
        <child link="leg_5_femur_a" />
        <axis xyz="0.0 -1.0 2.0717667630298715e-33" />
        <limit lower="-2.356194" upper="0.785398" effort="1000000" velocity="1000000" />
    </joint>

    <joint name="leg_5_femur_a_femur_b" type="fixed">
        <origin xyz="0.0 0.0010000000000000009 0.04770578" rpy="3.141592653589793 -9.589690804707752e-49 5.551115123125783e-17" />
        <parent link="leg_5_femur_a" />
        <child link="leg_5_femur_b" />
    </joint>

    <joint name="leg_5_femur_b_femur_c" type="fixed">
        <origin xyz="0.0 0.0435 -0.01" rpy="-3.141592653589793 -4.9303806576313227e-32 1.2325951644078307e-32" />
        <parent link="leg_5_femur_b" />
        <child link="leg_5_femur_c" />
    </joint>

    <joint name="leg_5_tibia_joint" type="revolute">
        <origin xyz="0.029583280000000017 0.0 0.06344154" rpy="-3.2028555402441196e-32 -9.589690804707752e-49 5.551115123125783e-17" />
        <parent link="leg_5_femur_a" />
        <child link="leg_5_MG996R_t" />
        <axis xyz="-5.551115123125783e-17 -1.0 -3.4512664603419266e-31" />
        <limit lower="-1.570796" upper="1.570796" effort="1000000" velocity="1000000" />
    </joint>

    <joint name="leg_5_MG996R_t_tibia" type="fixed">
        <origin xyz="-0.014450000000000003 -0.031066209999999997 -0.005250000000000004" rpy="-3.141592653589793 -8.484424295716667e-47 -5.551115123125763e-17" />
        <parent link="leg_5_MG996R_t" />
        <child link="leg_5_tibia" />
    </joint>

    <!-- Leg 6 joints -->
    <joint name="base_leg_6_MG996R_c" type="fixed">
        <origin xyz="0.03264053 -0.060065150000000005 0.013999999999999999" rpy="3.141592653589793 -0.0 0.0" />
        <parent link="base" />
        <child link="leg_6_MG996R_c" />
    </joint>

    <joint name="leg_6_coxa_joint" type="revolute">
        <origin xyz="0.028425689999999997 0.021001069999999997 0.031066209999999997" rpy="-3.141592653589793 -0.0 1.251344390463166e-32" />
        <parent link="leg_6_MG996R_c" />
        <child link="leg_6_coxa_b" />
        <axis xyz="0.0 6.162975822039155e-33 1.0" />
        <limit lower="-1.570796" upper="1.570796" effort="1000000" velocity="1000000" />
    </joint>

    <joint name="leg_6_coxa_b_MG996R_f" type="fixed">
        <origin xyz="0.02916816000000001 -0.03906765 -0.00535" rpy="3.141592653589793 -1.5707963267948966 0" />
        <parent link="leg_6_coxa_b" />
        <child link="leg_6_MG996R_f" />
    </joint>

    <joint name="leg_6_MG996R_f_coxa_a" type="fixed">
        <origin xyz="0.0494 -1.7763568394002505e-17 0.0" rpy="-2.4442543409198012e-32 -1.5707963267948966 0" />
        <parent link="leg_6_MG996R_f" />
        <child link="leg_6_coxa_a" />
    </joint>

    <joint name="leg_6_femur_joint" type="revolute">
        <origin xyz="0.03495 -0.025679440000000008 0.01825481999999999" rpy="3.141592653589793 -1.5707963267948966 0" />
        <parent link="leg_6_MG996R_f" />
        <child link="leg_6_femur_a" />
        <axis xyz="-0.707107 -0.707107 1.4803983593078296e-34" />
        <limit lower="-2.356194" upper="0.785398" effort="1000000" velocity="1000000" />
    </joint>

    <joint name="leg_6_femur_a_femur_b" type="fixed">
        <origin xyz="0.0007071000000000005 0.000707109999999993 0.057705780000000005" rpy="3.141592653589793 -5.59284578221332e-17 -5.551115123125784e-17" />
        <parent link="leg_6_femur_a" />
        <child link="leg_6_femur_b" />
    </joint>

    <joint name="leg_6_femur_b_femur_c" type="fixed">
        <origin xyz="-0.03075914 0.030759150000000002 0.0" rpy="-3.141592653589793 1.59199441504844e-17 -5.551115123125784e-17" />
        <parent link="leg_6_femur_b" />
        <child link="leg_6_femur_c" />
    </joint>

    <joint name="leg_6_tibia_joint" type="revolute">
        <origin xyz="0.020918530000000005 -0.020918540000000013 0.06344154" rpy="-6.289234938331015e-17 -5.59284578221332e-17 -5.551115123125784e-17" />
        <parent link="leg_6_femur_a" />
        <child link="leg_6_MG996R_t" />
        <axis xyz="-0.7071069999999999 -0.7071069999999999 -2.4934463508646154e-17" />
        <limit lower="-1.570796" upper="1.570796" effort="1000000" velocity="1000000" />
    </joint>

    <joint name="leg_6_MG996R_t_tibia" type="fixed">
        <origin xyz="0.0027462499999999857 -0.04668051 0.005250000000000004" rpy="6.289234938331016e-17 5.592845782213298e-17 5.551115123125774e-17" />
        <parent link="leg_6_MG996R_t" />
        <child link="leg_6_tibia" />
    </joint>

</robot>