<?xml version='1.0' encoding='utf-8'?>
<robot name="hexapod">

    <material name="black">
        <color rgba="0 0 0 1" />
    </material>

    <material name="gray">
        <color rgba="0.4 0.4 0.4 1" />
    </material>

    <material name="white">
        <color rgba="1 1 1 1" />
    </material>

    <material name="orange">
        <color rgba="0.902 0.345 0 1" />
    </material>

    <!--Leg 1 links-->
    <link name="base_link">
        <inertial>
            <origin xyz="-0.0213566016347122 0.013931984749781528 0.00836989290746161" rpy="0.0 -0.0 0.0" />
            <mass value="0.207953278714177" />
            <inertia ixx="3.989639417761133e-05" iyy="3.989640031111844e-05" izz="3.6226092838335206e-05" ixy="1.1428841708080039e-05" iyz="3.349213930771384e-07" ixz="-3.349118845850951e-07" />
        </inertial>
        <visual name="base_link_visual">
            <origin xyz="-0.013930002111251416 -0.007283200121891475 2.2204460492503132e-17" rpy="3.141592653589793 1.245344534372108e-16 2.356194490192345" />
            <geometry>
                <mesh filename="CAD/MG996R.stl" scale="0.001 0.001 0.001" />
            </geometry>
            <material name="gray"/>
        </visual>
        <collision name="base_link_collision">
            <origin xyz="-0.013930002111251416 -0.007283200121891475 2.2204460492503132e-17" rpy="3.141592653589793 1.245344534372108e-16 2.356194490192345" />
            <geometry>
                <mesh filename="CAD/MG996R.stl" scale="0.001 0.001 0.001" />
            </geometry>
        </collision>
    </link>

    <link name="leg_1_MG996R_f">
        <inertial>
            <origin xyz="0.024952796767646526 0.009630716290236095 0.0022060948384998546" rpy="0.0 -0.0 0.0" />
            <mass value="0.207953278714177" />
            <inertia ixx="2.846755553628441e-05" iyy="4.377565917187119e-05" izz="4.377567261890959e-05" ixy="3.349144703087767e-07" iyz="-7.549573057054858e-06" ixz="3.349188073535178e-07" />
        </inertial>
        <visual name="leg_1_MG996R_f_visual">
            <origin xyz="0.004699996796564361 0.01060660093167094 -0.01060660586827753" rpy="2.3561944901923453 3.410597503508584e-17 1.540743955509788e-32" />
            <geometry>
                <mesh filename="CAD/MG996R.stl" scale="0.001 0.001 0.001" />
            </geometry>
            <material name="gray"/>
        </visual>
        <collision name="leg_1_MG996R_f_collision">
            <origin xyz="0.004699996796564361 0.01060660093167094 -0.01060660586827753" rpy="2.3561944901923453 3.410597503508584e-17 1.540743955509788e-32" />
            <geometry>
                <mesh filename="CAD/MG996R.stl" scale="0.001 0.001 0.001" />
            </geometry>
        </collision>
    </link>

    <link name="leg_1_MG996R_t">
        <inertial>
            <origin xyz="0.008979632074602933 -0.02311780679666102 4.09182035809863e-09" rpy="0.0 -0.0 7.002961686799377e-34" />
            <mass value="0.207953278714177" />
            <inertia ixx="3.187318053441031e-05" iyy="3.282046784020779e-05" izz="5.1325238952446006e-05" ixy="-3.879268651024205e-06" iyz="6.92276835135608e-12" ixz="-2.5857237346299217e-12" />
        </inertial>
        <visual name="leg_1_MG996R_t_visual">
            <origin xyz="0.0005771479097073318 -0.043357107026899176 -0.009749998110869998" rpy="1.5707963267948968 -2.529221735498422e-16 0.7853981633974484" />
            <geometry>
                <mesh filename="CAD/MG996R.stl" scale="0.001 0.001 0.001" />
            </geometry>
            <material name="gray"/>
        </visual>
        <collision name="leg_1_MG996R_t_collision">
            <origin xyz="0.0005771479097073318 -0.043357107026899176 -0.009749998110869998" rpy="1.5707963267948968 -2.529221735498422e-16 0.7853981633974484" />
            <geometry>
                <mesh filename="CAD/MG996R.stl" scale="0.001 0.001 0.001" />
            </geometry>
        </collision>
    </link>

    <link name="leg_1_coxa_a">
        <inertial>
            <origin xyz="0.008150925434592561 0.01830499415619695 0.0006271852210843588" rpy="0.0 -0.0 0.0" />
            <mass value="0.03329037594662584" />
            <inertia ixx="4.131218918157248e-06" iyy="4.292509549727152e-06" izz="8.13497513364118e-06" ixy="-3.4675873338201415e-06" iyz="-4.436065358599036e-08" ixz="-4.967608887462187e-08" />
        </inertial>
        <visual name="leg_1_coxa_a_visual">
            <origin xyz="-0.008308500528462624 0.0015909894715424855 -0.001750003203435586" rpy="-1.245344534372106e-16 1.5023172683244996e-16 -0.7853981633974481" />
            <geometry>
                <mesh filename="CAD/coxa_a_right.stl" scale="0.001 0.001 0.001" />
            </geometry>
            <material name="gray"/>
        </visual>
        <collision name="leg_1_coxa_a_collision">
            <origin xyz="-0.008308500528462624 0.0015909894715424855 -0.001750003203435586" rpy="-1.245344534372106e-16 1.5023172683244996e-16 -0.7853981633974481" />
            <geometry>
                <mesh filename="CAD/coxa_a_right.stl" scale="0.001 0.001 0.001" />
            </geometry>
        </collision>
    </link>

    <link name="leg_1_coxa_b">
        <inertial>
            <origin xyz="-0.016082730051457803 -0.015894011955612512 -0.005835649360206568" rpy="0.0 -0.0 0.0" />
            <mass value="0.04490836615745227" />
            <inertia ixx="7.570806724760545e-06" iyy="7.815179248384845e-06" izz="1.486969927151291e-05" ixy="-6.737300382606579e-06" iyz="-1.0459627444581849e-07" ixz="-1.0048041289742698e-07" />
        </inertial>
        <visual name="leg_1_coxa_b_visual">
            <origin xyz="-0.037476660528462616 -0.037476660528457516 0.04149999679656438" rpy="-1.245344534372106e-16 1.5023172683245e-16 -0.7853981633974481" />
            <geometry>
                <mesh filename="CAD/coxa_b_right.stl" scale="0.001 0.001 0.001" />
            </geometry>
            <material name="gray"/>
        </visual>
        <collision name="leg_1_coxa_b_collision">
            <origin xyz="-0.037476660528462616 -0.037476660528457516 0.04149999679656438" rpy="-1.245344534372106e-16 1.5023172683245e-16 -0.7853981633974481" />
            <geometry>
                <mesh filename="CAD/leg_1_coxa_b.stl" scale="0.001 0.001 0.001" />
            </geometry>
        </collision>
    </link>

    <link name="leg_1_femur_a">
        <inertial>
            <origin xyz="-0.007313766969440483 -0.0018738117298011225 0.03907114287949463" rpy="0.0 -0.0 0.0" />
            <mass value="0.06532641332455354" />
            <inertia ixx="4.0924780174512575e-05" iyy="4.0827509479549485e-05" izz="8.434001460605163e-06" ixy="-3.990162260728773e-06" iyz="7.2994033516955215e-06" ixz="7.334386903970892e-06" />
        </inertial>
        <visual name="leg_1_femur_a_visual">
            <origin xyz="-0.0007071020514142746 0.0007071066182250796 -3.203435625653839e-09" rpy="1.5707963267948966 -0.6108652381980162 -2.356194490192345" />
            <geometry>
                <mesh filename="CAD/femur_a_right.stl" scale="0.001 0.001 0.001" />
            </geometry>
            <material name="gray"/>
        </visual>
        <collision name="leg_1_femur_a_collision">
            <origin xyz="-0.0007071020514142746 0.0007071066182250796 -3.203435625653839e-09" rpy="1.5707963267948966 -0.6108652381980162 -2.356194490192345" />
            <geometry>
                <mesh filename="CAD/femur_a_right.stl" scale="0.001 0.001 0.001" />
            </geometry>
        </collision>
    </link>
    
    <link name="leg_1_femur_b">
        <inertial>
            <origin xyz="0.015606805962859537 0.015152340349115861 -0.0052004379221506185" rpy="0.0 -0.0 -7.002961686799377e-34" />
            <mass value="0.0800214310563922" />
            <inertia ixx="9.693159673782297e-06" iyy="9.69315967378208e-06" izz="1.3901924233197978e-05" ixy="-5.667417293105776e-06" iyz="-1.3985747771352728e-07" ixz="1.398574777137448e-07" />
        </inertial>
        <visual name="leg_1_femur_b_visual">
            <origin xyz="-2.051414238479765e-09 3.3817748779085832e-09 0.04770578320343561" rpy="-1.5707963267948968 0.6108652381980162 2.356194490192345" />
            <geometry>
                <mesh filename="CAD/femur_b_right.stl" scale="0.001 0.001 0.001" />
            </geometry>
            <material name="gray"/>
        </visual>
        <collision name="leg_1_femur_b_collision">
            <origin xyz="-2.051414238479765e-09 3.3817748779085832e-09 0.04770578320343561" rpy="-1.5707963267948968 0.6108652381980162 2.356194490192345" />
            <geometry>
                <mesh filename="CAD/femur_b_right.stl" scale="0.001 0.001 0.001" />
            </geometry>
        </collision>
    </link>

    <link name="leg_1_femur_c">
        <inertial>
            <origin xyz="-0.0010886446390956995 -0.004918304334164514 -0.006733416303654849" rpy="0.0 -0.0 7.002961686799377e-34" />
            <mass value="0.048399072148255506" />
            <inertia ixx="2.2465407655417502e-05" iyy="2.259983189186051e-05" izz="4.141692185716337e-06" ixy="-1.929776213000357e-06" iyz="3.2931885882197726e-06" ixz="3.246172654049007e-06" />
        </inertial>
        <visual name="leg_1_femur_c_visual">
            <origin xyz="-0.030759142051414213 0.03075914661822509 -0.04770578320343558" rpy="1.5707963267948966 -0.6108652381980162 -2.356194490192345" />
            <geometry>
                <mesh filename="CAD/femur_c_right.stl" scale="0.001 0.001 0.001" />
            </geometry>
            <material name="gray"/>
        </visual>
        <collision name="leg_1_femur_c_collision">
            <origin xyz="-0.030759142051414213 0.03075914661822509 -0.04770578320343558" rpy="1.5707963267948966 -0.6108652381980162 -2.356194490192345" />
            <geometry>
                <mesh filename="CAD/femur_c_right.stl" scale="0.001 0.001 0.001" />
            </geometry>
        </collision>
    </link>

    <link name="leg_1_tibia">
        <inertial>
            <origin xyz="-0.04085132676876166 0.025253080823863953 -0.009277024870086095" rpy="0.0 -0.0 -1.6038036517675087e-64" />
            <mass value="0.10828707727885009" />
            <inertia ixx="5.5437188486367334e-05" iyy="6.147434583849689e-05" izz="0.0001071830159033978" ixy="5.173583962738001e-05" iyz="-2.259988236504463e-06" ixz="1.476543947169463e-06" />
        </inertial>
        <visual name="leg_1_tibia_visual">
            <origin xyz="-0.03719381938681872 0.026870057867797073 0.004749998110869997" rpy="2.356194490192345 1.5707963267948963 0" />
            <geometry>
                <mesh filename="CAD/tibia_right.stl" scale="0.001 0.001 0.001" />
            </geometry>
            <material name="gray"/>
        </visual>
        <collision name="leg_1_tibia_collision">
            <origin xyz="-0.03719381938681872 0.026870057867797073 0.004749998110869997" rpy="2.356194490192345 1.5707963267948963 0" />
            <geometry>
                <mesh filename="CAD/tibia_right.stl" scale="0.001 0.001 0.001" />
            </geometry>
        </collision>
    </link>

    <!-- Leg 1 joints -->

    <joint name="leg_1_coxa_joint" type="revolute">
        <origin xyz="-0.028425689999999997 0.021001069999999997 0.031066209999999997" rpy="3.141592653589793 -0.0 3.0033433937731107e-33" />
        <parent link="base_link" />
        <child link="leg_1_coxa_b" />
        <axis xyz="0.0 0.0 1.0" />
        <limit lower="-1.570796" upper="1.570796" effort="1000000" velocity="1000000" />
    </joint>

    <joint name="leg_1_coxa_b_MG996R_f" type="fixed">
        <origin xyz="-0.02916816000000001 -0.03906765 -0.00535" rpy="6.626416783217546e-33 -1.5707963267948966 0" />
        <parent link="leg_1_coxa_b" />
        <child link="leg_1_MG996R_f" />
    </joint>

    <joint name="leg_1_MG996R_f_coxa_a" type="fixed">
        <origin xyz="0.0494 0.0 0.0" rpy="6.704561300464011e-33 1.5707963267948966 0" />
        <parent link="leg_1_MG996R_f" />
        <child link="leg_1_coxa_a" />
    </joint>

    <joint name="leg_1_femur_joint" type="revolute">
        <origin xyz="0.03495 0.025679440000000008 0.01825481999999999" rpy="6.704561300464011e-33 1.5707963267948966 0" />
        <parent link="leg_1_MG996R_f" />
        <child link="leg_1_femur_a" />
        <axis xyz="0.707107 -0.707107 1.999343393356845e-32" />
        <limit lower="-0.785398" upper="2.356194" effort="1000000" velocity="1000000" />
    </joint>

    <joint name="leg_1_femur_a_femur_b" type="fixed">
        <origin xyz="-0.0007071000000000005 0.000707109999999993 0.04770578" rpy="-3.141592653589793 1.6337250741359954e-17 -5.551115123125783e-17" />
        <parent link="leg_1_femur_a" />
        <child link="leg_1_femur_b" />
    </joint>
    
    <joint name="leg_1_femur_b_femur_c" type="fixed">
        <origin xyz="0.03075914000000001 0.030759150000000002 0.0" rpy="3.141592653589793 -0.0 -7.002961686799377e-34" />
        <parent link="leg_1_femur_b" />
        <child link="leg_1_femur_c" />
    </joint>

    <joint name="leg_1_tibia_joint" type="revolute">
        <origin xyz="-0.020918530000000005 -0.020918540000000013 0.06344154" rpy="4.0156312877350055e-17 1.6337250741359954e-17 -5.551115123125783e-17" />
        <parent link="leg_1_femur_a" />
        <child link="leg_1_MG996R_t" />
        <axis xyz="-0.707107 0.707107 -1.8398022027031245e-17" />
        <limit lower="-1.570796" upper="1.570796" effort="1000000" velocity="1000000" />
    </joint>

    <joint name="leg_1_MG996R_t_tibia" type="fixed">
        <origin xyz="0.033881879999999996 -0.013446489999999986 -0.005250000000000004" rpy="3.141592653589793 -1.6337250741359945e-17 5.551115123125788e-17" />
        <parent link="leg_1_MG996R_t" />
        <child link="leg_1_tibia" />
    </joint>

</robot>