<?xml version='1.0' encoding='utf-8'?>
<robot name="hexapod">

    <material name="black">
        <color rgba="0 0 0 1" />
    </material>

    <material name="gray">
        <color rgba="0.4 0.4 0.4 1" />
    </material>

    <material name="white">
        <color rgba="1 1 1 1" />
    </material>

    <material name="orange">
        <color rgba="0.902 0.345 0 1" />
    </material>

    <!-- Leg 6 links -->
    <link name="base_link">
        <inertial>
            <origin xyz="0.021356604749801736 0.013931981634710731 0.008369892907461604" rpy="0.0 -0.0 0.0" />
            <mass value="0.207953278714177" />
            <inertia ixx="3.9896400311118874e-05" iyy="3.989639417761035e-05" izz="3.622609283833629e-05" ixy="-1.1428841708080472e-05" iyz="3.349118845851222e-07" ixz="3.349213930771113e-07" />
        </inertial>
        <visual name="base_link_visual">
            <origin xyz="0.0001414198781287057 0.006505382111249958 4.440892098500626e-18" rpy="-3.141592653589793 2.0112649739774984e-16 0.7853981633974471" />
            <geometry>
                <mesh filename="CAD/MG996R.stl" scale="0.001 0.001 0.001" />
            </geometry>
            <material name="gray"/>
        </visual>
        <collision name="base_link_collision">
            <origin xyz="0.0001414198781287057 0.006505382111249958 4.440892098500626e-18" rpy="-3.141592653589793 2.0112649739774984e-16 0.7853981633974471" />
            <geometry>
                <mesh filename="CAD/MG996R.stl" scale="0.001 0.001 0.001" />
            </geometry>
        </collision>
    </link>

    <link name="leg_6_MG996R_f">
        <inertial>
            <origin xyz="0.024952796767646505 -0.009630719405307088 0.00220609172344032" rpy="0.0 -0.0 0.0" />
            <mass value="0.207953278714177" />
            <inertia ixx="2.846755553628441e-05" iyy="4.377567261890787e-05" izz="4.3775659171870984e-05" ixy="-3.349188073534975e-07" iyz="7.549573057055295e-06" ixz="3.349144703087564e-07" />
        </inertial>
        <visual name="leg_6_MG996R_f_visual">
            <origin xyz="0.004699996796564301 0.0031819813014702623 0.0031819763648752364" rpy="-2.3561944901923395 1.3922145338705843e-18 -1.3922145338712252e-18" />
            <geometry>
                <mesh filename="CAD/MG996R.stl" scale="0.001 0.001 0.001" />
            </geometry>
            <material name="gray"/>
        </visual>
        <collision name="leg_6_MG996R_f_collision">
            <origin xyz="0.004699996796564301 0.0031819813014702623 0.0031819763648752364" rpy="-2.3561944901923395 1.3922145338705843e-18 -1.3922145338712252e-18" />
            <geometry>
                <mesh filename="CAD/MG996R.stl" scale="0.001 0.001 0.001" />
            </geometry>
        </collision>
    </link>

    <link name="leg_6_MG996R_t">
        <inertial>
            <origin xyz="-0.008979632074587993 -0.023117806796664572 -3.1356040430807753e-10" rpy="-1.232595164407831e-32 -1.2325951644078312e-32 -1.1599674393591448e-33" />
            <mass value="0.207953278714177" />
            <inertia ixx="3.187318053440943e-05" iyy="3.282046784020951e-05" izz="5.1325238952446874e-05" ixy="3.879268651024635e-06" iyz="-6.92276878432721e-12" ixz="-2.58572416608766e-12" />
        </inertial>
        <visual name="leg_6_MG996R_t_visual">
            <origin xyz="-0.0005771479096923749 -0.04335710702690275 0.009750001889129951" rpy="-1.5707963267948966 -8.698363882287291e-16 2.3561944901923435" />
            <geometry>
                <mesh filename="CAD/MG996R.stl" scale="0.001 0.001 0.001" />
            </geometry>
            <material name="gray"/>
        </visual>
        <collision name="leg_6_MG996R_t_collision">
            <origin xyz="-0.0005771479096923749 -0.04335710702690275 0.009750001889129951" rpy="-1.5707963267948966 -8.698363882287291e-16 2.3561944901923435" />
            <geometry>
                <mesh filename="CAD/MG996R.stl" scale="0.001 0.001 0.001" />
            </geometry>
        </collision>
    </link>

    <link name="leg_6_coxa_a">
        <inertial>
            <origin xyz="-0.008150925434577462 -0.018304994156193324 -0.000627185221084341" rpy="0.0 -0.0 -4.032124600414999e-68" />
            <mass value="0.03329037594662584" />
            <inertia ixx="4.131218918157248e-06" iyy="4.292509549727152e-06" izz="8.134975133641397e-06" ixy="-3.4675873338201415e-06" iyz="-4.4360653585976805e-08" ixz="-4.967608887462187e-08" />
        </inertial>
        <visual name="leg_6_coxa_a_visual">
            <origin xyz="0.008308500528477704 -0.001590989471538844 0.0017500032034356038" rpy="2.6334328169288294e-16 1.0633403582450601e-16 2.3561944901923435" />
            <geometry>
                <mesh filename="CAD/coxa_a_left.stl" scale="0.001 0.001 0.001" />
            </geometry>
            <material name="gray"/>
        </visual>
        <collision name="leg_6_coxa_a_collision">
            <origin xyz="0.008308500528477704 -0.001590989471538844 0.0017500032034356038" rpy="2.6334328169288294e-16 1.0633403582450601e-16 2.3561944901923435" />
            <geometry>
                <mesh filename="CAD/coxa_a_left.stl" scale="0.001 0.001 0.001" />
            </geometry>
        </collision>
    </link>

    <link name="leg_6_coxa_b">
        <inertial>
            <origin xyz="0.016082730051480344 -0.01589401195560855 -0.0058356493602066475" rpy="0.0 -0.0 0.0" />
            <mass value="0.044908366157452306" />
            <inertia ixx="7.570806724452794e-06" iyy="7.81517924805644e-06" izz="1.4869699270878e-05" ixy="6.737300381971345e-06" iyz="-1.0459627444668585e-07" ixz="1.0048041289666804e-07" />
        </inertial>
        <visual name="leg_6_coxa_b_visual">
            <origin xyz="0.03747666052847764 -0.03747666052846109 0.04149999679656441" rpy="-3.141592653589793 -1.0633403582450606e-16 -2.356194490192341" />
            <geometry>
                <mesh filename="CAD/coxa_b_left.stl" scale="0.001 0.001 0.001" />
            </geometry>
            <material name="gray"/>
        </visual>
        <collision name="leg_6_coxa_b_collision">
            <origin xyz="0.03747666052847764 -0.03747666052846109 0.04149999679656441" rpy="-3.141592653589793 -1.0633403582450606e-16 -2.356194490192341" />
            <geometry>
                <mesh filename="CAD/coxa_b_left.stl" scale="0.001 0.001 0.001" />
            </geometry>
        </collision>
    </link>

    <link name="leg_6_femur_a">
        <inertial>
            <origin xyz="0.007313766969462936 -0.0018738117298121894 0.03907114287950212" rpy="0.0 -0.0 4.032124600414999e-68" />
            <mass value="0.06532641332455366" />
            <inertia ixx="4.092478017380524e-05" iyy="4.082750947883695e-05" izz="8.434001460453158e-06" ixy="3.99016226065277e-06" iyz="7.299403352230955e-06" ixz="-7.334386904503235e-06" />
        </inertial>
        <visual name="leg_6_femur_a_visual">
            <origin xyz="0.0007071020514292847 0.0007071066182214736 -3.20343568116499e-09" rpy="1.5707963267948966 -0.6108652381980165 -0.78539816339745" />
            <geometry>
                <mesh filename="CAD/femur_a_left.stl" scale="0.001 0.001 0.001" />
            </geometry>
            <material name="gray"/>
        </visual>
        <collision name="leg_6_femur_a_collision">
            <origin xyz="0.0007071020514292847 0.0007071066182214736 -3.20343568116499e-09" rpy="1.5707963267948966 -0.6108652381980165 -0.78539816339745" />
            <geometry>
                <mesh filename="CAD/femur_a_left.stl" scale="0.001 0.001 0.001" />
            </geometry>
        </collision>
    </link>

    <link name="leg_6_femur_b">
        <inertial>
            <origin xyz="-0.015606805962844509 0.01515234034911952 0.004799562077849391" rpy="-1.232595164407831e-32 1.2325951644078312e-32 1.1599674393591448e-33" />
            <mass value="0.0800214310563922" />
            <inertia ixx="9.693159673780342e-06" iyy="9.693159673782077e-06" izz="1.3901924233198412e-05" ixy="5.6674172931058834e-06" iyz="-1.3985747771331253e-07" ixz="-1.398574777135294e-07" />
        </inertial>
        <visual name="leg_6_femur_b_visual">
            <origin xyz="2.051429248695058e-09 3.3817785016765357e-09 0.057705783203435744" rpy="-1.5707963267948966 0.6108652381980164 0.7853981633974499" />
            <geometry>
                <mesh filename="CAD/femur_b_left.stl" scale="0.001 0.001 0.001" />
            </geometry>
            <material name="gray"/>
        </visual>
        <collision name="leg_6_femur_b_collision">
            <origin xyz="2.051429248695058e-09 3.3817785016765357e-09 0.057705783203435744" rpy="-1.5707963267948966 0.6108652381980164 0.7853981633974499" />
            <geometry>
                <mesh filename="CAD/femur_b_left.stl" scale="0.001 0.001 0.001" />
            </geometry>
        </collision>
    </link>
    
    <link name="leg_6_femur_c">
        <inertial>
            <origin xyz="0.0010886446391108872 -0.0049183043341680666 -0.016733416303654974" rpy="0.0 -0.0 0.0" />
            <mass value="0.04839907214825549" />
            <inertia ixx="2.2465407655423682e-05" iyy="2.2599831891867822e-05" izz="4.14169218571959e-06" ixy="1.9297762130017666e-06" iyz="3.2931885882170625e-06" ixz="-3.2461726540463213e-06" />
        </inertial>
        <visual name="leg_6_femur_c_visual">
            <origin xyz="0.03075914205142933 0.030759146618221607 -0.05770578320343578" rpy="1.5707963267948966 -0.6108652381980165 -0.7853981633974499" />
            <geometry>
                <mesh filename="CAD/femur_c_left.stl" scale="0.001 0.001 0.001" />
            </geometry>
            <material name="gray"/>
        </visual>
        <collision name="leg_6_femur_c_collision">
            <origin xyz="0.03075914205142933 0.030759146618221607 -0.05770578320343578" rpy="1.5707963267948966 -0.6108652381980165 -0.7853981633974499" />
            <geometry>
                <mesh filename="CAD/femur_c_left.stl" scale="0.001 0.001 0.001" />
            </geometry>
        </collision>
    </link>

    <link name="leg_6_tibia">
        <inertial>
            <origin xyz="0.005778831687387029 0.009819416807217537 -0.0012229751299139657" rpy="0.0 -0.0 1.255085382316192e-62" />
            <mass value="0.10828707727885012" />
            <inertia ixx="5.543718848637254e-05" iyy="6.147434583850256e-05" izz="0.00010718301590340908" ixy="5.173583962738523e-05" iyz="-2.2599882365042464e-06" ixz="1.476543947169463e-06" />
        </inertial>
        <visual name="leg_6_tibia_visual">
            <origin xyz="0.0021213243054440944 0.008202439763284417 -0.015249998110870093" rpy="0.7853981633974483 -1.5707963267948957 0" />
            <geometry>
                <mesh filename="CAD/tibia_left.stl" scale="0.001 0.001 0.001" />
            </geometry>
            <material name="gray"/>
        </visual>
        <collision name="leg_6_tibia_collision">
            <origin xyz="0.0021213243054440944 0.008202439763284417 -0.015249998110870093" rpy="0.7853981633974483 -1.5707963267948957 0" />
            <geometry>
                <mesh filename="CAD/tibia_left.stl" scale="0.001 0.001 0.001" />
            </geometry>
        </collision>
    </link>

    <!-- Leg 6 joints -->
    <joint name="leg_6_coxa_joint" type="revolute">
        <origin xyz="0.028425689999999997 0.021001069999999997 0.031066209999999997" rpy="-3.141592653589793 -0.0 1.251344390463166e-32" />
        <parent link="base_link" />
        <child link="leg_6_coxa_b" />
        <axis xyz="0.0 6.162975822039155e-33 1.0" />
        <limit lower="-1.570796" upper="1.570796" effort="1000000" velocity="1000000" />
    </joint>

    <joint name="leg_6_coxa_b_MG996R_f" type="fixed">
        <origin xyz="0.02916816000000001 -0.03906765 -0.00535" rpy="3.141592653589793 -1.5707963267948966 0" />
        <parent link="leg_6_coxa_b" />
        <child link="leg_6_MG996R_f" />
    </joint>
    
    <joint name="leg_6_MG996R_f_coxa_a" type="fixed">
        <origin xyz="0.0494 -1.7763568394002505e-17 0.0" rpy="-2.4442543409198012e-32 -1.5707963267948966 0" />
        <parent link="leg_6_MG996R_f" />
        <child link="leg_6_coxa_a" />
    </joint>

    <joint name="leg_6_femur_joint" type="revolute">
        <origin xyz="0.03495 -0.025679440000000008 0.01825481999999999" rpy="3.141592653589793 -1.5707963267948966 0" />
        <parent link="leg_6_MG996R_f" />
        <child link="leg_6_femur_a" />
        <axis xyz="-0.707107 -0.707107 1.4803983593078296e-34" />
        <limit lower="-2.356194" upper="0.785398" effort="1000000" velocity="1000000" />
    </joint>

    <joint name="leg_6_femur_a_femur_b" type="fixed">
        <origin xyz="0.0007071000000000005 0.000707109999999993 0.057705780000000005" rpy="3.141592653589793 -5.59284578221332e-17 -5.551115123125784e-17" />
        <parent link="leg_6_femur_a" />
        <child link="leg_6_femur_b" />
    </joint>

    <joint name="leg_6_femur_b_femur_c" type="fixed">
        <origin xyz="-0.03075914 0.030759150000000002 0.0" rpy="-3.141592653589793 1.59199441504844e-17 -5.551115123125784e-17" />
        <parent link="leg_6_femur_b" />
        <child link="leg_6_femur_c" />
    </joint>

    <joint name="leg_6_tibia_joint" type="revolute">
        <origin xyz="0.020918530000000005 -0.020918540000000013 0.06344154" rpy="-6.289234938331015e-17 -5.59284578221332e-17 -5.551115123125784e-17" />
        <parent link="leg_6_femur_a" />
        <child link="leg_6_MG996R_t" />
        <axis xyz="-0.7071069999999999 -0.7071069999999999 -2.4934463508646154e-17" />
        <limit lower="-1.570796" upper="1.570796" effort="1000000" velocity="1000000" />
    </joint>
    
    <joint name="leg_6_MG996R_t_tibia" type="fixed">
        <origin xyz="0.0027462499999999857 -0.04668051 0.005250000000000004" rpy="6.289234938331016e-17 5.592845782213298e-17 5.551115123125774e-17" />
        <parent link="leg_6_MG996R_t" />
        <child link="leg_6_tibia" />
    </joint>

</robot>